Workbook

Sheet Read_Me
A1: field | B1: value
A2: Workbook | B2: technical_findings_matrix.xlsx
A3: Package ID | B3: CU-JULY-2026-QUAL
A4: Prepared by | B4: OpenAI Codex
A5: Prepared date (UTC) | B5: 46227
A6: Model purpose | B6: Technical findings model built directly from source_register.xlsx.
A7: Population rule | B7: Inputs rows 2–75 are the same 74 evidence records from Source_Register; record IDs are not regenerated and every row links back to the exact source-register row.
A8: Evidence priority | B8: Use measured values where available; flag literature-only values as unverified.
A9: Condition rule | B9: Only values matching PROTO-CU-77 conditions enter the condition-matched evidence calculation. Mismatched conditions remain registered but excluded.
A10: Chemistry rule | B10: Chemistry is separate. The lowest applicable published limit governs; a dated, narrowly scoped approved waiver changes acceptance only for its named lot/impurity.
A11: Identity rule | B11: Unresolved aliases remain in Inputs but are excluded from property comparisons. Chemistry may still be evaluated by declared lot/application scope.
A12: Anchor rule | B12: Inputs carries three anchors per evidence row: the exact Source_Register row, the underlying source file, and the precise source-register detail row; external DOI/ARK/AFLOW anchors are also retained.
A13: Sheet flow | B13: Read_Me → Inputs → Calculations → Scenarios → Outputs → Checks.
A14: Editability | B14: All input and output tables are ordinary editable Excel tables with filters; no worksheet is protected and no screenshots are embedded.
A15: Calculation chain | B15: Chemistry PASS/FAIL and formula-selected protocol matches feed the trace-resistance margin and configured lot risk score.
A16: Sensitivity rule | B16: Scenarios reuse the same Inputs and formulas; only the stated waiver, PCN, or service-temperature switch changes.
A17: Formula visibility | B17: Recalculation cells contain live formulas. Checks / Visible formula audit displays the key formula expressions beside their current results.
... A19: Type control | B19: Dates are Excel dates; percentages and engineering values remain numeric with unit columns or numeric formats; scenarios include explicit row checks.

Sheet Inputs
A1: source_register_row | B1: source_register_anchor | C1: record_id | D1: canonical_material_id | E1: canonical_formula_or_name | F1: lot_id | G1: trace_id | H1: source_family | I1: source_file_anchor | J1: workbook_detail_anchor | K1: external_evidence_anchor | L1: inclusion_status | M1: source_quality_flag | N1: canonical_material_name | O1: evidence_class | P1: property_or_claim | Q1: value | R1: unit | S1: test_temperature_c | T1: test_pressure_kpa | U1: test_strain_rate_s_inv | V1: method_or_structure | W1: source_document_id | X1: source_record_id | Y1: input_alias_or_oxidation_notation | Z1: resolution_type | AA1: resolution_status | AB1: resolution_detail | AC1: exception_applicable | AD1: exception_type | AE1: exception_document_id | AF1: exception_author | AG1: exception_date | AH1: exception_scope | AI1: overridden_clause_or_limit | AJ1: exception_value | AK1: exception_unit | AL1: source_path | AM1: detail_sheet | AN1: detail_row | AO1: inclusion_reason | AP1: notes | AQ1: payload_oxygen_ppm | AR1: payload_sulfur_ppm | AS1: payload_lead_ppm | AT1: payload_bismuth_ppm | AU1: payload_iron_ppm | AV1: payload_nickel_ppm | AW1: payload_length_mm | AX1: payload_width_um | AY1: payload_thickness_um | AZ1: payload_sample_count
A2: 2 | B2: Source_Register row 2 | C2: aflow:19ae1fff932d1df8 | D2: MAT-AGALCU-INCL | E2: Ag-Al-Cu — Ag-Al-Cu AFLOW inclusions | H2: AFLOW | I2: CAT-AFLOW · aflow_conductor_slice.csv | J2: AFLOW_Slice · row 2 | K2: aflowlib.duke.edu:AFLOWDATA/LIB3_WEB/AgAlCu_pv/TBCC001.ABC | L2: included_supporting_evidence | M2: curated AFLOW snapshot; computational structure/formation values; formula-level support only | N2: Ag-Al-Cu AFLOW inclusions | O2: AFLOW catalog | P2: computed structure/properties | V2: space group 42; Pearson oF12 | W2: CAT-AFLOW | X2: aflow:19ae1fff932d1df8 | Z2: none | AA2: comparator/identity context; not a July release material | AB2: No alias or oxidation notation appears on this evidence row. | AC2: No | AL2: data/data/catalog/aflow_conductor_slice.csv | AM2: AFLOW_Slice | AN2: 2 | AO2: Retained for identity, source, scope, or design traceability.
A3: 3 | B3: Source_Register row 3 | C3: aflow:53725bf233e77afc | D3: MAT-AGALCU-INCL | E3: Ag-Al-Cu — Ag-Al-Cu AFLOW inclusions | H3: AFLOW | I3: CAT-AFLOW · aflow_conductor_slice.csv | J3: AFLOW_Slice · row 3 | K3: aflowlib.duke.edu:AFLOWDATA/LIB3_WEB/AgAlCu_pv/TBCC003.ABC | L3: included_supporting_evidence | M3: curated AFLOW snapshot; computational structure/formation values; formula-level support only | N3: Ag-Al-Cu AFLOW inclusions | O3: AFLOW catalog | P3: computed structure/properties | V3: space group 107; Pearson tI6 | W3: CAT-AFLOW | X3: aflow:53725bf233e77afc | Z3: none | AA3: comparator/identity context; not a July release material | AB3: No alias or oxidation notation appears on this evidence row. | AC3: No | AL3: data/data/catalog/aflow_conductor_slice.csv | AM3: AFLOW_Slice | AN3: 3 | AO3: Retained for identity, source, scope, or design traceability.
A4: 4 | B4: Source_Register row 4 | C4: aflow:65ad75192503ef40 | D4: MAT-AGALCU-INCL | E4: Ag-Al-Cu — Ag-Al-Cu AFLOW inclusions | H4: AFLOW | I4: CAT-AFLOW · aflow_conductor_slice.csv | J4: AFLOW_Slice · row 4 | K4: aflowlib.duke.edu:AFLOWDATA/LIB3_WEB/AgAlCu_pv/TFCC003.ABC | L4: included_supporting_evidence | M4: curated AFLOW snapshot; computational structure/formation values; formula-level support only | N4: Ag-Al-Cu AFLOW inclusions | O4: AFLOW catalog | P4: computed structure/properties | V4: space group 107; Pearson tI6 | W4: CAT-AFLOW | X4: aflow:65ad75192503ef40 | Z4: none | AA4: comparator/identity context; not a July release material | AB4: No alias or oxidation notation appears on this evidence row. | AC4: No | AL4: data/data/catalog/aflow_conductor_slice.csv | AM4: AFLOW_Slice | AN4: 4 | AO4: Retained for identity, source, scope, or design traceability.
A5: 5 | B5: Source_Register row 5 | C5: aflow:aca47c434f9e2dc8 | D5: MAT-AGALCU-INCL | E5: Ag-Al-Cu — Ag-Al-Cu AFLOW inclusions | H5: AFLOW | I5: CAT-AFLOW · aflow_conductor_slice.csv | J5: AFLOW_Slice · row 5 | K5: aflowlib.duke.edu:AFLOWDATA/LIB3_WEB/AgAlCu_pv/TFCC002.ABC | L5: included_supporting_evidence | M5: curated AFLOW snapshot; computational structure/formation values; formula-level support only | N5: Ag-Al-Cu AFLOW inclusions | O5: AFLOW catalog | P5: computed structure/properties | V5: space group 44; Pearson oI6 | W5: CAT-AFLOW | X5: aflow:aca47c434f9e2dc8 | Z5: none | AA5: comparator/identity context; not a July release material | AB5: No alias or oxidation notation appears on this evidence row. | AC5: No | AL5: data/data/catalog/aflow_conductor_slice.csv | AM5: AFLOW_Slice | AN5: 5 | AO5: Retained for identity, source, scope, or design traceability.
A6: 6 | B6: Source_Register row 6 | C6: aflow:58ef78db88741d84 | D6: MAT-AGALCU-INCL | E6: Ag-Al-Cu — Ag-Al-Cu AFLOW inclusions | H6: AFLOW | I6: CAT-AFLOW · aflow_conductor_slice.csv | J6: AFLOW_Slice · row 6 | K6: aflowlib.duke.edu:AFLOWDATA/LIB3_WEB/AgAlCu_pv/TBCC011.CAB | L6: included_supporting_evidence | M6: curated AFLOW snapshot; computational structure/formation values; formula-level support only | N6: Ag-Al-Cu AFLOW inclusions | O6: AFLOW catalog | P6: computed structure/properties | V6: space group 123; Pearson tP4 | W6: CAT-AFLOW | X6: aflow:58ef78db88741d84 | Z6: none | AA6: comparator/identity context; not a July release material | AB6: No alias or oxidation notation appears on this evidence row. | AC6: No | AL6: data/data/catalog/aflow_conductor_slice.csv | AM6: AFLOW_Slice | AN6: 6 | AO6: Retained for identity, source, scope, or design traceability.
A7: 7 | B7: Source_Register row 7 | C7: aflow:bc7191682427e0db | D7: MAT-AGALCU-INCL | E7: Ag-Al-Cu — Ag-Al-Cu AFLOW inclusions | H7: AFLOW | I7: CAT-AFLOW · aflow_conductor_slice.csv | J7: AFLOW_Slice · row 7 | K7: aflowlib.duke.edu:AFLOWDATA/LIB3_WEB/AgAlCu_pv/TFCC010.CAB | L7: included_supporting_evidence | M7: curated AFLOW snapshot; computational structure/formation values; formula-level support only | N7: Ag-Al-Cu AFLOW inclusions | O7: AFLOW catalog | P7: computed structure/properties | V7: space group 47; Pearson oP4 | W7: CAT-AFLOW | X7: aflow:bc7191682427e0db | Z7: none | AA7: comparator/identity context; not a July release material | AB7: No alias or oxidation notation appears on this evidence row. | AC7: No | AL7: data/data/catalog/aflow_conductor_slice.csv | AM7: AFLOW_Slice | AN7: 7 | AO7: Retained for identity, source, scope, or design traceability.
A8: 8 | B8: Source_Register row 8 | C8: aflow:e96a2b45334f7475 | D8: MAT-AGALCU-INCL | E8: Ag-Al-Cu — Ag-Al-Cu AFLOW inclusions | H8: AFLOW | I8: CAT-AFLOW · aflow_conductor_slice.csv | J8: AFLOW_Slice · row 8 | K8: aflowlib.duke.edu:AFLOWDATA/LIB3_WEB/AgAlCu_pv/TFCC012.CAB | L8: included_supporting_evidence | M8: curated AFLOW snapshot; computational structure/formation values; formula-level support only | N8: Ag-Al-Cu AFLOW inclusions | O8: AFLOW catalog | P8: computed structure/properties | V8: space group 123; Pearson tP4 | W8: CAT-AFLOW | X8: aflow:e96a2b45334f7475 | Z8: none | AA8: comparator/identity context; not a July release material | AB8: No alias or oxidation notation appears on this evidence row. | AC8: No | AL8: data/data/catalog/aflow_conductor_slice.csv | AM8: AFLOW_Slice | AN8: 8 | AO8: Retained for identity, source, scope, or design traceability.
A9: 9 | B9: Source_Register row 9 | C9: aflow:c3d5872edfcfea9b | D9: MAT-AGALCU-INCL | E9: Ag-Al-Cu — Ag-Al-Cu AFLOW inclusions | H9: AFLOW | I9: CAT-AFLOW · aflow_conductor_slice.csv | J9: AFLOW_Slice · row 9 | K9: aflowlib.duke.edu:AFLOWDATA/LIB3_WEB/AgAlCu_pv/TFCC005.BCA | L9: included_supporting_evidence | M9: curated AFLOW snapshot; computational structure/formation values; formula-level support only | N9: Ag-Al-Cu AFLOW inclusions | O9: AFLOW catalog | P9: computed structure/properties | V9: space group 25; Pearson oP4 | W9: CAT-AFLOW | X9: aflow:c3d5872edfcfea9b | Z9: none | AA9: comparator/identity context; not a July release material | AB9: No alias or oxidation notation appears on this evidence row. | AC9: No | AL9: data/data/catalog/aflow_conductor_slice.csv | AM9: AFLOW_Slice | AN9: 9 | AO9: Retained for identity, source, scope, or design traceability.
A10: 10 | B10: Source_Register row 10 | C10: aflow:query-snapshot-cu-a1-202607 | D10: MAT-CU-C101 | E10: Cu — C10100 OFHC copper | H10: AFLOW | I10: CAT-AFLOW · aflow_conductor_slice.csv | J10: AFLOW_Slice · row 10 | K10: AFLOW A1 copper query snapshot supplied with July conductor package | L10: included_supporting_evidence | M10: curated AFLOW snapshot; computational structure/formation values; formula-level support only | N10: C10100 OFHC copper | O10: AFLOW catalog | P10: computed structure/properties | V10: space group 225; Pearson cF4 | W10: CAT-AFLOW | X10: aflow:query-snapshot-cu-a1-202607 | Y10: C10100 OFHC | Z10: supplier alias | AA10: resolved to elemental Cu structure; supplier grade remains supplier-controlled | AB10: Known source label(s) for this canonical material; current evidence row uses the canonical ID. | AC10: No | AL10: data/data/catalog/aflow_conductor_slice.csv | AM10: AFLOW_Slice | AN10: 10 | AO10: Retained for identity, source, scope, or design traceability.
A11: 11 | B11: Source_Register row 11 | C11: ark:/88434/mds01dp7vr | D11: MAT-YBCO-CUPRATE | E11: Y-Ba-Cu-O — YBCO cuprate | H11: NIST | I11: CAT-NIST · nist_copper_records.csv | J11: NIST_Records · row 2 | K11: doi:10.18434/T4KP8J | L11: included_supporting_evidence | M11: curated NIST record; context or decoy screening | N11: YBCO cuprate | O11: NIST catalog | P11: NIST High Temperature Superconducting (HTS) Materials Database - SRD 62 | W11: CAT-NIST | X11: ark:/88434/mds01dp7vr | Z11: none | AA11: comparator/identity context; not a July release material | AB11: No alias or oxidation notation appears on this evidence row. | AC11: No | AL11: data/data/catalog/nist_copper_records.csv | AM11: NIST_Records | AN11: 2 | AO11: Retained for identity, source, scope, or design traceability.
A12: 12 | B12: Source_Register row 12 | C12: ark:/88434/mds012mz82 | D12: MAT-CU-C101 | E12: Cu — C10100 OFHC copper | H12: NIST | I12: CAT-NIST · nist_copper_records.csv | J12: NIST_Records · row 3 | K12: ark:/88434/mds012mz82 | L12: included_supporting_evidence | M12: curated NIST record; context or decoy screening | N12: C10100 OFHC copper | O12: NIST catalog | P12: NIST Handbook of Basic Atomic Spectroscopic Data - SRD 108 | W12: CAT-NIST | X12: ark:/88434/mds012mz82 | Y12: C10100 OFHC | Z12: supplier alias | AA12: resolved to elemental Cu structure; supplier grade remains supplier-controlled | AB12: Known source label(s) for this canonical material; current evidence row uses the canonical ID. | AC12: No | AL12: data/data/catalog/nist_copper_records.csv | AM12: NIST_Records | AN12: 3 | AO12: Retained for identity, source, scope, or design traceability.
A13: 13 | B13: Source_Register row 13 | C13: ark:/88434/mds2-2940 | D13: MAT-CU-C101 | E13: Cu — C10100 OFHC copper | H13: NIST | I13: CAT-NIST · nist_copper_records.csv | J13: NIST_Records · row 4 | K13: doi:10.18434/mds2-2940 | L13: included_supporting_evidence | M13: curated NIST record; context or decoy screening | N13: C10100 OFHC copper | O13: NIST catalog | P13: Experimental Measurements for Pyrolysis Model Validation - Anaerobic Gasification of PMMA Under External Thermal Radiation | W13: CAT-NIST | X13: ark:/88434/mds2-2940 | Y13: C10100 OFHC | Z13: supplier alias | AA13: resolved to elemental Cu structure; supplier grade remains supplier-controlled | AB13: Known source label(s) for this canonical material; current evidence row uses the canonical ID. | AC13: No | AL13: data/data/catalog/nist_copper_records.csv | AM13: NIST_Records | AN13: 4 | AO13: Retained for identity, source, scope, or design traceability.
A14: 14 | B14: Source_Register row 14 | C14: ark:/88434/mds2-4076 | D14: MAT-CU-HBPLATE | E14: Cu — Hybrid-bond electroplated copper | H14: NIST | I14: CAT-NIST · nist_copper_records.csv | J14: NIST_Records · row 5 | K14: doi:10.18434/mds2-4076 | L14: included_supporting_evidence | M14: curated NIST record; condition-matched copper property support | N14: Hybrid-bond electroplated copper | O14: NIST catalog | P14: Elastic-plastic Single-Step and Multi-Step Indentation via IIT and AFM on Hybrid Bonding Copper | W14: CAT-NIST | X14: ark:/88434/mds2-4076 | Y14: HB electro-Cu | Z14: supplier alias | AA14: resolved at supplier/process and NIST application-family level; no process-specific AFLOW record | AB14: Known source label(s) for this canonical material; current evidence row uses the canonical ID. | AC14: No | AL14: data/data/catalog/nist_copper_records.csv | AM14: NIST_Records | AN14: 5 | AO14: Retained for identity, source, scope, or design traceability.
A15: 15 | B15: Source_Register row 15 | C15: COD-SUM-MAT-CU-C101 | D15: MAT-CU-C101 | E15: Cu — C10100 OFHC copper | H15: COD | I15: CAT-COD-CU · cod_copper_summary.csv | J15: COD_Summary · row 2 | L15: included_supporting_evidence | M15: curated COD identity summary; crystallographic identity support | N15: C10100 OFHC copper | O15: COD catalog | P15: crystal identity summary | R15: records | V15: space group None; None | W15: CAT-COD-CU | X15: COD-SUM-MAT-CU-C101 | Y15: C10100 OFHC | Z15: supplier alias | AA15: resolved to elemental Cu structure; supplier grade remains supplier-controlled | AB15: Known source label(s) for this canonical material; current evidence row uses the canonical ID. | AC15: No | AL15: data/data/catalog/cod_copper_summary.csv | AM15: COD_Summary | AN15: 2 | AO15: Retained for identity, source, scope, or design traceability.
A16: 16 | B16: Source_Register row 16 | C16: COD-SUM-MAT-CU2O-CUPRITE | D16: MAT-CU2O-CUPRITE | E16: Cu2O — Copper(I) oxide / cuprite | H16: COD | I16: CAT-COD-CU · cod_copper_summary.csv | J16: COD_Summary · row 3 | L16: included_supporting_evidence | M16: curated COD identity summary; crystallographic identity support | N16: Copper(I) oxide / cuprite | O16: COD catalog | P16: crystal identity summary | R16: records | V16: space group None; None | W16: CAT-COD-CU | X16: COD-SUM-MAT-CU2O-CUPRITE | Y16: Cu^1O | Z16: legacy oxidation-state notation | AA16: comparator/identity context; not a July release material | AB16: Known source label(s) for this canonical material; current evidence row uses the canonical ID. | AC16: No | AL16: data/data/catalog/cod_copper_summary.csv | AM16: COD_Summary | AN16: 3 | AO16: Retained for identity, source, scope, or design traceability.
A17: 17 | B17: Source_Register row 17 | C17: COD-SUM-MAT-CUO-TENORITE | D17: MAT-CUO-TENORITE | E17: CuO — Copper(II) oxide / tenorite | H17: COD | I17: CAT-COD-CU · cod_copper_summary.csv | J17: COD_Summary · row 4 | L17: included_supporting_evidence | M17: curated COD identity summary; crystallographic identity support | N17: Copper(II) oxide / tenorite | O17: COD catalog | P17: crystal identity summary | R17: records | V17: space group None; None | W17: CAT-COD-CU | X17: COD-SUM-MAT-CUO-TENORITE | Y17: Cu^2O | Z17: legacy oxidation-state notation | AA17: comparator/identity context; not a July release material | AB17: Known source label(s) for this canonical material; current evidence row uses the canonical ID. | AC17: No | AL17: data/data/catalog/cod_copper_summary.csv | AM17: COD_Summary | AN17: 4 | AO17: Retained for identity, source, scope, or design traceability.
A18: 18 | B18: Source_Register row 18 | C18: COD-SUM-MAT-CU3SN-ETA | D18: MAT-CU3SN-ETA | E18: Cu3Sn — Eta copper-tin intermetallic | H18: COD | I18: CAT-COD-CU · cod_copper_summary.csv | J18: COD_Summary · row 5 | L18: included_supporting_evidence | M18: curated COD identity summary; crystallographic identity support | N18: Eta copper-tin intermetallic | O18: COD catalog | P18: crystal identity summary | R18: records | V18: space group None; None | W18: CAT-COD-CU | X18: COD-SUM-MAT-CU3SN-ETA | Y18: eta-tin copper | Z18: supplier alias | AA18: not resolved across AFLOW, NIST, and supplier evidence | AB18: Known source label(s) for this canonical material; current evidence row uses the canonical ID. | AC18: No | AL18: data/data/catalog/cod_copper_summary.csv | AM18: COD_Summary | AN18: 5 | AO18: Retained for identity, source, scope, or design traceability.
A19: 19 | B19: Source_Register row 19 | C19: OQMD-MAT-CU2O-CUPRITE | D19: MAT-CU2O-CUPRITE | E19: Cu2O — Copper(I) oxide / cuprite | H19: OQMD | I19: CAT-OQMD · oqmd_copper_targets.csv | J19: OQMD_Targets · row 2 | L19: included_supporting_evidence | M19: computed OQMD formation/stability values; not measured release evidence | N19: Copper(I) oxide / cuprite | O19: OQMD catalog | P19: computed formation/stability target | Q19: 0.00044117667 | R19: eV/atom | V19: space group Pn-3m | W19: CAT-OQMD | X19: OQMD-MAT-CU2O-CUPRITE | Y19: Cu^1O | Z19: legacy oxidation-state notation | AA19: comparator/identity context; not a July release material | AB19: Known source label(s) for this canonical material; current evidence row uses the canonical ID. | AC19: No | AL19: data/data/catalog/oqmd_copper_targets.csv | AM19: OQMD_Targets | AN19: 2 | AO19: Retained for identity, source, scope, or design traceability.
A20: 20 | B20: Source_Register row 20 | C20: OQMD-MAT-CUO-TENORITE | D20: MAT-CUO-TENORITE | E20: CuO — Copper(II) oxide / tenorite | H20: OQMD | I20: CAT-OQMD · oqmd_copper_targets.csv | J20: OQMD_Targets · row 3 | L20: included_supporting_evidence | M20: computed OQMD formation/stability values; not measured release evidence | N20: Copper(II) oxide / tenorite | O20: OQMD catalog | P20: computed formation/stability target | Q20: 0.026504872 | R20: eV/atom | V20: space group C2/c | W20: CAT-OQMD | X20: OQMD-MAT-CUO-TENORITE | Y20: Cu^2O | Z20: legacy oxidation-state notation | AA20: comparator/identity context; not a July release material | AB20: Known source label(s) for this canonical material; current evidence row uses the canonical ID. | AC20: No | AL20: data/data/catalog/oqmd_copper_targets.csv | AM20: OQMD_Targets | AN20: 3 | AO20: Retained for identity, source, scope, or design traceability.
A21: 21 | B21: Source_Register row 21 | C21: OQMD-MAT-CU3SN-ETA | D21: MAT-CU3SN-ETA | E21: Cu3Sn — Eta copper-tin intermetallic | H21: OQMD | I21: CAT-OQMD · oqmd_copper_targets.csv | J21: OQMD_Targets · row 4 | L21: included_supporting_evidence | M21: computed OQMD formation/stability values; not measured release evidence | N21: Eta copper-tin intermetallic | O21: OQMD catalog | P21: computed formation/stability target | Q21: 0.071482468 | R21: eV/atom | V21: space group Fm-3m | W21: CAT-OQMD | X21: OQMD-MAT-CU3SN-ETA | Y21: eta-tin copper | Z21: supplier alias | AA21: not resolved across AFLOW, NIST, and supplier evidence | AB21: Known source label(s) for this canonical material; current evidence row uses the canonical ID. | AC21: No | AL21: data/data/catalog/oqmd_copper_targets.csv | AM21: OQMD_Targets | AN21: 4 | AO21: Retained for identity, source, scope, or design traceability.
A22: 22 | B22: Source_Register row 22 | C22: OQMD-MAT-AL2CU-THETA | D22: MAT-AL2CU-THETA | E22: Al2Cu — Theta Al2Cu | H22: OQMD | I22: CAT-OQMD · oqmd_copper_targets.csv | J22: OQMD_Targets · row 5 | L22: included_supporting_evidence | M22: computed OQMD formation/stability values; not measured release evidence | N22: Theta Al2Cu | O22: OQMD catalog | P22: computed formation/stability target | Q22: 0.018707923 | R22: eV/atom | V22: space group Fmmm | W22: CAT-OQMD | X22: OQMD-MAT-AL2CU-THETA | Z22: none | AA22: comparator/identity context; not a July release material | AB22: No alias or oxidation notation appears on this evidence row. | AC22: No | AL22: data/data/catalog/oqmd_copper_targets.csv | AM22: OQMD_Targets | AN22: 5 | AO22: Retained for identity, source, scope, or design traceability.
A23: 23 | B23: Source_Register row 23 | C23: OQMD-MAT-ALCU3-GAMMA | D23: MAT-ALCU3-GAMMA | E23: AlCu3 — Gamma AlCu3 | H23: OQMD | I23: CAT-OQMD · oqmd_copper_targets.csv | J23: OQMD_Targets · row 6 | L23: included_supporting_evidence | M23: computed OQMD formation/stability values; not measured release evidence | N23: Gamma AlCu3 | O23: OQMD catalog | P23: computed formation/stability target | Q23: 0.011023996 | R23: eV/atom | V23: space group Pm-3m | W23: CAT-OQMD | X23: OQMD-MAT-ALCU3-GAMMA | Z23: none | AA23: comparator/identity context; not a July release material | AB23: No alias or oxidation notation appears on this evidence row. | AC23: No | AL23: data/data/catalog/oqmd_copper_targets.csv | AM23: OQMD_Targets | AN23: 6 | AO23: Retained for identity, source, scope, or design traceability.
A24: 24 | B24: Source_Register row 24 | C24: OQMD-MAT-ZNCU-BETA | D24: MAT-ZNCU-BETA | E24: ZnCu — Beta ZnCu | H24: OQMD | I24: CAT-OQMD · oqmd_copper_targets.csv | J24: OQMD_Targets · row 7 | L24: included_supporting_evidence | M24: computed OQMD formation/stability values; not measured release evidence | N24: Beta ZnCu | O24: OQMD catalog | P24: computed formation/stability target | Q24: 0.0038489522 | R24: eV/atom | V24: space group Pm-3m | W24: CAT-OQMD | X24: OQMD-MAT-ZNCU-BETA | Z24: none | AA24: comparator/identity context; not a July release material | AB24: No alias or oxidation notation appears on this evidence row. | AC24: No | AL24: data/data/catalog/oqmd_copper_targets.csv | AM24: OQMD_Targets | AN24: 7 | AO24: Retained for identity, source, scope, or design traceability.
A25: 25 | B25: Source_Register row 25 | C25: OQMD-MAT-CUAU-L10 | D25: MAT-CUAU-L10 | E25: CuAu — L1_0 CuAu | H25: OQMD | I25: CAT-OQMD · oqmd_copper_targets.csv | J25: OQMD_Targets · row 8 | L25: included_supporting_evidence | M25: computed OQMD formation/stability values; not measured release evidence | N25: L1_0 CuAu | O25: OQMD catalog | P25: computed formation/stability target | Q25: 2.547e-05 | R25: eV/atom | V25: space group P4/mmm | W25: CAT-OQMD | X25: OQMD-MAT-CUAU-L10 | Z25: none | AA25: comparator/identity context; not a July release material | AB25: No alias or oxidation notation appears on this evidence row. | AC25: No | AL25: data/data/catalog/oqmd_copper_targets.csv | AM25: OQMD_Targets | AN25: 8 | AO25: Retained for identity, source, scope, or design traceability.
A26: 26 | B26: Source_Register row 26 | C26: LIT-0726-01 | D26: MAT-CU-C101 | E26: Cu — C10100 OFHC copper | H26: Literature | I26: 10.1007/BF01174717 · property_pull.csv | J26: Literature · row 2 | K26: 10.1007/BF01174717 | L26: included_unverified_support_only | M26: literature property claim; unverified and subordinate to measurement | N26: C10100 OFHC copper | O26: literature | P26: electrical_conductivity_iacs | Q26: 101 | R26: percent_IACS | W26: 10.1007/BF01174717 | X26: LIT-0726-01 | Y26: C10100 OFHC | Z26: supplier alias | AA26: resolved to elemental Cu structure; supplier grade remains supplier-controlled | AB26: Known source label(s) for this canonical material; current evidence row uses the canonical ID. | AC26: No | AL26: data/data/literature/property_pull.csv | AM26: Literature | AN26: 2 | AO26: Literature-only evidence is unverified and cannot replace measured evidence. | AP26: Thermal expansion of copper
A27: 27 | B27: Source_Register row 27 | C27: LIT-0726-02 | D27: MAT-CU-HBPLATE | E27: Cu — Hybrid-bond electroplated copper | H27: Literature | I27: 10.18434/mds2-4076 · property_pull.csv | J27: Literature · row 3 | K27: 10.18434/mds2-4076 | L27: included_unverified_support_only | M27: literature/reference value; incomplete protocol-condition metadata; unverified | N27: Hybrid-bond electroplated copper | O27: literature | P27: yield_strength | Q27: 228 | R27: MPa | W27: 10.18434/mds2-4076 | X27: LIT-0726-02 | Y27: HB electro-Cu | Z27: supplier alias | AA27: resolved at supplier/process and NIST application-family level; no process-specific AFLOW record | AB27: Known source label(s) for this canonical material; current evidence row uses the canonical ID. | AC27: No | AL27: data/data/literature/property_pull.csv | AM27: Literature | AN27: 3 | AO27: Literature-only evidence is unverified and cannot replace measured evidence. | AP27: Elastic-plastic indentation on hybrid bonding copper
A28: 28 | B28: Source_Register row 28 | C28: LIT-0726-03 | D28: MAT-CU-C101 | E28: Cu — C10100 OFHC copper | H28: Literature | I28: 10.1063/1.1728392 · property_pull.csv | J28: Literature · row 4 | K28: 10.1063/1.1728392 | L28: included_unverified_support_only | M28: literature-only; unverified | N28: C10100 OFHC copper | O28: literature | P28: coefficient_thermal_expansion | Q28: 16.7 | R28: um_mK | W28: 10.1063/1.1728392 | X28: LIT-0726-03 | Y28: C10100 OFHC | Z28: supplier alias | AA28: resolved to elemental Cu structure; supplier grade remains supplier-controlled | AB28: Known source label(s) for this canonical material; current evidence row uses the canonical ID. | AC28: No | AL28: data/data/literature/property_pull.csv | AM28: Literature | AN28: 4 | AO28: Literature-only evidence is unverified and cannot replace measured evidence. | AP28: Copper lattice expansion study
A29: 29 | B29: Source_Register row 29 | C29: LIT-0726-04 | D29: MAT-CU-HBPLATE | E29: Cu — Hybrid-bond electroplated copper | H29: Literature | I29: 10.1109/ECTC.2026.cu-hb · property_pull.csv | J29: Literature · row 5 | K29: 10.1109/ECTC.2026.cu-hb | L29: included_unverified_support_only | M29: literature-only; unverified | N29: Hybrid-bond electroplated copper | O29: literature | P29: electromigration_activation_energy | Q29: 0.86 | R29: eV | W29: 10.1109/ECTC.2026.cu-hb | X29: LIT-0726-04 | Y29: HB electro-Cu | Z29: supplier alias | AA29: resolved at supplier/process and NIST application-family level; no process-specific AFLOW record | AB29: Known source label(s) for this canonical material; current evidence row uses the canonical ID. | AC29: No | AL29: data/data/literature/property_pull.csv | AM29: Literature | AN29: 5 | AO29: Literature-only evidence is unverified and cannot replace measured evidence. | AP29: Advanced packaging copper interconnect aging
A30: 30 | B30: Source_Register row 30 | C30: LIT-0726-05 | D30: MAT-CUSO4-CUPRIC | E30: CuSO4 — Cupric sulfate | H30: Literature | I30: PubChem CID 24462 · property_pull.csv | J30: Literature · row 6 | K30: PubChem CID 24462 | L30: included_unverified_support_only | M30: identity-only; not property evidence | N30: Cupric sulfate | O30: literature | P30: compound_canonicalized | Q30: 1 | R30: flag | W30: PubChem CID 24462 | X30: LIT-0726-05 | Y30: cupric sulfate | Z30: supplier alias | AA30: comparator/identity context; not a July release material | AB30: Known source label(s) for this canonical material; current evidence row uses the canonical ID. | AC30: No | AL30: data/data/literature/property_pull.csv | AM30: Literature | AN30: 6 | AO30: Literature-only evidence is unverified and cannot replace measured evidence. | AP30: Copper sulfate canonical compound
A31: 31 | B31: Source_Register row 31 | C31: LIT-0726-06 | D31: MAT-YBCO-CUPRATE | E31: Y-Ba-Cu-O — YBCO cuprate | H31: Literature | I31: 10.18434/T4KP8J · property_pull.csv | J31: Literature · row 7 | K31: 10.18434/T4KP8J | L31: excluded | M31: domain decoy; excluded | N31: YBCO cuprate | O31: literature | P31: superconducting_context | Q31: 1 | R31: flag | W31: 10.18434/T4KP8J | X31: LIT-0726-06 | Z31: none | AA31: comparator/identity context; not a July release material | AB31: No alias or oxidation notation appears on this evidence row. | AC31: No | AL31: data/data/literature/property_pull.csv | AM31: Literature | AN31: 7 | AO31: Rejected false positive or domain decoy. | AP31: NIST HTS cuprate database
A32: 32 | B32: Source_Register row 32 | C32: LIT-0726-07 | D32: MAT-CU-C101 | E32: Cu — C10100 OFHC copper | H32: Literature | I32: arXiv:3d-ic-packaging-page · property_pull.csv | J32: Literature · row 8 | K32: arXiv:3d-ic-packaging-page | L32: excluded | M32: title/scope false positive; rejected | N32: C10100 OFHC copper | O32: literature | P32: grid_support | Q32: 1 | R32: flag | W32: arXiv:3d-ic-packaging-page | X32: LIT-0726-07 | Y32: C10100 OFHC | Z32: supplier alias | AA32: resolved to elemental Cu structure; supplier grade remains supplier-controlled | AB32: Known source label(s) for this canonical material; current evidence row uses the canonical ID. | AC32: No | AL32: data/data/literature/property_pull.csv | AM32: Literature | AN32: 8 | AO32: Rejected false positive or domain decoy. | AP32: Copper grid mentioned in packaging metadata
A33: 33 | B33: Source_Register row 33 | C33: LR-COND-0726-01 | D33: MAT-CU-C101 | E33: Cu — C10100 OFHC copper | F33: LOT-CU-2607-A | G33: TRACE-HDI-110 | H33: Laboratory measurement | I33: LAB-COND · conductivity_panel_tests.csv | J33: Electrical_Thermal · row 2 | L33: included_measurement_not_protocol_matchable | M33: measured value; PROTO-CU-77 has no percent-IACS condition row | N33: C10100 OFHC copper | O33: laboratory measurement | P33: electrical_conductivity_iacs | Q33: 101.52 | R33: percent_IACS | S33: 23 | T33: 101.3 | U33: 0.001 | V33: LM-CU-07 | W33: LAB-COND | X33: LR-COND-0726-01 | Y33: C10100 OFHC | Z33: supplier alias | AA33: resolved to elemental Cu structure; supplier grade remains supplier-controlled | AB33: Known source label(s) for this canonical material; current evidence row uses the canonical ID. | AC33: No | AL33: data/data/lab_reports/conductivity_panel_tests.csv | AM33: Electrical_Thermal | AN33: 2 | AO33: Measured record retained; PROTO-CU-77 does not define percent-IACS test conditions. | AP33: T=23.0 C; P=101.3 kPa; strain=0.001
A34: 34 | B34: Source_Register row 34 | C34: LR-COND-0726-02 | D34: MAT-CU-C101 | E34: Cu — C10100 OFHC copper | F34: LOT-CU-2607-A | G34: TRACE-HDI-110 | H34: Laboratory measurement | I34: LAB-COND · conductivity_panel_tests.csv | J34: Electrical_Thermal · row 3 | L34: included_measured_evidence | M34: measured value | N34: C10100 OFHC copper | O34: laboratory measurement | P34: resistivity_20c | Q34: 1.699 | R34: uohm_cm | S34: 20 | T34: 101.3 | U34: 0.001 | V34: LM-CU-07 | W34: LAB-COND | X34: LR-COND-0726-02 | Y34: C10100 OFHC | Z34: supplier alias | AA34: resolved to elemental Cu structure; supplier grade remains supplier-controlled | AB34: Known source label(s) for this canonical material; current evidence row uses the canonical ID. | AC34: No | AL34: data/data/lab_reports/conductivity_panel_tests.csv | AM34: Electrical_Thermal | AN34: 3 | AO34: Measured evidence retained under its recorded conditions and scope. | AP34: T=20.0 C; P=101.3 kPa; strain=0.001
A35: 35 | B35: Source_Register row 35 | C35: LR-COND-0726-03 | D35: MAT-CU-WIRE | E35: Cu (supplier grade claim) — E-Cu58 copper wire | F35: LOT-CU-2607-B | G35: TRACE-HB-180 | H35: Laboratory measurement | I35: LAB-COND · conductivity_panel_tests.csv | J35: Electrical_Thermal · row 4 | L35: excluded_from_property_comparison_pending_identity | M35: measured value; PROTO-CU-77 has no percent-IACS condition row | N35: E-Cu58 copper wire | O35: laboratory measurement | P35: electrical_conductivity_iacs | Q35: 100.94 | R35: percent_IACS | S35: 23 | T35: 101.3 | U35: 0.001 | V35: LM-CU-07 | W35: LAB-COND | X35: LR-COND-0726-03 | Y35: E-Cu58 | Z35: supplier alias | AA35: not resolved across AFLOW, NIST, and supplier evidence | AB35: Known source label(s) for this canonical material; current evidence row uses the canonical ID. | AC35: No | AL35: data/data/lab_reports/conductivity_panel_tests.csv | AM35: Electrical_Thermal | AN35: 4 | AO35: Canonical alias exists, but identity is not resolved across AFLOW, NIST, and supplier evidence; retain the measured record without using it in property comparison. | AP35: T=23.0 C; P=101.3 kPa; strain=0.001
A36: 36 | B36: Source_Register row 36 | C36: LR-COND-0726-04 | D36: MAT-CU-HBPLATE | E36: Cu — Hybrid-bond electroplated copper | F36: LOT-CU-2607-C | G36: TRACE-HB-205 | H36: Laboratory measurement | I36: LAB-COND · conductivity_panel_tests.csv | J36: Electrical_Thermal · row 5 | L36: included_measurement_not_protocol_matchable | M36: measured value; PROTO-CU-77 has no percent-IACS condition row | N36: Hybrid-bond electroplated copper | O36: laboratory measurement | P36: electrical_conductivity_iacs | Q36: 100.9 | R36: percent_IACS | S36: 23 | T36: 101.3 | U36: 0.001 | V36: LM-CU-07 | W36: LAB-COND | X36: LR-COND-0726-04 | Y36: HB electro-Cu | Z36: supplier alias | AA36: resolved at supplier/process and NIST application-family level; no process-specific AFLOW record | AB36: Known source label(s) for this canonical material; current evidence row uses the canonical ID. | AC36: No | AL36: data/data/lab_reports/conductivity_panel_tests.csv | AM36: Electrical_Thermal | AN36: 5 | AO36: Measured record retained; PROTO-CU-77 does not define percent-IACS test conditions. | AP36: T=23.0 C; P=101.3 kPa; strain=0.001
A37: 37 | B37: Source_Register row 37 | C37: LR-COND-0726-04D | D37: MAT-CU-HBPLATE | E37: Cu — Hybrid-bond electroplated copper | F37: LOT-CU-2607-C | G37: TRACE-HB-205 | H37: Laboratory measurement | I37: LAB-COND · conductivity_panel_tests.csv | J37: Electrical_Thermal · row 6 | L37: excluded_duplicate | M37: duplicate synchronized record; do not double count; PROTO-CU-77 has no percent-IACS condition row | N37: Hybrid-bond electroplated copper | O37: laboratory measurement | P37: electrical_conductivity_iacs | Q37: 100.9 | R37: percent_IACS | S37: 23 | T37: 101.3 | U37: 0.001 | V37: LM-CU-07 | W37: LAB-COND | X37: LR-COND-0726-04D | Y37: HB electro-Cu | Z37: supplier alias | AA37: resolved at supplier/process and NIST application-family level; no process-specific AFLOW record | AB37: Known source label(s) for this canonical material; current evidence row uses the canonical ID. | AC37: No | AL37: data/data/lab_reports/conductivity_panel_tests.csv | AM37: Electrical_Thermal | AN37: 6 | AO37: Retained for traceability; excluded from counts and comparisons. | AP37: T=23.0 C; P=101.3 kPa; strain=0.001
A38: 38 | B38: Source_Register row 38 | C38: LR-COND-0726-05 | D38: MAT-CU-HBPLATE | E38: Cu — Hybrid-bond electroplated copper | F38: LOT-CU-2607-D | G38: TRACE-HB-225 | H38: Laboratory measurement | I38: LAB-COND · conductivity_panel_tests.csv | J38: Electrical_Thermal · row 7 | L38: included_measurement_not_protocol_matchable | M38: measured value; PROTO-CU-77 has no percent-IACS condition row | N38: Hybrid-bond electroplated copper | O38: laboratory measurement | P38: electrical_conductivity_iacs | Q38: 97.85 | R38: percent_IACS | S38: 23 | T38: 101.3 | U38: 0.001 | V38: LM-CU-07 | W38: LAB-COND | X38: LR-COND-0726-05 | Y38: HB electro-Cu | Z38: supplier alias | AA38: resolved at supplier/process and NIST application-family level; no process-specific AFLOW record | AB38: Known source label(s) for this canonical material; current evidence row uses the canonical ID. | AC38: No | AL38: data/data/lab_reports/conductivity_panel_tests.csv | AM38: Electrical_Thermal | AN38: 7 | AO38: Measured record retained; PROTO-CU-77 does not define percent-IACS test conditions. | AP38: T=23.0 C; P=101.3 kPa; strain=0.001
A39: 39 | B39: Source_Register row 39 | C39: LR-COND-0726-06 | D39: MAT-CU-HBPLATE | E39: Cu — Hybrid-bond electroplated copper | F39: LOT-CU-2607-D | G39: TRACE-HB-225 | H39: Laboratory measurement | I39: LAB-COND · conductivity_panel_tests.csv | J39: Electrical_Thermal · row 8 | L39: included_measured_evidence | M39: measured value | N39: Hybrid-bond electroplated copper | O39: laboratory measurement | P39: resistivity_20c | Q39: 1.762 | R39: uohm_cm | S39: 20 | T39: 101.3 | U39: 0.001 | V39: LM-CU-07 | W39: LAB-COND | X39: LR-COND-0726-06 | Y39: HB electro-Cu | Z39: supplier alias | AA39: resolved at supplier/process and NIST application-family level; no process-specific AFLOW record | AB39: Known source label(s) for this canonical material; current evidence row uses the canonical ID. | AC39: No | AL39: data/data/lab_reports/conductivity_panel_tests.csv | AM39: Electrical_Thermal | AN39: 8 | AO39: Measured evidence retained under its recorded conditions and scope. | AP39: T=20.0 C; P=101.3 kPa; strain=0.001
A40: 40 | B40: Source_Register row 40 | C40: LR-COND-0726-07 | D40: MAT-CU3SN-ETA | E40: Cu3Sn — Eta copper-tin intermetallic | F40: LOT-CU-2607-E | G40: TRACE-BGA-320 | H40: Laboratory measurement | I40: LAB-COND · conductivity_panel_tests.csv | J40: Electrical_Thermal · row 9 | L40: excluded_from_property_comparison_pending_identity | M40: measured value; PROTO-CU-77 has no percent-IACS condition row | N40: Eta copper-tin intermetallic | O40: laboratory measurement | P40: electrical_conductivity_iacs | Q40: 68.4 | R40: percent_IACS | S40: 23 | T40: 101.3 | U40: 0.001 | V40: LM-CU-07 | W40: LAB-COND | X40: LR-COND-0726-07 | Y40: eta-tin copper | Z40: supplier alias | AA40: not resolved across AFLOW, NIST, and supplier evidence | AB40: Known source label(s) for this canonical material; current evidence row uses the canonical ID. | AC40: No | AL40: data/data/lab_reports/conductivity_panel_tests.csv | AM40: Electrical_Thermal | AN40: 9 | AO40: Canonical alias exists, but identity is not resolved across AFLOW, NIST, and supplier evidence; retain the measured record without using it in property comparison. | AP40: T=23.0 C; P=101.3 kPa; strain=0.001
...

Sheet Calculations
A1: A. Protocol-condition matched measured evidence
A3: calc_id | B3: record_id | C3: material_id | D3: property | E3: value | F3: unit | G3: temperature_C | H3: pressure_kPa | I3: strain_rate_s-1 | J3: method | K3: protocol_rule | L3: condition_match | M3: priority_result | N3: input_anchor | O3: source_anchor | P3: selected_value | Q3: selection_status | R3: visible_formula_logic
A4: CM-01 | B4: LR-COND-0726-02 | C4: =Inputs!$D$34 -> MAT-CU-C101 | D4: =Inputs!$P$34 -> resistivity_20c | E4: =Inputs!$Q$34 -> 1.699 | F4: =Inputs!$R$34 -> uohm_cm | G4: =Inputs!$S$34 -> 20 | H4: =Inputs!$T$34 -> 101.3 | I4: =Inputs!$U$34 -> 0.001 | J4: =Inputs!$V$34 -> LM-CU-07 | K4: 20 C reference; ambient pressure | L4: =AND(G4=20,H4<>"") -> TRUE | M4: Selected measured value | N4: Inputs row 34 | O4: =Inputs!$I$34 -> LAB-COND · conductivity_panel_tests.csv | P4: =IF(AND(L4=TRUE(),M4="Selected measured value"),E4,NA()) -> 1.699 | Q4: =IF(ISNUMBER(P4),"SELECTED","EXCLUDED") -> SELECTED | R4: IF(condition_match AND measured-priority, reported value, NA)
A5: CM-02 | B5: LR-COND-0726-06 | C5: =Inputs!$D$39 -> MAT-CU-HBPLATE | D5: =Inputs!$P$39 -> resistivity_20c | E5: =Inputs!$Q$39 -> 1.762 | F5: =Inputs!$R$39 -> uohm_cm | G5: =Inputs!$S$39 -> 20 | H5: =Inputs!$T$39 -> 101.3 | I5: =Inputs!$U$39 -> 0.001 | J5: =Inputs!$V$39 -> LM-CU-07 | K5: 20 C reference; ambient pressure | L5: =AND(G5=20,H5<>"") -> TRUE | M5: Selected measured value | N5: Inputs row 39 | O5: =Inputs!$I$39 -> LAB-COND · conductivity_panel_tests.csv | P5: =IF(AND(L5=TRUE(),M5="Selected measured value"),E5,NA()) -> 1.762 | Q5: =IF(ISNUMBER(P5),"SELECTED","EXCLUDED") -> SELECTED | R5: IF(condition_match AND measured-priority, reported value, NA)
A6: CM-03 | B6: LR-THERM-0726-01 | C6: =Inputs!$D$41 -> MAT-CU-C101 | D6: =Inputs!$P$41 -> thermal_conductivity | E6: =Inputs!$Q$41 -> 392.6 | F6: =Inputs!$R$41 -> W_mK | G6: =Inputs!$S$41 -> 23 | H6: =Inputs!$T$41 -> 101.3 | I6: =Inputs!$U$41 -> 0.001 | J6: =Inputs!$V$41 -> LM-CU-07 | K6: 23 +/- 2 C; 101.3 +/- 5 kPa | L6: =AND(G6>=21,G6<=25,H6>=96.3,H6<=106.3) -> TRUE | M6: Selected measured value | N6: Inputs row 41 | O6: =Inputs!$I$41 -> LAB-COND · conductivity_panel_tests.csv | P6: =IF(AND(L6=TRUE(),M6="Selected measured value"),E6,NA()) -> 392.6 | Q6: =IF(ISNUMBER(P6),"SELECTED","EXCLUDED") -> SELECTED | R6: IF(condition_match AND measured-priority, reported value, NA)
A7: CM-04 | B7: LR-THERM-0726-02 | C7: =Inputs!$D$42 -> MAT-CU-HBPLATE | D7: =Inputs!$P$42 -> thermal_conductivity | E7: =Inputs!$Q$42 -> 386.8 | F7: =Inputs!$R$42 -> W_mK | G7: =Inputs!$S$42 -> 23 | H7: =Inputs!$T$42 -> 101.3 | I7: =Inputs!$U$42 -> 0.001 | J7: =Inputs!$V$42 -> LM-CU-07 | K7: 23 +/- 2 C; 101.3 +/- 5 kPa | L7: =AND(G7>=21,G7<=25,H7>=96.3,H7<=106.3) -> TRUE | M7: Selected measured value | N7: Inputs row 42 | O7: =Inputs!$I$42 -> LAB-COND · conductivity_panel_tests.csv | P7: =IF(AND(L7=TRUE(),M7="Selected measured value"),E7,NA()) -> 386.8 | Q7: =IF(ISNUMBER(P7),"SELECTED","EXCLUDED") -> SELECTED | R7: IF(condition_match AND measured-priority, reported value, NA)
A8: CM-05 | B8: MECH-0726-01 | C8: =Inputs!$D$43 -> MAT-CU-HBPLATE | D8: =Inputs!$P$43 -> yield_strength | E8: =Inputs!$Q$43 -> 219 | F8: =Inputs!$R$43 -> MPa | G8: =Inputs!$S$43 -> 23 | H8: =Inputs!$T$43 -> 101.3 | I8: =Inputs!$U$43 -> 0.001 | J8: =Inputs!$V$43 -> IIT-AFM | K8: 23 +/- 2 C; 101.3 +/- 5 kPa; 1.0E-3 s^-1 | L8: =AND(G8>=21,G8<=25,H8>=96.3,H8<=106.3,I8=0.001) -> TRUE | M8: Selected measured value | N8: Inputs row 43 | O8: =Inputs!$I$43 -> LAB-MECH · mechanical_property_runs.csv | P8: =IF(AND(L8=TRUE(),M8="Selected measured value"),E8,NA()) -> 219 | Q8: =IF(ISNUMBER(P8),"SELECTED","EXCLUDED") -> SELECTED | R8: IF(condition_match AND measured-priority, reported value, NA)
A9: CM-06 | B9: MECH-0726-03 | C9: =Inputs!$D$45 -> MAT-CU-HBPLATE | D9: =Inputs!$P$45 -> hardness | E9: =Inputs!$Q$45 -> 0.92 | F9: =Inputs!$R$45 -> GPa | G9: =Inputs!$S$45 -> 23 | H9: =Inputs!$T$45 -> 101.3 | I9: =Inputs!$U$45 -> 0.001 | J9: =Inputs!$V$45 -> IIT-AFM | K9: 23 +/- 2 C; 101.3 +/- 5 kPa; 1.0E-3 s^-1 | L9: =AND(G9>=21,G9<=25,H9>=96.3,H9<=106.3,I9=0.001) -> TRUE | M9: Selected measured value | N9: Inputs row 45 | O9: =Inputs!$I$45 -> LAB-MECH · mechanical_property_runs.csv | P9: =IF(AND(L9=TRUE(),M9="Selected measured value"),E9,NA()) -> 0.92 | Q9: =IF(ISNUMBER(P9),"SELECTED","EXCLUDED") -> SELECTED | R9: IF(condition_match AND measured-priority, reported value, NA)
A10: CM-07 | B10: MECH-0726-04 | C10: =Inputs!$D$46 -> MAT-CU-C101 | D10: =Inputs!$P$46 -> yield_strength | E10: =Inputs!$Q$46 -> 205 | F10: =Inputs!$R$46 -> MPa | G10: =Inputs!$S$46 -> 23 | H10: =Inputs!$T$46 -> 101.3 | I10: =Inputs!$U$46 -> 0.001 | J10: =Inputs!$V$46 -> tensile_microcoupon | K10: 23 +/- 2 C; 101.3 +/- 5 kPa; 1.0E-3 s^-1 | L10: =AND(G10>=21,G10<=25,H10>=96.3,H10<=106.3,I10=0.001) -> TRUE | M10: Selected measured value | N10: Inputs row 46 | O10: =Inputs!$I$46 -> LAB-MECH · mechanical_property_runs.csv | P10: =IF(AND(L10=TRUE(),M10="Selected measured value"),E10,NA()) -> 205 | Q10: =IF(ISNUMBER(P10),"SELECTED","EXCLUDED") -> SELECTED | R10: IF(condition_match AND measured-priority, reported value, NA)
A13: B. Like-for-like property comparisons only
A14: comparison_id | B14: property | C14: material_A | D14: value_A | E14: material_B | F14: value_B | G14: unit | H14: difference_B_minus_A | I14: percent_difference | J14: condition_basis
A15: CMP-01 | B15: resistivity_20c | C15: =C4 -> MAT-CU-C101 | D15: =E4 -> 1.699 | E15: =C5 -> MAT-CU-HBPLATE | F15: =E5 -> 1.762 | G15: =F4 -> uohm_cm | H15: =F15-D15 -> 0.063 | I15: =IFERROR(H15/D15,"") -> 0.037080636 | J15: 20 C reference
A16: CMP-02 | B16: thermal_conductivity | C16: =C6 -> MAT-CU-C101 | D16: =E6 -> 392.6 | E16: =C7 -> MAT-CU-HBPLATE | F16: =E7 -> 386.8 | G16: =F6 -> W_mK | H16: =F16-D16 -> -5.8 | I16: =IFERROR(H16/D16,"") -> -0.014773306 | J16: 23 C; 101.3 kPa
A19: C. LOT-CU-2607-D trace resistance at service temperature
A20: calc_id | B20: resistivity_uohm_cm | C20: length_mm | D20: width_um | E20: average_thickness_um | F20: reference_temp_C | G20: service_temp_C | H20: alpha_per_C | I20: R20_mOhm | J20: Rservice_mOhm | K20: limit_mOhm | L20: margin_mOhm | M20: selected_property_source | N20: visible_formula_logic
A21: RES-D | B21: =P5 -> 1.762 | C21: =Inputs!$AW$56 -> 50 | D21: =Inputs!$AX$56 -> 400 | E21: =Inputs!$AY$73 -> 17.8 | F21: =Assumption_ReferenceTemperature -> 20 | G21: =Assumption_ServiceTemperature -> 85 | H21: =Assumption_TemperatureCoefficient -> 0.00393 | I21: =B21*0.00000001*(C21*0.001)/((D21*0.000001)*(E21*0.000001))*1000 -> 123.73596 | J21: =I21*(1+H21*(G21-F21)) -> 155.3443 | K21: =Control_MaxTraceResistance -> 160 | L21: =K21-J21 -> 4.6556952 | M21: CM-02 selected_value (P5) | N21: Rservice = selected resistivity × geometry/thickness × [1 + alpha × (Tservice − Tref)]
A25: D. Chemistry — measured assay versus strictest applicable published limit
A26: chem_calc_id | B26: lot_id | C26: material_id | D26: impurity | E26: measured_ppm | F26: published_limit_ppm | G26: exception_document | H26: acceptance_limit_ppm | I26: margin_ppm | J26: result | K26: assay_input_anchor | L26: governing_sources
A27: CHEM-01 | B27: LOT-CU-2607-A | C27: =Inputs!$D$47 -> MAT-CU-C101 | D27: Oxygen | E27: =Inputs!$AQ$47 -> 3.2 | F27: =MIN(Inputs!$I$81) -> 8 | H27: =F27 -> 8 | I27: =H27-E27 -> 4.8 | J27: =IF(E27<=H27,"PASS","FAIL") -> PASS | K27: Inputs row 47 | L27: STD-CU-101; CQA-CU-772
A28: CHEM-02 | B28: LOT-CU-2607-A | C28: =Inputs!$D$47 -> MAT-CU-C101 | D28: Sulfur | E28: =Inputs!$AR$47 -> 2.1 | F28: =MIN(Inputs!$I$82,Inputs!$I$87) -> 4 | H28: =F28 -> 4 | I28: =H28-E28 -> 1.9 | J28: =IF(E28<=H28,"PASS","FAIL") -> PASS | K28: Inputs row 47 | L28: STD-CU-101; CQA-CU-772
A29: CHEM-03 | B29: LOT-CU-2607-A | C29: =Inputs!$D$47 -> MAT-CU-C101 | D29: Lead | E29: =Inputs!$AS$47 -> 1.2 | F29: =MIN(Inputs!$I$83) -> 5 | H29: =F29 -> 5 | I29: =H29-E29 -> 3.8 | J29: =IF(E29<=H29,"PASS","FAIL") -> PASS | K29: Inputs row 47 | L29: STD-CU-101; CQA-CU-772
A30: CHEM-04 | B30: LOT-CU-2607-A | C30: =Inputs!$D$47 -> MAT-CU-C101 | D30: Bismuth | E30: =Inputs!$AT$47 -> 0.4 | F30: =MIN(Inputs!$I$84) -> 3 | H30: =F30 -> 3 | I30: =H30-E30 -> 2.6 | J30: =IF(E30<=H30,"PASS","FAIL") -> PASS | K30: Inputs row 47 | L30: STD-CU-101; CQA-CU-772
A31: CHEM-05 | B31: LOT-CU-2607-A | C31: =Inputs!$D$47 -> MAT-CU-C101 | D31: Iron | E31: =Inputs!$AU$47 -> 4 | F31: =MIN(Inputs!$I$85) -> 10 | H31: =F31 -> 10 | I31: =H31-E31 -> 6 | J31: =IF(E31<=H31,"PASS","FAIL") -> PASS | K31: Inputs row 47 | L31: STD-CU-101; CQA-CU-772
A32: CHEM-06 | B32: LOT-CU-2607-A | C32: =Inputs!$D$47 -> MAT-CU-C101 | D32: Nickel | E32: =Inputs!$AV$47 -> 2 | F32: =MIN(Inputs!$I$86) -> 10 | H32: =F32 -> 10 | I32: =H32-E32 -> 8 | J32: =IF(E32<=H32,"PASS","FAIL") -> PASS | K32: Inputs row 47 | L32: STD-CU-101; CQA-CU-772
A33: CHEM-07 | B33: LOT-CU-2607-B | C33: =Inputs!$D$48 -> MAT-CU-WIRE | D33: Oxygen | E33: =Inputs!$AQ$48 -> 6.2 | F33: =MIN(Inputs!$I$81,Inputs!$I$96) -> 5 | G33: MAT-WVR-26-071 | H33: =Waiver_LOT_B_OxygenLimit -> 7 | I33: =H33-E33 -> 0.8 | J33: =IF(E33<=H33,"PASS","FAIL") -> PASS | K33: Inputs row 48 | L33: STD-CU-101; STD-CU-309; CQA-CU-772
A34: CHEM-08 | B34: LOT-CU-2607-B | C34: =Inputs!$D$48 -> MAT-CU-WIRE | D34: Sulfur | E34: =Inputs!$AR$48 -> 2.8 | F34: =MIN(Inputs!$I$82,Inputs!$I$97,Inputs!$I$87) -> 4 | H34: =F34 -> 4 | I34: =H34-E34 -> 1.2 | J34: =IF(E34<=H34,"PASS","FAIL") -> PASS | K34: Inputs row 48 | L34: STD-CU-101; STD-CU-309; CQA-CU-772
A35: CHEM-09 | B35: LOT-CU-2607-B | C35: =Inputs!$D$48 -> MAT-CU-WIRE | D35: Lead | E35: =Inputs!$AS$48 -> 0.9 | F35: =MIN(Inputs!$I$83,Inputs!$I$98) -> 5 | H35: =F35 -> 5 | I35: =H35-E35 -> 4.1 | J35: =IF(E35<=H35,"PASS","FAIL") -> PASS | K35: Inputs row 48 | L35: STD-CU-101; STD-CU-309; CQA-CU-772
A36: CHEM-10 | B36: LOT-CU-2607-B | C36: =Inputs!$D$48 -> MAT-CU-WIRE | D36: Bismuth | E36: =Inputs!$AT$48 -> 0.5 | F36: =MIN(Inputs!$I$84,Inputs!$I$99) -> 3 | H36: =F36 -> 3 | I36: =H36-E36 -> 2.5 | J36: =IF(E36<=H36,"PASS","FAIL") -> PASS | K36: Inputs row 48 | L36: STD-CU-101; STD-CU-309; CQA-CU-772
A37: CHEM-11 | B37: LOT-CU-2607-B | C37: =Inputs!$D$48 -> MAT-CU-WIRE | D37: Iron | E37: =Inputs!$AU$48 -> 4.8 | F37: =MIN(Inputs!$I$85,Inputs!$I$100) -> 10 | H37: =F37 -> 10 | I37: =H37-E37 -> 5.2 | J37: =IF(E37<=H37,"PASS","FAIL") -> PASS | K37: Inputs row 48 | L37: STD-CU-101; STD-CU-309; CQA-CU-772
A38: CHEM-12 | B38: LOT-CU-2607-B | C38: =Inputs!$D$48 -> MAT-CU-WIRE | D38: Nickel | E38: =Inputs!$AV$48 -> 2.4 | F38: =MIN(Inputs!$I$86,Inputs!$I$101) -> 5 | H38: =F38 -> 5 | I38: =H38-E38 -> 2.6 | J38: =IF(E38<=H38,"PASS","FAIL") -> PASS | K38: Inputs row 48 | L38: STD-CU-101; STD-CU-309; CQA-CU-772
A39: CHEM-13 | B39: LOT-CU-2607-C | C39: =Inputs!$D$49 -> MAT-CU-HBPLATE | D39: Oxygen | E39: =Inputs!$AQ$49 -> 4.8 | F39: =MIN(Inputs!$I$81,Inputs!$I$90) -> 6 | H39: =F39 -> 6 | I39: =H39-E39 -> 1.2 | J39: =IF(E39<=H39,"PASS","FAIL") -> PASS | K39: Inputs row 49 | L39: STD-CU-101; STD-CU-214; CQA-CU-772
A40: CHEM-14 | B40: LOT-CU-2607-C | C40: =Inputs!$D$49 -> MAT-CU-HBPLATE | D40: Sulfur | E40: =Inputs!$AR$49 -> 3.6 | F40: =MIN(Inputs!$I$82,Inputs!$I$91,Inputs!$I$87) -> 4 | H40: =F40 -> 4 | I40: =H40-E40 -> 0.4 | J40: =IF(E40<=H40,"PASS","FAIL") -> PASS | K40: Inputs row 49 | L40: STD-CU-101; STD-CU-214; CQA-CU-772
A41: CHEM-15 | B41: LOT-CU-2607-C | C41: =Inputs!$D$49 -> MAT-CU-HBPLATE | D41: Lead | E41: =Inputs!$AS$49 -> 3.2 | F41: =MIN(Inputs!$I$83,Inputs!$I$92) -> 5 | H41: =F41 -> 5 | I41: =H41-E41 -> 1.8 | J41: =IF(E41<=H41,"PASS","FAIL") -> PASS | K41: Inputs row 49 | L41: STD-CU-101; STD-CU-214; CQA-CU-772
A42: CHEM-16 | B42: LOT-CU-2607-C | C42: =Inputs!$D$49 -> MAT-CU-HBPLATE | D42: Bismuth | E42: =Inputs!$AT$49 -> 1.1 | F42: =MIN(Inputs!$I$84,Inputs!$I$93) -> 2.5 | H42: =F42 -> 2.5 | I42: =H42-E42 -> 1.4 | J42: =IF(E42<=H42,"PASS","FAIL") -> PASS | K42: Inputs row 49 | L42: STD-CU-101; STD-CU-214; CQA-CU-772
A43: CHEM-17 | B43: LOT-CU-2607-C | C43: =Inputs!$D$49 -> MAT-CU-HBPLATE | D43: Iron | E43: =Inputs!$AU$49 -> 5 | F43: =MIN(Inputs!$I$85,Inputs!$I$94) -> 8 | H43: =F43 -> 8 | I43: =H43-E43 -> 3 | J43: =IF(E43<=H43,"PASS","FAIL") -> PASS | K43: Inputs row 49 | L43: STD-CU-101; STD-CU-214; CQA-CU-772
A44: CHEM-18 | B44: LOT-CU-2607-C | C44: =Inputs!$D$49 -> MAT-CU-HBPLATE | D44: Nickel | E44: =Inputs!$AV$49 -> 3.9 | F44: =MIN(Inputs!$I$86,Inputs!$I$95) -> 8 | H44: =F44 -> 8 | I44: =H44-E44 -> 4.1 | J44: =IF(E44<=H44,"PASS","FAIL") -> PASS | K44: Inputs row 49 | L44: STD-CU-101; STD-CU-214; CQA-CU-772
A45: CHEM-19 | B45: LOT-CU-2607-D | C45: =Inputs!$D$50 -> MAT-CU-HBPLATE | D45: Oxygen | E45: =Inputs!$AQ$50 -> 4.6 | F45: =MIN(Inputs!$I$81,Inputs!$I$90) -> 6 | H45: =F45 -> 6 | I45: =H45-E45 -> 1.4 | J45: =IF(E45<=H45,"PASS","FAIL") -> PASS | K45: Inputs row 50 | L45: STD-CU-101; STD-CU-214; CQA-CU-772
A46: CHEM-20 | B46: LOT-CU-2607-D | C46: =Inputs!$D$50 -> MAT-CU-HBPLATE | D46: Sulfur | E46: =Inputs!$AR$50 -> 5 | F46: =MIN(Inputs!$I$82,Inputs!$I$91,Inputs!$I$87) -> 4 | H46: =F46 -> 4 | I46: =H46-E46 -> -1 | J46: =IF(E46<=H46,"PASS","FAIL") -> FAIL | K46: Inputs row 50 | L46: STD-CU-101; STD-CU-214; CQA-CU-772
A47: CHEM-21 | B47: LOT-CU-2607-D | C47: =Inputs!$D$50 -> MAT-CU-HBPLATE | D47: Lead | E47: =Inputs!$AS$50 -> 4.6 | F47: =MIN(Inputs!$I$83,Inputs!$I$92) -> 5 | H47: =F47 -> 5 | I47: =H47-E47 -> 0.4 | J47: =IF(E47<=H47,"PASS","FAIL") -> PASS | K47: Inputs row 50 | L47: STD-CU-101; STD-CU-214; CQA-CU-772
A48: CHEM-22 | B48: LOT-CU-2607-D | C48: =Inputs!$D$50 -> MAT-CU-HBPLATE | D48: Bismuth | E48: =Inputs!$AT$50 -> 1.2 | F48: =MIN(Inputs!$I$84,Inputs!$I$93) -> 2.5 | H48: =F48 -> 2.5 | I48: =H48-E48 -> 1.3 | J48: =IF(E48<=H48,"PASS","FAIL") -> PASS | K48: Inputs row 50 | L48: STD-CU-101; STD-CU-214; CQA-CU-772
...

Sheet Scenarios
A1: Scenario sensitivity — exceptions and service temperature
A3: scenario_id | B3: scenario_name | C3: service_temp_C | D3: PCN_thickness_applies | E3: waiver_B_oxygen_applies | F3: D_Rservice_mOhm | G3: D_resistance_limit_mOhm | H3: D_resistance_result | I3: D_thickness_limit_um | J3: D_thickness_result | K3: B_oxygen_limit_ppm | L3: B_oxygen_result | M3: scenario_note | N3: D_chemical_violation_flag | O3: D_electrical_violation_flag | P3: D_margin_under10_flag | Q3: D_exception_flag | R3: D_risk_score | S3: D_risk_status | T3: B_chemical_violation_flag | U3: B_exception_flag | V3: B_catalog_flag | W3: B_risk_score | X3: B_risk_status | Y3: D_score_delta_vs_current | Z3: B_score_delta_vs_current | AA3: visible_formula_logic | AB3: scenario_check
A4: SCN-01 | B4: Current controlled basis | C4: 85 | D4: Yes | E4: Yes | F4: =Calculations!$I$21*(1+Assumption_TemperatureCoefficient*(C4-Assumption_ReferenceTemperature)) -> 155.3443 | G4: =Control_MaxTraceResistance -> 160 | H4: =IF(F4<=G4,"PASS","FAIL") -> PASS | I4: =IF(D4="Yes",Control_PCNThicknessFloor,Control_BaseThicknessFloor) -> 17.5 | J4: =IF(Inputs!$AY$73>=I4,"PASS","FAIL") -> PASS | K4: =IF(E4="Yes",Waiver_LOT_B_OxygenLimit,Inputs!$I$96) -> 7 | L4: =IF(Inputs!$AQ$48<=K4,"PASS","FAIL") -> PASS | M4: Effective PCN and approved waiver | N4: 1 | O4: 1 | P4: =--(G4-F4<10) -> TRUE | Q4: =--(D4="Yes") -> TRUE | R4: =N4*RiskWeight_Chemical+O4*RiskWeight_Electrical+P4*RiskWeight_ResistanceMargin+Q4*RiskWeight_DocumentedException -> 88 | S4: =IF(R4>=RiskThreshold_Hold,"HOLD",IF(R4>=RiskThreshold_Conditional,"CONDITIONAL","RELEASE")) -> HOLD | T4: =--(L4="FAIL") -> FALSE | U4: =--(E4="Yes") -> TRUE | V4: 1 | W4: =T4*RiskWeight_Chemical+U4*RiskWeight_DocumentedException+V4*RiskWeight_CatalogQuality -> 12 | X4: =IF(W4>=RiskThreshold_Hold,"HOLD",IF(W4>=RiskThreshold_Conditional,"CONDITIONAL","RELEASE")) -> CONDITIONAL | Y4: =R4-$R$4 -> 0 | Z4: =W4-$W$4 -> 0 | AA4: Scenario results use the same assay, geometry, selected resistivity, configured weights, and thresholds as the current calculation. | AB4: =IF(AND(ISNUMBER(F4),ISNUMBER(G4),OR(H4="PASS",H4="FAIL"),ISNUMBER(I4),OR(J4="PASS",J4="FAIL"),ISNUMBER(K4),OR(L4="PASS",L4="FAIL"),ISNUMBER(R4),OR(S4="HOLD",S4="CONDITIONAL",S4="RELEASE"),ISNUMBER(W4),OR(X4="HOLD",X4="CONDITIONAL",X4="RELEASE")),"PASS","FAIL") -> PASS
A5: SCN-02 | B5: No oxygen waiver | C5: 85 | D5: Yes | E5: No | F5: =Calculations!$I$21*(1+Assumption_TemperatureCoefficient*(C5-Assumption_ReferenceTemperature)) -> 155.3443 | G5: =Control_MaxTraceResistance -> 160 | H5: =IF(F5<=G5,"PASS","FAIL") -> PASS | I5: =IF(D5="Yes",Control_PCNThicknessFloor,Control_BaseThicknessFloor) -> 17.5 | J5: =IF(Inputs!$AY$73>=I5,"PASS","FAIL") -> PASS | K5: =IF(E5="Yes",Waiver_LOT_B_OxygenLimit,Inputs!$I$96) -> 5 | L5: =IF(Inputs!$AQ$48<=K5,"PASS","FAIL") -> FAIL | M5: Shows waiver dependency for LOT-B | N5: 1 | O5: 1 | P5: =--(G5-F5<10) -> TRUE | Q5: =--(D5="Yes") -> TRUE | R5: =N5*RiskWeight_Chemical+O5*RiskWeight_Electrical+P5*RiskWeight_ResistanceMargin+Q5*RiskWeight_DocumentedException -> 88 | S5: =IF(R5>=RiskThreshold_Hold,"HOLD",IF(R5>=RiskThreshold_Conditional,"CONDITIONAL","RELEASE")) -> HOLD | T5: =--(L5="FAIL") -> TRUE | U5: =--(E5="Yes") -> FALSE | V5: 1 | W5: =T5*RiskWeight_Chemical+U5*RiskWeight_DocumentedException+V5*RiskWeight_CatalogQuality -> 44 | X5: =IF(W5>=RiskThreshold_Hold,"HOLD",IF(W5>=RiskThreshold_Conditional,"CONDITIONAL","RELEASE")) -> CONDITIONAL | Y5: =R5-$R$4 -> 0 | Z5: =W5-$W$4 -> 32 | AA5: Scenario results use the same assay, geometry, selected resistivity, configured weights, and thresholds as the current calculation. | AB5: =IF(AND(ISNUMBER(F5),ISNUMBER(G5),OR(H5="PASS",H5="FAIL"),ISNUMBER(I5),OR(J5="PASS",J5="FAIL"),ISNUMBER(K5),OR(L5="PASS",L5="FAIL"),ISNUMBER(R5),OR(S5="HOLD",S5="CONDITIONAL",S5="RELEASE"),ISNUMBER(W5),OR(X5="HOLD",X5="CONDITIONAL",X5="RELEASE")),"PASS","FAIL") -> PASS
A6: SCN-03 | B6: No process change notice | C6: 85 | D6: No | E6: Yes | F6: =Calculations!$I$21*(1+Assumption_TemperatureCoefficient*(C6-Assumption_ReferenceTemperature)) -> 155.3443 | G6: =Control_MaxTraceResistance -> 160 | H6: =IF(F6<=G6,"PASS","FAIL") -> PASS | I6: =IF(D6="Yes",Control_PCNThicknessFloor,Control_BaseThicknessFloor) -> 18 | J6: =IF(Inputs!$AY$73>=I6,"PASS","FAIL") -> FAIL | K6: =IF(E6="Yes",Waiver_LOT_B_OxygenLimit,Inputs!$I$96) -> 7 | L6: =IF(Inputs!$AQ$48<=K6,"PASS","FAIL") -> PASS | M6: Uses CCP E-3 18.0 um floor | N6: 1 | O6: 1 | P6: =--(G6-F6<10) -> TRUE | Q6: =--(D6="Yes") -> FALSE | R6: =N6*RiskWeight_Chemical+O6*RiskWeight_Electrical+P6*RiskWeight_ResistanceMargin+Q6*RiskWeight_DocumentedException -> 80 | S6: =IF(R6>=RiskThreshold_Hold,"HOLD",IF(R6>=RiskThreshold_Conditional,"CONDITIONAL","RELEASE")) -> HOLD | T6: =--(L6="FAIL") -> FALSE | U6: =--(E6="Yes") -> TRUE | V6: 1 | W6: =T6*RiskWeight_Chemical+U6*RiskWeight_DocumentedException+V6*RiskWeight_CatalogQuality -> 12 | X6: =IF(W6>=RiskThreshold_Hold,"HOLD",IF(W6>=RiskThreshold_Conditional,"CONDITIONAL","RELEASE")) -> CONDITIONAL | Y6: =R6-$R$4 -> -8 | Z6: =W6-$W$4 -> 0 | AA6: Scenario results use the same assay, geometry, selected resistivity, configured weights, and thresholds as the current calculation. | AB6: =IF(AND(ISNUMBER(F6),ISNUMBER(G6),OR(H6="PASS",H6="FAIL"),ISNUMBER(I6),OR(J6="PASS",J6="FAIL"),ISNUMBER(K6),OR(L6="PASS",L6="FAIL"),ISNUMBER(R6),OR(S6="HOLD",S6="CONDITIONAL",S6="RELEASE"),ISNUMBER(W6),OR(X6="HOLD",X6="CONDITIONAL",X6="RELEASE")),"PASS","FAIL") -> PASS
