Workbook

Sheet Med_Reconciliation
A1: Medication Reconciliation — CT-2026-0713-18 — Mara Ellison
A2: One row per retained medication identity. Source labels are crosswalked on that identity row; only active pharmacy-profile rows receive an operational action. Evidence and escalation are row-specific.
A3: Identity ID | B3: Retained medication identity | C3: Crosswalked source labels / identity basis | D3: Risk | E3: Escalation status | F3: Assigned owner | G3: Due date | H3: Source-supported disposition | I3: Evidence status | J3: Active profile row? | K3: Same-day profile action | L3: Profile action basis | M3: Evidence timeline | N3: Final outpatient directions | O3: Gap / next action | P3: Signed discharge summary | Q3: Post-summary clarification | R3: Reconciliation queue | S3: Admission history | T3: Patient portal | U3: Pharmacy profile | V3: Dispense-history summary | W3: Allergy / safety | X3: Reviewer notes | Y3: Verified disposition | Z3: Verification owner | AA3: Verified date
A4: MED-001 | B4: Apixaban 5 mg tablet | C4: Eliquis 5 mg tablet; apixaban 5 mg tablet | D4: HIGH | E4: HIGH-RISK REVIEW | F4: Owen Laird, PharmD — Outpatient Pharmacy | G4: 46218 | H4: KEEP | I4: RESOLVED | J4: YES | K4: RELEASE | L4: Active profile row plus explicit KEEP in the final signed summary. | M4: 2026-07-10 — Latest dispense DISP-001-1: apixaban 5 mg tablet; filled; 60 units / 30 days 2026-07-10 08:12 — Admission ADM-0710-001 (ADM-V1): Eliquis 5 mg tablet; active; Take 1 tablet by mouth twice daily 2026-07-13 16:40 — Final summary DCS-MED-001: Continue apixaban 5 mg tablet; Take 1 tablet by mouth twice daily 2026-07-14 22:20 — Pharmacy snapshot RXH-0714-001: apixaban 5 mg tablet; profile=active; fill=filled | N4: apixaban 5 mg tablet | Take 1 tablet by mouth twice daily | P4: DCS-MED-001 | Continue | apixaban 5 mg tablet | Take 1 tablet by mouth twice daily | Anticoagulant continued at discharge. | S4: ADM-0710-001 | ADM-V1 | Eliquis 5 mg tablet | 5 mg | Take 1 tablet by mouth twice daily | active | captured 2026-07-10 08:12 | U4: RXH-0714-001 | apixaban 5 mg tablet | profile=active | fill=filled | last_fill=2026-07-13 | Take 1 tablet by mouth twice daily | refills available | V4: 1 row(s) | latest=2026-07-10 | status=filled | qty=60 | days=30
A5: MED-002 | B5: Warfarin 5 mg tablet | C5: warfarin 5 mg tablet; warfarin; warfarin sodium 5 mg tablet | D5: HIGH | E5: HIGH-RISK REVIEW | F5: Owen Laird, PharmD — Outpatient Pharmacy | G5: 46218 | H5: STOP | I5: RESOLVED | J5: NO | L5: No action: pharmacy-profile row is inactive. Retain the source disposition for crosswalk/history; do not infer a treatment or fill decision. | M5: 2026-06-19 — Latest dispense DISP-002-1: warfarin sodium 5 mg tablet; filled; 30 units / 30 days 2026-07-10 08:12 — Admission ADM-0710-002 (ADM-V1): warfarin 5 mg tablet; active before admission; Take 1 tablet by mouth every evening 2026-07-13 09:15 — Portal PTL-0713-001: warfarin; taking; Patient wrote: old blood thinner bottle still on counter. 2026-07-13 11:05 — Queue RCQ-7714: keep pending discharge; open/preliminary 2026-07-13 16:40 — Final summary DCS-STOP-001: Stop warfarin 5 mg tablet; Stop at discharge 2026-07-14 22:20 — Pharmacy snapshot RXH-0714-002: warfarin sodium 5 mg tablet; profile=inactive; fill=filled | N5: warfarin 5 mg tablet | Stop at discharge | O5: Stop is final, but an obsolete preliminary queue row remains open. | P5: DCS-STOP-001 | Stop | warfarin 5 mg tablet | Stop at discharge | Replaced by active apixaban order. | R5: RCQ-7714 | 2026-07-13 11:05 | keep pending discharge | open/preliminary | Preliminary row expires when the final transition summary posts. | S5: ADM-0710-002 | ADM-V1 | warfarin 5 mg tablet | 5 mg | Take 1 tablet by mouth every evening | active before admission | captured 2026-07-10 08:12 | T5: PTL-0713-001 | warfarin | 5 mg | once every evening | taking | Patient wrote: old blood thinner bottle still on counter. | U5: RXH-0714-002 | warfarin sodium 5 mg tablet | profile=inactive | fill=filled | last_fill=2026-06-21 | Take 1 tablet by mouth every evening | profile inactive after transition | V5: 2 row(s) | latest=2026-06-19 | status=filled | qty=30 | days=30
A6: MED-003 | B6: Metoprolol tartrate 50 mg tablet | C6: metoprolol tartrate 50 mg tablet; metoprolol tartrate; Lopressor | D6: MED | E6: MED-RISK REVIEW | F6: Owen Laird, PharmD — Outpatient Pharmacy | G6: 46219 | H6: STOP | I6: RESOLVED | J6: NO | L6: No action: pharmacy-profile row is inactive. Retain the source disposition for crosswalk/history; do not infer a treatment or fill decision. | M6: 2026-06-14 — Latest dispense DISP-003-1: metoprolol tartrate 50 mg tablet; filled; 60 units / 30 days 2026-07-10 08:12 — Admission ADM-0710-003 (ADM-V1): metoprolol tartrate 50 mg tablet; active; Take 1 tablet by mouth twice daily 2026-07-13 09:15 — Portal PTL-0713-002A: metoprolol tartrate; taking; Entered from bottle label. 2026-07-13 09:15 — Portal PTL-0713-002B: Lopressor; taking; Same tablet; duplicate entry from phone app. 2026-07-13 13:30 — Queue RCQ-7718: change expected; open/preliminary 2026-07-13 16:40 — Final summary DCS-STOP-002: Stop metoprolol tartrate 50 mg tablet; Stop at discharge 2026-07-14 15:10 — Prescriber clarification: Do not carry tartrate forward. 2026-07-14 22:20 — Pharmacy snapshot RXH-0714-003: metoprolol tartrate 50 mg tablet; profile=inactive; fill=filled | N6: metoprolol tartrate 50 mg tablet | Stop at discharge | O6: Stop/change is final, but an obsolete preliminary queue row remains open. | P6: DCS-STOP-002 | Stop | metoprolol tartrate 50 mg tablet | Stop at discharge | Use extended-release formulation below. | Q6: 2026-07-14 15:10 — Do not carry tartrate forward. | R6: RCQ-7718 | 2026-07-13 13:30 | change expected | open/preliminary | Await final formulation and dose. | S6: ADM-0710-003 | ADM-V1 | metoprolol tartrate 50 mg tablet | 50 mg | Take 1 tablet by mouth twice daily | active | captured 2026-07-10 08:12 | T6: PTL-0713-002A | metoprolol tartrate | 50 mg | morning and bedtime | taking | Entered from bottle label. PTL-0713-002B | Lopressor | 50 mg | twice daily | taking | Same tablet; duplicate entry from phone app. | U6: RXH-0714-003 | metoprolol tartrate 50 mg tablet | profile=inactive | fill=filled | last_fill=2026-06-14 | Take 1 tablet by mouth twice daily | profile inactive after transition | V6: 3 row(s) | latest=2026-06-14 | status=filled | qty=60 | days=30
A7: MED-004 | B7: Metoprolol succinate ER 100 mg tablet | C7: metoprolol succinate ER 100 mg tablet | D7: MED | E7: MED-RISK REVIEW | F7: Owen Laird, PharmD — Outpatient Pharmacy | G7: 46219 | H7: CHANGE | I7: RESOLVED | J7: NO | L7: No action: no pharmacy-profile row exists for this identity. Retain the source disposition for crosswalk/history; route any signed order through normal intake. | M7: 2026-07-13 16:40 — Final summary DCS-MED-002: Change metoprolol succinate ER 100 mg tablet; Take 1 tablet by mouth once daily 2026-07-14 15:10 — Prescriber clarification: Use succinate ER 100 mg once daily from signed summary. | N7: metoprolol succinate ER 100 mg tablet | Take 1 tablet by mouth once daily | O7: New formulation is absent from latest pharmacy profile. | P7: DCS-MED-002 | Change | metoprolol succinate ER 100 mg tablet | Take 1 tablet by mouth once daily | Changed from metoprolol tartrate 50 mg twice daily. | Q7: 2026-07-14 15:10 — Use succinate ER 100 mg once daily from signed summary.
A8: MED-005 | B8: Lisinopril 20 mg tablet | C8: lisinopril 20 mg tablet | D8: HIGH | E8: ACTIVE PROFILE — STOP ACTION | F8: Owen Laird, PharmD — Outpatient Pharmacy | G8: 46218 | H8: STOP | I8: RESOLVED | J8: YES | K8: STOP | L8: STOP supported by the final signed stop order and active HIGH angioedema allergy. | M8: 2026-07-11 17:45 — Admission ADM-0710-004 (ADM-V2): lisinopril 20 mg tablet; active at admission; Take 1 tablet by mouth daily 2026-07-12 — Latest dispense DISP-004-1: lisinopril 20 mg tablet; ready_to_fill; 30 units / 30 days 2026-07-12 14:22 — Allergy ALG-ACEI-20260710: lisinopril / cough; LOW inactive 2026-07-12 14:22 — Allergy ALG-ACEI-20260712: lisinopril / angioedema; HIGH active 2026-07-13 16:40 — Final summary DCS-STOP-003: Stop lisinopril 20 mg tablet; Stop at discharge 2026-07-14 22:20 — Pharmacy snapshot RXH-0714-005: lisinopril 20 mg tablet; profile=active; fill=ready_to_fill | N8: lisinopril 20 mg tablet | Stop at discharge | O8: HIGH-RISK mismatch: pharmacy profile remains active/ready_to_fill despite severe allergy and stop order. | P8: DCS-STOP-003 | Stop | lisinopril 20 mg tablet | Stop at discharge | ACE inhibitor allergy verified during stay. | S8: ADM-0710-004 | ADM-V2 | lisinopril 20 mg tablet | 20 mg | Take 1 tablet by mouth daily | active at admission | captured 2026-07-11 17:45 | U8: RXH-0714-005 | lisinopril 20 mg tablet | profile=active | fill=ready_to_fill | last_fill=2026-07-14 | Take 1 tablet by mouth daily | refills available | V8: 1 row(s) | latest=2026-07-12 | status=ready_to_fill | qty=30 | days=30 | W8: ACTIVE HIGH allergy: lisinopril—angioedema; verified 2026-07-12 14:22.
A9: MED-006 | B9: Losartan 50 mg tablet | C9: losartan 50 mg tablet | D9: MED | E9: MED-RISK REVIEW | F9: Owen Laird, PharmD — Outpatient Pharmacy | G9: 46219 | H9: CHANGE | I9: RESOLVED | J9: NO | L9: No action: no pharmacy-profile row exists for this identity. Retain the source disposition for crosswalk/history; route any signed order through normal intake. | M9: 2026-07-13 16:40 — Final summary DCS-MED-003: Change losartan 50 mg tablet; Take 1 tablet by mouth daily | N9: losartan 50 mg tablet | Take 1 tablet by mouth daily | O9: New discharge medication is absent from latest pharmacy profile. | P9: DCS-MED-003 | Change | losartan 50 mg tablet | Take 1 tablet by mouth daily | New discharge antihypertensive after lisinopril allergy update.
A10: MED-007 | B10: Insulin glargine U-100 pen | C10: Lantus SoloStar U-100 insulin pen; Lantus insulin pen; Basaglar KwikPen U-100; insulin glargine-yfgn U-100 pen | FG-SUB-001: approved U-100 glargine product identity | D10: HIGH | E10: ACTIVE PROFILE — CHANGE ACTION | F10: Owen Laird, PharmD — Outpatient Pharmacy | G10: 46218 | H10: CHANGE | I10: RESOLVED | J10: YES | K10: CHANGE | L10: Active profile row plus explicit CHANGE in the final signed summary. | M10: 2026-07-05 — Latest dispense DISP-005-1: Basaglar KwikPen U-100; filled; 15 units / 30 days 2026-07-10 08:12 — Admission ADM-0710-005 (ADM-V1): Lantus SoloStar U-100 insulin pen; active; Inject 28 units subcutaneously nightly 2026-07-13 09:15 — Portal PTL-0713-003: Lantus insulin pen; taking; Patient reports usually 28 units. 2026-07-13 16:40 — Final summary DCS-MED-004: Change insulin glargine-yfgn U-100 pen; Inject 30 units subcutaneously nightly 2026-07-14 22:20 — Pharmacy snapshot RXH-0714-107: Basaglar KwikPen U-100; profile=active; fill=filled | N10: insulin glargine-yfgn U-100 pen | Inject 30 units subcutaneously nightly | O10: Latest pharmacy row reflects 28 units; signed discharge dose is 30 units. | P10: DCS-MED-004 | Change | insulin glargine-yfgn U-100 pen | Inject 30 units subcutaneously nightly | Dose changed from 28 units; formulary U-100 glargine products are interchangeable. | S10: ADM-0710-005 | ADM-V1 | Lantus SoloStar U-100 insulin pen | 28 units | Inject 28 units subcutaneously nightly | active | captured 2026-07-10 08:12 | T10: PTL-0713-003 | Lantus insulin pen | 28 units | every night | taking | Patient reports usually 28 units. | U10: RXH-0714-107 | Basaglar KwikPen U-100 | profile=active | fill=filled | last_fill=2026-07-08 | Inject 28 units subcutaneously nightly | refills available | V10: 3 row(s) | latest=2026-07-05 | status=filled | qty=15 | days=30
A11: MED-008 | B11: Insulin lispro U-100 pen | C11: Humalog KwikPen U-100; Humalog; insulin lispro U-100 pen | D11: HIGH | E11: HIGH-RISK REVIEW | F11: Owen Laird, PharmD — Outpatient Pharmacy | G11: 46218 | H11: KEEP | I11: RESOLVED | J11: YES | K11: RELEASE | L11: Active profile row plus explicit KEEP in the final signed summary. | M11: 2026-07-06 — Latest dispense DISP-006-1: insulin lispro U-100 pen; filled; 15 units / 30 days 2026-07-10 08:12 — Admission ADM-0710-006 (ADM-V1): Humalog KwikPen U-100; active; Inject 6 units before meals 2026-07-13 09:15 — Portal PTL-0713-004: Humalog; taking; Uses when eating. 2026-07-13 16:40 — Final summary DCS-MED-005: Continue insulin lispro U-100 pen; Inject 6 units subcutaneously before meals 2026-07-14 22:20 — Pharmacy snapshot RXH-0714-006: insulin lispro U-100 pen; profile=active; fill=filled | N11: insulin lispro U-100 pen | Inject 6 units subcutaneously before meals | P11: DCS-MED-005 | Continue | insulin lispro U-100 pen | Inject 6 units subcutaneously before meals | Continue home mealtime insulin. | S11: ADM-0710-006 | ADM-V1 | Humalog KwikPen U-100 | 6 units | Inject 6 units before meals | active | captured 2026-07-10 08:12 | T11: PTL-0713-004 | Humalog | 6 units | with meals | taking | Uses when eating. | U11: RXH-0714-006 | insulin lispro U-100 pen | profile=active | fill=filled | last_fill=2026-07-08 | Inject 6 units before meals | refills available | V11: 3 row(s) | latest=2026-07-06 | status=filled | qty=15 | days=30
A12: MED-009 | B12: Metformin ER 500 mg tablet | C12: metformin ER 500 mg tablet; metformin ER | D12: LOW | E12: NO OPEN ESCALATION | F12: Owen Laird, PharmD — Outpatient Pharmacy | G12: 46220 | H12: STOP | I12: RESOLVED | J12: NO | L12: No action: pharmacy-profile row is inactive. Retain the source disposition for crosswalk/history; do not infer a treatment or fill decision. | M12: 2026-06-18 — Latest dispense DISP-007-1: metformin ER 500 mg tablet; filled; 60 units / 30 days 2026-07-10 08:12 — Admission ADM-0710-007 (ADM-V1): metformin ER 500 mg tablet; active at admission; Take 1 tablet by mouth twice daily 2026-07-13 09:15 — Portal PTL-0713-005: metformin ER; taking; Patient unsure if still needed. 2026-07-13 16:40 — Final summary DCS-STOP-004: Stop metformin ER 500 mg tablet; Stop at discharge 2026-07-14 22:20 — Pharmacy snapshot RXH-0714-007: metformin ER 500 mg tablet; profile=inactive; fill=filled | N12: metformin ER 500 mg tablet | Stop at discharge | P12: DCS-STOP-004 | Stop | metformin ER 500 mg tablet | Stop at discharge | Stopped by discharging service. | S12: ADM-0710-007 | ADM-V1 | metformin ER 500 mg tablet | 500 mg | Take 1 tablet by mouth twice daily | active at admission | captured 2026-07-10 08:12 | T12: PTL-0713-005 | metformin ER | 500 mg | twice a day | taking | Patient unsure if still needed. | U12: RXH-0714-007 | metformin ER 500 mg tablet | profile=inactive | fill=filled | last_fill=2026-06-20 | Take 1 tablet by mouth twice daily | profile inactive after transition | V12: 2 row(s) | latest=2026-06-18 | status=filled | qty=60 | days=30
A13: MED-010 | B13: Furosemide tablet | C13: furosemide 20 mg tablet; water pill - furosemide; furosemide 40 mg tablet | D13: MED | E13: ACTIVE PROFILE — CHANGE ACTION | F13: Owen Laird, PharmD — Outpatient Pharmacy | G13: 46218 | H13: CHANGE | I13: RESOLVED | J13: YES | K13: CHANGE | L13: Active profile row plus explicit CHANGE in the final signed summary. | M13: 2026-06-26 — Latest dispense DISP-008-1: furosemide 20 mg tablet; filled; 30 units / 30 days 2026-07-11 17:45 — Admission ADM-0710-008 (ADM-V2): furosemide 20 mg tablet; active; Take 1 tablet by mouth daily 2026-07-13 09:15 — Portal PTL-0713-006: water pill - furosemide; taking; Bottle says 20 mg. 2026-07-13 16:40 — Final summary DCS-MED-006: Change furosemide 40 mg tablet; Take 1 tablet by mouth daily 2026-07-14 22:20 — Pharmacy snapshot RXH-0714-008: furosemide 20 mg tablet; profile=active; fill=filled | N13: furosemide 40 mg tablet | Take 1 tablet by mouth daily | O13: Latest pharmacy row reflects 20 mg; signed discharge dose is 40 mg. | P13: DCS-MED-006 | Change | furosemide 40 mg tablet | Take 1 tablet by mouth daily | Dose increased from 20 mg daily. | S13: ADM-0710-008 | ADM-V2 | furosemide 20 mg tablet | 20 mg | Take 1 tablet by mouth daily | active | captured 2026-07-11 17:45 | T13: PTL-0713-006 | water pill - furosemide | 20 mg | every morning | taking | Bottle says 20 mg. | U13: RXH-0714-008 | furosemide 20 mg tablet | profile=active | fill=filled | last_fill=2026-06-30 | Take 1 tablet by mouth daily | refills available | V13: 1 row(s) | latest=2026-06-26 | status=filled | qty=30 | days=30
A14: MED-011 | B14: Potassium chloride ER 20 mEq tablet | C14: potassium chloride ER 20 mEq tablet; Klor-Con M20; Klor-Con M20 tablet | FG-SUB-004: approved potassium chloride ER 20 mEq product identity | D14: MED | E14: MED-RISK REVIEW | F14: Owen Laird, PharmD — Outpatient Pharmacy | G14: 46218 | H14: KEEP | I14: RESOLVED | J14: YES | K14: RELEASE | L14: RELEASE supported by the 2026-07-14 prescriber clarification after the reported BMP. | M14: 2026-06-29 — Latest dispense DISP-009-1: Klor-Con M20 tablet; filled; 30 units / 30 days 2026-07-10 08:12 — Admission ADM-0710-009 (ADM-V1): potassium chloride ER 20 mEq tablet; active; Take 1 tablet by mouth daily 2026-07-13 09:15 — Portal PTL-0713-007: Klor-Con M20; taking; Holds when told after labs. 2026-07-13 13:38 — Queue RCQ-7721: hold pending lab review; open/preliminary 2026-07-13 16:40 — Final summary DCS-MED-007: Continue potassium chloride ER 20 mEq tablet; Take 1 tablet by mouth daily after lab review 2026-07-14 15:10 — Prescriber clarification: BMP at 14:36 reportedly K 4.2; continue ER 20 mEq once daily. 2026-07-14 15:25 — Queue RCQ-7744: continue; closed/current 2026-07-14 22:20 — Pharmacy snapshot RXH-0714-009: Klor-Con M20 tablet; profile=active; fill=filled | N14: potassium chloride ER 20 mEq tablet | Take 1 tablet by mouth daily after lab review | O14: Resolved by email/queue, but final signed summary was not amended and preliminary queue row remains open. | P14: DCS-MED-007 | Continue | potassium chloride ER 20 mEq tablet | Take 1 tablet by mouth daily after lab review | Conditional discharge instruction; prescriber clarification follows. | Q14: 2026-07-14 15:10 — BMP at 14:36 reportedly K 4.2; continue ER 20 mEq once daily. | R14: RCQ-7721 | 2026-07-13 13:38 | hold pending lab review | open/preliminary | Lab result not yet available. RCQ-7744 | 2026-07-14 15:25 | continue | closed/current | Prescriber confirmed continuation after BMP resulted. | S14: ADM-0710-009 | ADM-V1 | potassium chloride ER 20 mEq tablet | 20 mEq | Take 1 tablet by mouth daily | active | captured 2026-07-10 08:12 | T14: PTL-0713-007 | Klor-Con M20 | 20 mEq | daily | taking | Holds when told after labs. | U14: RXH-0714-009 | Klor-Con M20 tablet | profile=active | fill=filled | last_fill=2026-07-02 | Take 1 tablet by mouth daily | refills available | V14: 3 row(s) | latest=2026-06-29 | status=filled | qty=30 | days=30
A15: MED-012 | B15: Spironolactone 25 mg tablet | C15: spironolactone 25 mg tablet; spironolactone | D15: MED | E15: OPEN ESCALATION | F15: Owen Laird, PharmD — route to Cardiology | G15: 46218 | H15: CLARIFY | I15: OPEN | J15: YES | K15: CLARIFY | L15: CLARIFY: final summary is silent; prescriber requested a cardiology decision. | M15: 2026-06-29 — Latest dispense DISP-010-1: spironolactone 25 mg tablet; filled; 30 units / 30 days 2026-07-10 08:12 — Admission ADM-0710-010 (ADM-V1): spironolactone 25 mg tablet; active at admission; Take 1 tablet by mouth daily 2026-07-13 09:15 — Portal PTL-0713-008: spironolactone; taking; Patient says cardiology started it. 2026-07-14 08:21 — Queue RCQ-7732: ask prescriber; open/current 2026-07-14 15:10 — Prescriber clarification: Not confirmed; ask cardiology before dispensing. 2026-07-14 22:20 — Pharmacy snapshot RXH-0714-013: spironolactone 25 mg tablet; profile=active; fill=filled | O15: Final summary silent; obtain cardiology decision before dispensing. | Q15: 2026-07-14 15:10 — Not confirmed; ask cardiology before dispensing. | R15: RCQ-7732 | 2026-07-14 08:21 | ask prescriber | open/current | Active profile but not addressed in final transition summary. | S15: ADM-0710-010 | ADM-V1 | spironolactone 25 mg tablet | 25 mg | Take 1 tablet by mouth daily | active at admission | captured 2026-07-10 08:12 | T15: PTL-0713-008 | spironolactone | 25 mg | every morning | taking | Patient says cardiology started it. | U15: RXH-0714-013 | spironolactone 25 mg tablet | profile=active | fill=filled | last_fill=2026-07-01 | Take 1 tablet by mouth daily | refills available | V15: 2 row(s) | latest=2026-06-29 | status=filled | qty=30 | days=30
A16: MED-013 | B16: Aspirin 81 mg EC tablet | C16: aspirin EC 81 mg tablet; baby aspirin; aspirin 81 mg EC tablet | D16: LOW | E16: NO OPEN ESCALATION | F16: Owen Laird, PharmD — Outpatient Pharmacy | G16: 46220 | H16: STOP | I16: RESOLVED | J16: NO | L16: No action: no pharmacy-profile row exists for this identity. Retain the source disposition for crosswalk/history; route any signed order through normal intake. | M16: 2026-07-10 08:12 — Admission ADM-0710-011 (ADM-V1): aspirin EC 81 mg tablet; active; Take 1 tablet by mouth daily 2026-07-13 09:15 — Portal PTL-0713-009: baby aspirin; taking; OTC bottle in weekly pill box. 2026-07-13 16:40 — Final summary DCS-STOP-005: Stop aspirin 81 mg EC tablet; Stop at discharge | N16: aspirin 81 mg EC tablet | Stop at discharge | P16: DCS-STOP-005 | Stop | aspirin 81 mg EC tablet | Stop at discharge | Stopped by discharging service. | S16: ADM-0710-011 | ADM-V1 | aspirin EC 81 mg tablet | 81 mg | Take 1 tablet by mouth daily | active | captured 2026-07-10 08:12 | T16: PTL-0713-009 | baby aspirin | 81 mg | daily | taking | OTC bottle in weekly pill box.
A17: MED-014 | B17: Clopidogrel 75 mg tablet | C17: clopidogrel 75 mg tablet | D17: LOW | E17: ACTIVE PROFILE — STOP ACTION | F17: Owen Laird, PharmD — Outpatient Pharmacy | G17: 46218 | H17: STOP | I17: RESOLVED | J17: YES | K17: STOP | L17: Active profile row plus explicit STOP in the final signed summary. | M17: 2026-06-24 — Latest dispense DISP-011-1: clopidogrel 75 mg tablet; filled; 30 units / 30 days 2026-07-13 16:40 — Final summary DCS-STOP-006: Stop clopidogrel 75 mg tablet; Stop at discharge 2026-07-14 22:20 — Pharmacy snapshot RXH-0714-011: clopidogrel 75 mg tablet; profile=active; fill=filled | N17: clopidogrel 75 mg tablet | Stop at discharge | O17: Pharmacy profile remains active despite explicit discharge stop. | P17: DCS-STOP-006 | Stop | clopidogrel 75 mg tablet | Stop at discharge | No active outpatient order after transition. | U17: RXH-0714-011 | clopidogrel 75 mg tablet | profile=active | fill=filled | last_fill=2026-06-24 | Take 1 tablet by mouth daily | refills available | V17: 1 row(s) | latest=2026-06-24 | status=filled | qty=30 | days=30
A18: MED-015 | B18: Albuterol HFA 90 mcg inhaler | C18: albuterol HFA 90 mcg inhaler; Ventolin rescue inhaler; ProAir HFA 90 mcg inhaler; albuterol HFA inhaler | FG-SUB-003: approved albuterol HFA product identity | D18: LOW | E18: NO OPEN ESCALATION | F18: Owen Laird, PharmD — Outpatient Pharmacy | G18: 46218 | H18: KEEP | I18: RESOLVED | J18: YES | K18: RELEASE | L18: Active profile row plus explicit KEEP in the final signed summary. | M18: 2026-06-06 — Latest dispense DISP-012-1: ProAir HFA 90 mcg inhaler; filled; 1 units / 25 days 2026-07-11 17:45 — Admission ADM-0710-012 (ADM-V2): albuterol HFA 90 mcg inhaler; active; Inhale 2 puffs every 4 hours as needed 2026-07-13 09:15 — Portal PTL-0713-010: Ventolin rescue inhaler; taking as needed; Keeps in purse. 2026-07-13 16:40 — Final summary DCS-MED-008: Continue albuterol HFA inhaler; Inhale 2 puffs every 4 hours as needed 2026-07-14 22:20 — Pharmacy snapshot RXH-0714-012: ProAir HFA 90 mcg inhaler; profile=active; fill=filled | N18: albuterol HFA inhaler | Inhale 2 puffs every 4 hours as needed | P18: DCS-MED-008 | Continue | albuterol HFA inhaler | Inhale 2 puffs every 4 hours as needed | Any approved albuterol HFA product may dispense. | S18: ADM-0710-012 | ADM-V2 | albuterol HFA 90 mcg inhaler | 90 mcg | Inhale 2 puffs every 4 hours as needed | active | captured 2026-07-11 17:45 | T18: PTL-0713-010 | Ventolin rescue inhaler | 90 mcg | 2 puffs when wheezy | taking as needed | Keeps in purse. | U18: RXH-0714-012 | ProAir HFA 90 mcg inhaler | profile=active | fill=filled | last_fill=2026-06-10 | Inhale 2 puffs every 4 hours as needed | refills available | V18: 2 row(s) | latest=2026-06-06 | status=filled | qty=1 | days=25
A19: MED-016 | B19: Fluticasone-salmeterol 250/50 Diskus | C19: Advair Diskus 250/50; Advair; fluticasone-salmeterol 250/50 Diskus | D19: LOW | E19: NO OPEN ESCALATION | F19: Owen Laird, PharmD — Outpatient Pharmacy | G19: 46218 | H19: KEEP | I19: RESOLVED | J19: YES | K19: RELEASE | L19: Active profile row plus explicit KEEP in the final signed summary. | M19: 2026-07-01 — Latest dispense DISP-013-1: fluticasone-salmeterol 250/50 Diskus; filled; 1 units / 30 days 2026-07-10 08:12 — Admission ADM-0710-013 (ADM-V1): Advair Diskus 250/50; active; Inhale 1 puff twice daily 2026-07-13 09:15 — Portal PTL-0713-011: Advair; taking; Uses most days. 2026-07-13 16:40 — Final summary DCS-MED-009: Continue fluticasone-salmeterol 250/50 Diskus; Inhale 1 puff twice daily 2026-07-14 22:20 — Pharmacy snapshot RXH-0714-117: fluticasone-salmeterol 250/50 Diskus; profile=active; fill=filled | N19: fluticasone-salmeterol 250/50 Diskus | Inhale 1 puff twice daily | P19: DCS-MED-009 | Continue | fluticasone-salmeterol 250/50 Diskus | Inhale 1 puff twice daily | Continue maintenance inhaler. | S19: ADM-0710-013 | ADM-V1 | Advair Diskus 250/50 | 250/50 mcg | Inhale 1 puff twice daily | active | captured 2026-07-10 08:12 | T19: PTL-0713-011 | Advair | 250/50 | 1 puff morning and night | taking | Uses most days. | U19: RXH-0714-117 | fluticasone-salmeterol 250/50 Diskus | profile=active | fill=filled | last_fill=2026-07-05 | Inhale 1 puff twice daily | refills available | V19: 3 row(s) | latest=2026-07-01 | status=filled | qty=1 | days=30
A20: MED-017 | B20: Prednisone 10 mg taper | C20: prednisone 10 mg tablet; prednisone; prednisone 10 mg tablet taper | D20: LOW | E20: NO OPEN ESCALATION | F20: Owen Laird, PharmD — Outpatient Pharmacy | G20: 46220 | H20: STOP | I20: RESOLVED | J20: NO | L20: No action: pharmacy-profile row is inactive. Retain the source disposition for crosswalk/history; do not infer a treatment or fill decision. | M20: 2026-06-28 — Latest dispense DISP-014-1: prednisone 10 mg tablet; filled; 21 units / 6 days 2026-07-10 08:12 — Admission ADM-0710-014 (ADM-V1): prednisone 10 mg tablet; short course; Taper as directed 2026-07-13 09:15 — Portal PTL-0713-012: prednisone; uncertain; Bottle from last week. 2026-07-13 16:40 — Final summary DCS-STOP-007: Stop prednisone 10 mg tablet taper; Stop at discharge 2026-07-14 22:20 — Pharmacy snapshot RXH-0714-014: prednisone 10 mg tablet; profile=inactive; fill=filled | N20: prednisone 10 mg tablet taper | Stop at discharge | P20: DCS-STOP-007 | Stop | prednisone 10 mg tablet taper | Stop at discharge | Course complete. | S20: ADM-0710-014 | ADM-V1 | prednisone 10 mg tablet | 10 mg | Taper as directed | short course | captured 2026-07-10 08:12 | T20: PTL-0713-012 | prednisone | 10 mg | not sure | uncertain | Bottle from last week. | U20: RXH-0714-014 | prednisone 10 mg tablet | profile=inactive | fill=filled | last_fill=2026-07-01 | Taper as directed | profile inactive after transition | V20: 1 row(s) | latest=2026-06-28 | status=filled | qty=21 | days=6
A21: MED-018 | B21: Amoxicillin-clavulanate 875/125 mg tablet | C21: amoxicillin-clavulanate 875/125 mg tablet | D21: HIGH | E21: HIGH-RISK REVIEW | F21: Owen Laird, PharmD — Outpatient Pharmacy | G21: 46218 | H21: STOP | I21: RESOLVED | J21: NO | L21: No action: pharmacy-profile row is inactive. Retain the source disposition for crosswalk/history; do not infer a treatment or fill decision. | M21: 2026-07-05 — Latest dispense DISP-015-1: amoxicillin-clavulanate 875/125 mg tablet; filled; 14 units / 7 days 2026-07-10 08:12 — Admission ADM-0710-015 (ADM-V1): amoxicillin-clavulanate 875/125 mg tablet; short course before admission; Take 1 tablet by mouth twice daily 2026-07-10 12:44 — Allergy ALG-PCN-20240703: penicillin class / hives; HIGH active 2026-07-13 16:40 — Final summary DCS-STOP-008: Stop amoxicillin-clavulanate 875/125 mg tablet; Stop at discharge 2026-07-14 22:20 — Pharmacy snapshot RXH-0714-015: amoxicillin-clavulanate 875/125 mg tablet; profile=inactive; fill=filled | N21: amoxicillin-clavulanate 875/125 mg tablet | Stop at discharge | P21: DCS-STOP-008 | Stop | amoxicillin-clavulanate 875/125 mg tablet | Stop at discharge | Do not continue after allergy verification. | S21: ADM-0710-015 | ADM-V1 | amoxicillin-clavulanate 875/125 mg tablet | 875/125 mg | Take 1 tablet by mouth twice daily | short course before admission | captured 2026-07-10 08:12 | U21: RXH-0714-015 | amoxicillin-clavulanate 875/125 mg tablet | profile=inactive | fill=filled | last_fill=2026-07-06 | Take 1 tablet by mouth twice daily | profile inactive after transition | V21: 3 row(s) | latest=2026-07-05 | status=filled | qty=14 | days=7 | W21: ACTIVE HIGH penicillin-class allergy: hives; verified 2026-07-10 12:44.
A22: MED-019 | B22: Naproxen 500 mg tablet | C22: naproxen 500 mg tablet; naproxen | D22: HIGH | E22: HIGH-RISK REVIEW | F22: Owen Laird, PharmD — Outpatient Pharmacy | G22: 46218 | H22: STOP | I22: RESOLVED | J22: NO | L22: No action: no pharmacy-profile row exists for this identity. Retain the source disposition for crosswalk/history; route any signed order through normal intake. | M22: 2026-07-10 12:47 — Allergy ALG-NSAID-20260218: naproxen / hives; HIGH active 2026-07-11 17:45 — Admission ADM-0710-016 (ADM-V2): naproxen 500 mg tablet; active PRN; Take 1 tablet by mouth twice daily as needed 2026-07-13 09:15 — Portal PTL-0713-013: naproxen; has supply; Patient says it made hives once. 2026-07-13 16:40 — Final summary DCS-STOP-009: Stop naproxen 500 mg tablet; Stop at discharge | N22: naproxen 500 mg tablet | Stop at discharge | P22: DCS-STOP-009 | Stop | naproxen 500 mg tablet | Stop at discharge | NSAID allergy listed. | S22: ADM-0710-016 | ADM-V2 | naproxen 500 mg tablet | 500 mg | Take 1 tablet by mouth twice daily as needed | active PRN | captured 2026-07-11 17:45 | T22: PTL-0713-013 | naproxen | 500 mg | when joints hurt | has supply | Patient says it made hives once. | W22: ACTIVE HIGH naproxen allergy: hives; verified 2026-07-10 12:47.
A23: MED-020 | B23: Acetaminophen 500 mg tablet | C23: acetaminophen 500 mg tablet; Tylenol | D23: LOW | E23: NO OPEN ESCALATION | F23: Owen Laird, PharmD — Outpatient Pharmacy | G23: 46220 | H23: KEEP | I23: RESOLVED | J23: NO | L23: No action: no pharmacy-profile row exists for this identity. Retain the source disposition for crosswalk/history; route any signed order through normal intake. | M23: 2026-07-10 08:12 — Admission ADM-0710-017 (ADM-V1): acetaminophen 500 mg tablet; active PRN; Take 2 tablets every 8 hours as needed 2026-07-13 09:15 — Portal PTL-0713-014: Tylenol; taking as needed; OTC. 2026-07-13 16:40 — Final summary DCS-MED-010: Continue acetaminophen 500 mg tablet; Take 2 tablets by mouth every 8 hours as needed for pain | N23: acetaminophen 500 mg tablet | Take 2 tablets by mouth every 8 hours as needed for pain | P23: DCS-MED-010 | Continue | acetaminophen 500 mg tablet | Take 2 tablets by mouth every 8 hours as needed for pain | Maximum daily dose per label. | S23: ADM-0710-017 | ADM-V1 | acetaminophen 500 mg tablet | 500 mg | Take 2 tablets every 8 hours as needed | active PRN | captured 2026-07-10 08:12 | T23: PTL-0713-014 | Tylenol | 500 mg | 2 tablets when needed | taking as needed | OTC.
A24: MED-021 | B24: PPI: pantoprazole 40 mg / omeprazole 20 mg | C24: omeprazole 20 mg capsule; omeprazole; pantoprazole 40 mg tablet | FG-SUB-002: approved pantoprazole-to-omeprazole outpatient crosswalk | D24: LOW | E24: NO OPEN ESCALATION | F24: Owen Laird, PharmD — Outpatient Pharmacy | G24: 46218 | H24: CHANGE | I24: RESOLVED | J24: YES | K24: RELEASE | L24: RELEASE the existing omeprazole 20 mg profile identity: FG-SUB-002 resolves pantoprazole to omeprazole, and the 2026-07-14 prescriber clarification approves it. | M24: 2026-06-15 — Latest dispense DISP-016-1: omeprazole 20 mg capsule; filled; 30 units / 30 days 2026-07-10 08:12 — Admission ADM-0710-018 (ADM-V1): omeprazole 20 mg capsule; active; Take 1 capsule by mouth daily 2026-07-13 09:15 — Portal PTL-0713-015: omeprazole; taking; Buys OTC sometimes. 2026-07-13 16:40 — Final summary DCS-MED-011: Change pantoprazole 40 mg tablet; Take 1 tablet by mouth daily 2026-07-14 15:10 — Prescriber clarification: Outpatient formulary substitution approved; no do-not-substitute note. 2026-07-14 17:05 — Queue RCQ-7751: formulary substitution; closed/current 2026-07-14 22:20 — Pharmacy snapshot RXH-0714-016: omeprazole 20 mg capsule; profile=active; fill=filled | N24: pantoprazole 40 mg tablet | Take 1 tablet by mouth daily | O24: Resolved operationally through formulary substitution; no amended signed summary. | P24: DCS-MED-011 | Change | pantoprazole 40 mg tablet | Take 1 tablet by mouth daily | Outpatient formulary substitution allowed unless prohibited. | Q24: 2026-07-14 15:10 — Outpatient formulary substitution approved; no do-not-substitute note. | R24: RCQ-7751 | 2026-07-14 17:05 | formulary substitution | closed/current | Use approved outpatient PPI substitution unless discharge prohibits substitution. | S24: ADM-0710-018 | ADM-V1 | omeprazole 20 mg capsule | 20 mg | Take 1 capsule by mouth daily | active | captured 2026-07-10 08:12 | T24: PTL-0713-015 | omeprazole | 20 mg | daily before breakfast | taking | Buys OTC sometimes. | U24: RXH-0714-016 | omeprazole 20 mg capsule | profile=active | fill=filled | last_fill=2026-06-19 | Take 1 capsule by mouth daily | refills available | V24: 2 row(s) | latest=2026-06-15 | status=filled | qty=30 | days=30
A25: MED-022 | B25: Atorvastatin 40 mg tablet | C25: atorvastatin 40 mg tablet; atorvastatin | D25: LOW | E25: NO OPEN ESCALATION | F25: Owen Laird, PharmD — Outpatient Pharmacy | G25: 46220 | H25: STOP | I25: RESOLVED | J25: NO | L25: No action: pharmacy-profile row is inactive. Retain the source disposition for crosswalk/history; do not infer a treatment or fill decision. | M25: 2026-06-13 — Latest dispense DISP-017-1: atorvastatin 40 mg tablet; filled; 30 units / 30 days 2026-07-10 08:12 — Admission ADM-0710-019 (ADM-V1): atorvastatin 40 mg tablet; active; Take 1 tablet by mouth nightly 2026-07-13 09:15 — Portal PTL-0713-016: atorvastatin; taking; Old med list still has this. 2026-07-13 16:40 — Final summary DCS-STOP-010: Stop atorvastatin 40 mg tablet; Stop at discharge 2026-07-14 22:20 — Pharmacy snapshot RXH-0714-017: atorvastatin 40 mg tablet; profile=inactive; fill=filled | N25: atorvastatin 40 mg tablet | Stop at discharge | O25: Pharmacy profile remains active despite stop/change to rosuvastatin. | P25: DCS-STOP-010 | Stop | atorvastatin 40 mg tablet | Stop at discharge | Use rosuvastatin order below. | S25: ADM-0710-019 | ADM-V1 | atorvastatin 40 mg tablet | 40 mg | Take 1 tablet by mouth nightly | active | captured 2026-07-10 08:12 | T25: PTL-0713-016 | atorvastatin | 40 mg | nightly | taking | Old med list still has this. | U25: RXH-0714-017 | atorvastatin 40 mg tablet | profile=inactive | fill=filled | last_fill=2026-06-16 | Take 1 tablet by mouth nightly | profile inactive after transition | V25: 3 row(s) | latest=2026-06-13 | status=filled | qty=30 | days=30
A26: MED-023 | B26: Rosuvastatin 20 mg tablet | C26: rosuvastatin 20 mg tablet | D26: LOW | E26: NO OPEN ESCALATION | F26: Owen Laird, PharmD — Outpatient Pharmacy | G26: 46220 | H26: CHANGE | I26: RESOLVED | J26: NO | L26: No action: no pharmacy-profile row exists for this identity. Retain the source disposition for crosswalk/history; route any signed order through normal intake. | M26: 2026-07-13 16:40 — Final summary DCS-MED-012: Change rosuvastatin 20 mg tablet; Take 1 tablet by mouth nightly | N26: rosuvastatin 20 mg tablet | Take 1 tablet by mouth nightly | O26: New discharge medication is absent from latest pharmacy profile. | P26: DCS-MED-012 | Change | rosuvastatin 20 mg tablet | Take 1 tablet by mouth nightly | New discharge statin order; not a formulary substitution of atorvastatin.
A27: MED-024 | B27: Levothyroxine 75 mcg tablet | C27: levothyroxine 75 mcg tablet; levothyroxine | D27: LOW | E27: NO OPEN ESCALATION | F27: Owen Laird, PharmD — Outpatient Pharmacy | G27: 46218 | H27: KEEP | I27: RESOLVED | J27: YES | K27: RELEASE | L27: Active profile row plus explicit KEEP in the final signed summary. | M27: 2026-06-27 — Latest dispense DISP-018-1: levothyroxine 75 mcg tablet; filled; 90 units / 90 days 2026-07-11 17:45 — Admission ADM-0710-020 (ADM-V2): levothyroxine 75 mcg tablet; active; Take 1 tablet by mouth every morning 2026-07-13 09:15 — Portal PTL-0713-017: levothyroxine; taking; Takes before breakfast. 2026-07-13 16:40 — Final summary DCS-MED-013: Continue levothyroxine 75 mcg tablet; Take 1 tablet by mouth every morning 2026-07-14 22:20 — Pharmacy snapshot RXH-0714-018: levothyroxine 75 mcg tablet; profile=active; fill=filled | N27: levothyroxine 75 mcg tablet | Take 1 tablet by mouth every morning | P27: DCS-MED-013 | Continue | levothyroxine 75 mcg tablet | Take 1 tablet by mouth every morning | Continue. | S27: ADM-0710-020 | ADM-V2 | levothyroxine 75 mcg tablet | 75 mcg | Take 1 tablet by mouth every morning | active | captured 2026-07-11 17:45 | T27: PTL-0713-017 | levothyroxine | 75 mcg | early morning | taking | Takes before breakfast. | U27: RXH-0714-018 | levothyroxine 75 mcg tablet | profile=active | fill=filled | last_fill=2026-06-29 | Take 1 tablet by mouth every morning | refills available | V27: 2 row(s) | latest=2026-06-27 | status=filled | qty=90 | days=90
A28: MED-025 | B28: Sertraline 50 mg tablet | C28: sertraline 50 mg tablet; sertraline | D28: LOW | E28: NO OPEN ESCALATION | F28: Owen Laird, PharmD — Outpatient Pharmacy | G28: 46218 | H28: KEEP | I28: RESOLVED | J28: YES | K28: RELEASE | L28: Active profile row plus explicit KEEP in the final signed summary. | M28: 2026-07-03 — Latest dispense DISP-019-1: sertraline 50 mg tablet; filled; 30 units / 30 days 2026-07-10 08:12 — Admission ADM-0710-021 (ADM-V1): sertraline 50 mg tablet; active; Take 1 tablet by mouth daily 2026-07-13 09:15 — Portal PTL-0713-018: sertraline; taking; No change reported. 2026-07-13 16:40 — Final summary DCS-MED-014: Continue sertraline 50 mg tablet; Take 1 tablet by mouth daily 2026-07-14 22:20 — Pharmacy snapshot RXH-0714-019: sertraline 50 mg tablet; profile=active; fill=filled | N28: sertraline 50 mg tablet | Take 1 tablet by mouth daily | P28: DCS-MED-014 | Continue | sertraline 50 mg tablet | Take 1 tablet by mouth daily | Continue. | S28: ADM-0710-021 | ADM-V1 | sertraline 50 mg tablet | 50 mg | Take 1 tablet by mouth daily | active | captured 2026-07-10 08:12 | T28: PTL-0713-018 | sertraline | 50 mg | daily | taking | No change reported. | U28: RXH-0714-019 | sertraline 50 mg tablet | profile=active | fill=filled | last_fill=2026-07-03 | Take 1 tablet by mouth daily | refills available | V28: 2 row(s) | latest=2026-07-03 | status=filled | qty=30 | days=30
A29: MED-026 | B29: Trazodone 50 mg tablet | C29: trazodone 50 mg tablet; trazodone | D29: LOW | E29: ACTIVE PROFILE — STOP ACTION | F29: Owen Laird, PharmD — Outpatient Pharmacy | G29: 46218 | H29: STOP | I29: RESOLVED | J29: YES | K29: STOP | L29: Active profile row plus explicit STOP in the final signed summary. | M29: 2026-06-24 — Latest dispense DISP-020-1: trazodone 50 mg tablet; filled; 30 units / 30 days 2026-07-10 08:12 — Admission ADM-0710-022 (ADM-V1): trazodone 50 mg tablet; active PRN; Take 1 tablet by mouth at bedtime as needed 2026-07-13 09:15 — Portal PTL-0713-019: trazodone; taking as needed; Uses a few nights each week. 2026-07-13 16:40 — Final summary DCS-STOP-011: Stop trazodone 50 mg tablet; Stop at discharge 2026-07-14 22:20 — Pharmacy snapshot RXH-0714-020: trazodone 50 mg tablet; profile=active; fill=filled | N29: trazodone 50 mg tablet | Stop at discharge | O29: Pharmacy profile remains active despite explicit discharge stop. | P29: DCS-STOP-011 | Stop | trazodone 50 mg tablet | Stop at discharge | No active outpatient order after transition. | S29: ADM-0710-022 | ADM-V1 | trazodone 50 mg tablet | 50 mg | Take 1 tablet by mouth at bedtime as needed | active PRN | captured 2026-07-10 08:12 | T29: PTL-0713-019 | trazodone | 50 mg | at bedtime if needed | taking as needed | Uses a few nights each week. | U29: RXH-0714-020 | trazodone 50 mg tablet | profile=active | fill=filled | last_fill=2026-06-28 | Take 1 tablet by mouth at bedtime as needed | refills available | V29: 3 row(s) | latest=2026-06-24 | status=filled | qty=30 | days=30
A30: MED-027 | B30: Vitamin D3 2,000 unit capsule | C30: vitamin D3 2,000 unit capsule; vitamin D | D30: LOW | E30: NO OPEN ESCALATION | F30: Owen Laird, PharmD — Outpatient Pharmacy | G30: 46220 | H30: KEEP | I30: RESOLVED | J30: NO | L30: No action: no pharmacy-profile row exists for this identity. Retain the source disposition for crosswalk/history; route any signed order through normal intake. | M30: 2026-07-10 08:12 — Admission ADM-0710-023 (ADM-V1): vitamin D3 2,000 unit capsule; active OTC; Take 1 capsule by mouth daily 2026-07-13 09:15 — Portal PTL-0713-020: vitamin D; taking; OTC supplement. 2026-07-13 16:40 — Final summary DCS-MED-015: Continue vitamin D3 2,000 unit capsule; Take 1 capsule by mouth daily | N30: vitamin D3 2,000 unit capsule | Take 1 capsule by mouth daily | P30: DCS-MED-015 | Continue | vitamin D3 2,000 unit capsule | Take 1 capsule by mouth daily | Continue. | S30: ADM-0710-023 | ADM-V1 | vitamin D3 2,000 unit capsule | 2,000 units | Take 1 capsule by mouth daily | active OTC | captured 2026-07-10 08:12 | T30: PTL-0713-020 | vitamin D | 2000 IU | daily | taking | OTC supplement.
A31: MED-028 | B31: Fish oil 1,000 mg capsule | C31: fish oil; fish oil 1,000 mg capsule | D31: LOW | E31: NO OPEN ESCALATION | F31: Owen Laird, PharmD — Outpatient Pharmacy | G31: 46220 | H31: STOP | I31: RESOLVED | J31: NO | L31: No action: no pharmacy-profile row exists for this identity. Retain the source disposition for crosswalk/history; route any signed order through normal intake. | M31: 2026-07-13 09:15 — Portal PTL-0713-021: fish oil; taking; Patient reported supplement. 2026-07-13 16:40 — Final summary DCS-STOP-012: Stop fish oil 1,000 mg capsule; Stop at discharge | N31: fish oil 1,000 mg capsule | Stop at discharge | P31: DCS-STOP-012 | Stop | fish oil 1,000 mg capsule | Stop at discharge | Nonessential supplement not continued. | T31: PTL-0713-021 | fish oil | 1,000 mg | daily | taking | Patient reported supplement.
A32: MED-029 | B32: Multivitamin tablet | C32: multivitamin tablet; multivitamin | D32: LOW | E32: NO OPEN ESCALATION | F32: Owen Laird, PharmD — Outpatient Pharmacy | G32: 46220 | H32: KEEP | I32: RESOLVED | J32: NO | L32: No action: no pharmacy-profile row exists for this identity. Retain the source disposition for crosswalk/history; route any signed order through normal intake. | M32: 2026-07-11 17:45 — Admission ADM-0710-024 (ADM-V2): multivitamin tablet; active OTC; Take 1 tablet by mouth daily 2026-07-13 09:15 — Portal PTL-0713-022: multivitamin; taking; OTC. 2026-07-13 16:40 — Final summary DCS-MED-016: Continue multivitamin tablet; Take 1 tablet by mouth daily | N32: multivitamin tablet | Take 1 tablet by mouth daily | P32: DCS-MED-016 | Continue | multivitamin tablet | Take 1 tablet by mouth daily | Continue. | S32: ADM-0710-024 | ADM-V2 | multivitamin tablet | 1 tablet | Take 1 tablet by mouth daily | active OTC | captured 2026-07-11 17:45 | T32: PTL-0713-022 | multivitamin | 1 tablet | daily | taking | OTC.
A33: MED-030 | B33: Docusate 100 mg capsule | C33: docusate 100 mg capsule; docusate | D33: LOW | E33: NO OPEN ESCALATION | F33: Owen Laird, PharmD — Outpatient Pharmacy | G33: 46220 | H33: STOP | I33: RESOLVED | J33: NO | L33: No action: pharmacy-profile row is inactive. Retain the source disposition for crosswalk/history; do not infer a treatment or fill decision. | M33: 2026-05-30 — Latest dispense DISP-021-1: docusate 100 mg capsule; filled; 60 units / 30 days 2026-07-10 08:12 — Admission ADM-0710-025 (ADM-V1): docusate 100 mg capsule; active PRN; Take 1 capsule by mouth twice daily 2026-07-13 09:15 — Portal PTL-0713-023: docusate; taking; Keeps with other bottles. 2026-07-13 16:40 — Final summary DCS-STOP-013: Stop docusate 100 mg capsule; Stop at discharge 2026-07-14 22:20 — Pharmacy snapshot RXH-0714-021: docusate 100 mg capsule; profile=inactive; fill=filled | N33: docusate 100 mg capsule | Stop at discharge | P33: DCS-STOP-013 | Stop | docusate 100 mg capsule | Stop at discharge | Use senna order if needed. | S33: ADM-0710-025 | ADM-V1 | docusate 100 mg capsule | 100 mg | Take 1 capsule by mouth twice daily | active PRN | captured 2026-07-10 08:12 | T33: PTL-0713-023 | docusate | 100 mg | twice daily | taking | Keeps with other bottles. | U33: RXH-0714-021 | docusate 100 mg capsule | profile=inactive | fill=filled | last_fill=2026-06-01 | Take 1 capsule by mouth twice daily | profile inactive after transition | V33: 3 row(s) | latest=2026-05-30 | status=filled | qty=60 | days=30
A34: MED-031 | B34: Senna 8.6 mg tablet | C34: senna 8.6 mg tablet | D34: LOW | E34: NO OPEN ESCALATION | F34: Owen Laird, PharmD — Outpatient Pharmacy | G34: 46220 | H34: KEEP | I34: RESOLVED | J34: NO | L34: No action: no pharmacy-profile row exists for this identity. Retain the source disposition for crosswalk/history; route any signed order through normal intake. | M34: 2026-07-13 16:40 — Final summary DCS-MED-017: Continue senna 8.6 mg tablet; Take 1 tablet by mouth nightly | N34: senna 8.6 mg tablet | Take 1 tablet by mouth nightly | O34: New discharge bowel regimen is absent from latest pharmacy profile. | P34: DCS-MED-017 | Continue | senna 8.6 mg tablet | Take 1 tablet by mouth nightly | New discharge bowel regimen.
A35: MED-032 | B35: Oxycodone 5 mg tablet | C35: oxycodone 5 mg tablet; oxycodone | D35: HIGH | E35: HIGH-RISK REVIEW | F35: Owen Laird, PharmD — Outpatient Pharmacy | G35: 46218 | H35: STOP | I35: RESOLVED | J35: NO | L35: No action: pharmacy-profile row is inactive. Retain the source disposition for crosswalk/history; do not infer a treatment or fill decision. | M35: 2026-06-25 — Latest dispense DISP-022-1: oxycodone 5 mg tablet; filled; 20 units / 5 days 2026-07-10 08:12 — Admission ADM-0710-026 (ADM-V1): oxycodone 5 mg tablet; old acute fill; Take 1 tablet every 6 hours as needed 2026-07-13 09:15 — Portal PTL-0713-024: oxycodone; has supply; Leftover from procedure. 2026-07-13 16:40 — Final summary DCS-STOP-014: Stop oxycodone 5 mg tablet; Stop at discharge 2026-07-14 22:20 — Pharmacy snapshot RXH-0714-022: oxycodone 5 mg tablet; profile=inactive; fill=filled | N35: oxycodone 5 mg tablet | Stop at discharge | P35: DCS-STOP-014 | Stop | oxycodone 5 mg tablet | Stop at discharge | No active opioid order after transition. | S35: ADM-0710-026 | ADM-V1 | oxycodone 5 mg tablet | 5 mg | Take 1 tablet every 6 hours as needed | old acute fill | captured 2026-07-10 08:12 | T35: PTL-0713-024 | oxycodone | 5 mg | only if pain is bad | has supply | Leftover from procedure. | U35: RXH-0714-022 | oxycodone 5 mg tablet | profile=inactive | fill=filled | last_fill=2026-06-25 | Take 1 tablet every 6 hours as needed | profile inactive after transition | V35: 2 row(s) | latest=2026-06-25 | status=filled | qty=20 | days=5
A36: MED-033 | B36: Gabapentin 300 mg capsule | C36: gabapentin 300 mg capsule; gabapentin | D36: LOW | E36: NO OPEN ESCALATION | F36: Owen Laird, PharmD — Outpatient Pharmacy | G36: 46218 | H36: KEEP | I36: RESOLVED | J36: YES | K36: RELEASE | L36: Active profile row plus explicit KEEP in the final signed summary. | M36: 2026-07-04 — Latest dispense DISP-023-1: gabapentin 300 mg capsule; filled; 90 units / 30 days 2026-07-10 08:12 — Admission ADM-0710-027 (ADM-V1): gabapentin 300 mg capsule; active; Take 1 capsule by mouth three times daily 2026-07-13 09:15 — Portal PTL-0713-025: gabapentin; taking; No change reported. 2026-07-13 16:40 — Final summary DCS-MED-018: Continue gabapentin 300 mg capsule; Take 1 capsule by mouth three times daily 2026-07-14 22:20 — Pharmacy snapshot RXH-0714-023: gabapentin 300 mg capsule; profile=active; fill=filled | N36: gabapentin 300 mg capsule | Take 1 capsule by mouth three times daily | P36: DCS-MED-018 | Continue | gabapentin 300 mg capsule | Take 1 capsule by mouth three times daily | Continue. | S36: ADM-0710-027 | ADM-V1 | gabapentin 300 mg capsule | 300 mg | Take 1 capsule by mouth three times daily | active | captured 2026-07-10 08:12 | T36: PTL-0713-025 | gabapentin | 300 mg | three times a day | taking | No change reported. | U36: RXH-0714-023 | gabapentin 300 mg capsule | profile=active | fill=filled | last_fill=2026-07-04 | Take 1 capsule by mouth three times daily | refills available | V36: 3 row(s) | latest=2026-07-04 | status=filled | qty=90 | days=30
A37: MED-034 | B37: Nitroglycerin 0.4 mg SL tablet | C37: nitroglycerin 0.4 mg sublingual tablet; nitro tabs; nitroglycerin 0.4 mg SL tablet | D37: MED | E37: MED-RISK REVIEW | F37: Owen Laird, PharmD — Outpatient Pharmacy | G37: 46218 | H37: KEEP | I37: RESOLVED | J37: YES | K37: RELEASE | L37: Active profile row plus explicit KEEP in the final signed summary. | M37: 2026-05-15 — Latest dispense DISP-024-1: nitroglycerin 0.4 mg SL tablet; filled; 25 units / 30 days 2026-07-11 17:45 — Admission ADM-0710-028 (ADM-V2): nitroglycerin 0.4 mg sublingual tablet; active PRN; Dissolve 1 tablet under tongue as needed 2026-07-13 09:15 — Portal PTL-0713-026: nitro tabs; taking as needed; Bottle is old but carried. 2026-07-13 16:40 — Final summary DCS-MED-019: Continue nitroglycerin 0.4 mg SL tablet; Dissolve 1 tablet under tongue as needed per label 2026-07-14 22:20 — Pharmacy snapshot RXH-0714-024: nitroglycerin 0.4 mg SL tablet; profile=active; fill=filled | N37: nitroglycerin 0.4 mg SL tablet | Dissolve 1 tablet under tongue as needed per label | P37: DCS-MED-019 | Continue | nitroglycerin 0.4 mg SL tablet | Dissolve 1 tablet under tongue as needed per label | Continue PRN medication. | S37: ADM-0710-028 | ADM-V2 | nitroglycerin 0.4 mg sublingual tablet | 0.4 mg | Dissolve 1 tablet under tongue as needed | active PRN | captured 2026-07-11 17:45 | T37: PTL-0713-026 | nitro tabs | 0.4 mg | under tongue if chest pain | taking as needed | Bottle is old but carried. | U37: RXH-0714-024 | nitroglycerin 0.4 mg SL tablet | profile=active | fill=filled | last_fill=2026-05-17 | Dissolve 1 tablet under tongue as needed | refills available | V37: 3 row(s) | latest=2026-05-15 | status=filled | qty=25 | days=30
A38: MED-035 | B38: Magnesium oxide 400 mg tablet | C38: magnesium oxide 400 mg tablet; magnesium oxide | D38: MED | E38: OPEN ESCALATION | F38: Owen Laird, PharmD — route to Discharging Service | G38: 46218 | H38: CLARIFY | I38: OPEN | J38: YES | K38: CLARIFY | L38: CLARIFY: final summary is silent; discharging-service answer is still requested. | M38: 2026-06-19 — Latest dispense DISP-025-1: magnesium oxide 400 mg tablet; filled; 30 units / 30 days 2026-07-10 08:12 — Admission ADM-0710-029 (ADM-V1): magnesium oxide 400 mg tablet; active at admission; Take 1 tablet by mouth daily 2026-07-13 09:15 — Portal PTL-0713-027: magnesium oxide; taking; Patient says it was added after cramps. 2026-07-14 08:24 — Queue RCQ-7737: ask discharging service; open/current 2026-07-14 15:10 — Prescriber clarification: Needs an answer from discharging service. 2026-07-14 22:20 — Pharmacy snapshot RXH-0714-038: magnesium oxide 400 mg tablet; profile=active; fill=filled | O38: Final summary silent; obtain discharging-service decision. | Q38: 2026-07-14 15:10 — Needs an answer from discharging service. | R38: RCQ-7737 | 2026-07-14 08:24 | ask discharging service | open/current | Patient reports active use, final transition summary silent. | S38: ADM-0710-029 | ADM-V1 | magnesium oxide 400 mg tablet | 400 mg | Take 1 tablet by mouth daily | active at admission | captured 2026-07-10 08:12 | T38: PTL-0713-027 | magnesium oxide | 400 mg | daily | taking | Patient says it was added after cramps. | U38: RXH-0714-038 | magnesium oxide 400 mg tablet | profile=active | fill=filled | last_fill=2026-06-22 | Take 1 tablet by mouth daily | refills available | V38: 2 row(s) | latest=2026-06-19 | status=filled | qty=30 | days=30

Sheet Summary_Checks
A1: Live Medication Reconciliation Summary And Checks
A2: Formula-driven from MedRecTable. Edit Med_Reconciliation; counts and checks recalculate automatically when the workbook opens.
A4: Metric / check | B4: Live result | C4: Expected | D4: Status
A5: Retained medication identities | B5: =COUNTA(MedRecTable[Identity ID]) | C5: 35 retained rows
A6: Active profile identities | B6: =COUNTIF(MedRecTable[Active profile row?],"YES") | C6: Live count
A7: RELEASE actions | B7: =COUNTIF(MedRecTable[Same-day profile action],"RELEASE") | C7: Live count
A8: CHANGE actions | B8: =COUNTIF(MedRecTable[Same-day profile action],"CHANGE") | C8: Live count
A9: STOP actions | B9: =COUNTIF(MedRecTable[Same-day profile action],"STOP") | C9: Live count
A10: CLARIFY actions | B10: =COUNTIF(MedRecTable[Same-day profile action],"CLARIFY") | C10: Live count
A11: All active-profile actions | B11: =COUNTIF(MedRecTable[Same-day profile action],"<>") | C11: Live count
A12: HIGH-risk identities | B12: =COUNTIF(MedRecTable[Risk],"HIGH") | C12: Live count
A13: MED-risk identities | B13: =COUNTIF(MedRecTable[Risk],"MED") | C13: Live count
A14: LOW-risk identities | B14: =COUNTIF(MedRecTable[Risk],"LOW") | C14: Live count
A15: OPEN evidence statuses | B15: =COUNTIF(MedRecTable[Evidence status],"OPEN") | C15: Live count
A16: Due 2026-07-15 | B16: =COUNTIF(MedRecTable[Due date],DATE(2026,7,15)) | C16: Live count
A17: Due 2026-07-16 | B17: =COUNTIF(MedRecTable[Due date],DATE(2026,7,16)) | C17: Live count
A18: Due 2026-07-17 | B18: =COUNTIF(MedRecTable[Due date],DATE(2026,7,17)) | C18: Live count
A20: Integrity check | B20: Live exceptions | C20: Expected | D20: Status
A21: Active profile rows missing an action | B21: =COUNTIFS(MedRecTable[Active profile row?],"YES",MedRecTable[Same-day profile action],"") | C21: 0 | D21: =IF(B21=C21,"PASS","CHECK")
A22: Non-active rows carrying a profile action | B22: =COUNTIFS(MedRecTable[Active profile row?],"NO",MedRecTable[Same-day profile action],"<>") | C22: 0 | D22: =IF(B22=C22,"PASS","CHECK")
A23: Action count differs from active-profile count | B23: =ABS(COUNTIF(MedRecTable[Active profile row?],"YES")-COUNTIF(MedRecTable[Same-day profile action],"<>")) | C23: 0 | D23: =IF(B23=C23,"PASS","CHECK")
A24: Profile actions outside RELEASE/CHANGE/STOP/CLARIFY | B24: =COUNTIF(MedRecTable[Same-day profile action],"<>")-COUNTIF(MedRecTable[Same-day profile action],"RELEASE")-COUNTIF(MedRecTable[Same-day profile action],"CHANGE")-COUNTIF(MedRecTable[Same-day profile action],"STOP")-COUNTIF(MedRecTable[Same-day profile action],"CLARIFY") | C24: 0 | D24: =IF(B24=C24,"PASS","CHECK")
A25: Rows missing assigned owner | B25: =COUNTBLANK(MedRecTable[Assigned owner]) | C25: 0 | D25: =IF(B25=C25,"PASS","CHECK")
A26: Rows missing due date | B26: =COUNTBLANK(MedRecTable[Due date]) | C26: 0 | D26: =IF(B26=C26,"PASS","CHECK")
A27: Rows missing evidence timeline | B27: =COUNTBLANK(MedRecTable[Evidence timeline]) | C27: 0 | D27: =IF(B27=C27,"PASS","CHECK")
A28: CLARIFY action count differs from OPEN evidence count | B28: =ABS(COUNTIF(MedRecTable[Same-day profile action],"CLARIFY")-COUNTIF(MedRecTable[Evidence status],"OPEN")) | C28: 0 | D28: =IF(B28=C28,"PASS","CHECK")
A29: Duplicate retained identity IDs | B29: =SUMPRODUCT(--(COUNTIF(MedRecTable[Identity ID],MedRecTable[Identity ID])>1)) | C29: 0 | D29: =IF(B29=C29,"PASS","CHECK")

Sheet Action_View
A1: Recomputable Action View
A2: Linked to Med_Reconciliation. Use the table filters here for RELEASE, CHANGE, STOP, CLARIFY, owner, due date, risk, or evidence status; edit the source sheet, not this view.
A4: Identity ID | B4: Medication identity | C4: Risk | D4: Escalation status | E4: Assigned owner | F4: Due date | G4: Evidence status | H4: Active profile? | I4: Profile action | J4: Action basis | K4: Evidence timeline | L4: Gap / next action
A5: ='Med_Reconciliation'!A4 | B5: ='Med_Reconciliation'!B4 | C5: ='Med_Reconciliation'!D4 | D5: ='Med_Reconciliation'!E4 | E5: ='Med_Reconciliation'!F4 | F5: ='Med_Reconciliation'!G4 | G5: ='Med_Reconciliation'!I4 | H5: ='Med_Reconciliation'!J4 | I5: ='Med_Reconciliation'!K4 | J5: ='Med_Reconciliation'!L4 | K5: ='Med_Reconciliation'!M4 | L5: ='Med_Reconciliation'!O4
A6: ='Med_Reconciliation'!A5 | B6: ='Med_Reconciliation'!B5 | C6: ='Med_Reconciliation'!D5 | D6: ='Med_Reconciliation'!E5 | E6: ='Med_Reconciliation'!F5 | F6: ='Med_Reconciliation'!G5 | G6: ='Med_Reconciliation'!I5 | H6: ='Med_Reconciliation'!J5 | I6: ='Med_Reconciliation'!K5 | J6: ='Med_Reconciliation'!L5 | K6: ='Med_Reconciliation'!M5 | L6: ='Med_Reconciliation'!O5
A7: ='Med_Reconciliation'!A6 | B7: ='Med_Reconciliation'!B6 | C7: ='Med_Reconciliation'!D6 | D7: ='Med_Reconciliation'!E6 | E7: ='Med_Reconciliation'!F6 | F7: ='Med_Reconciliation'!G6 | G7: ='Med_Reconciliation'!I6 | H7: ='Med_Reconciliation'!J6 | I7: ='Med_Reconciliation'!K6 | J7: ='Med_Reconciliation'!L6 | K7: ='Med_Reconciliation'!M6 | L7: ='Med_Reconciliation'!O6
A8: ='Med_Reconciliation'!A7 | B8: ='Med_Reconciliation'!B7 | C8: ='Med_Reconciliation'!D7 | D8: ='Med_Reconciliation'!E7 | E8: ='Med_Reconciliation'!F7 | F8: ='Med_Reconciliation'!G7 | G8: ='Med_Reconciliation'!I7 | H8: ='Med_Reconciliation'!J7 | I8: ='Med_Reconciliation'!K7 | J8: ='Med_Reconciliation'!L7 | K8: ='Med_Reconciliation'!M7 | L8: ='Med_Reconciliation'!O7
A9: ='Med_Reconciliation'!A8 | B9: ='Med_Reconciliation'!B8 | C9: ='Med_Reconciliation'!D8 | D9: ='Med_Reconciliation'!E8 | E9: ='Med_Reconciliation'!F8 | F9: ='Med_Reconciliation'!G8 | G9: ='Med_Reconciliation'!I8 | H9: ='Med_Reconciliation'!J8 | I9: ='Med_Reconciliation'!K8 | J9: ='Med_Reconciliation'!L8 | K9: ='Med_Reconciliation'!M8 | L9: ='Med_Reconciliation'!O8
A10: ='Med_Reconciliation'!A9 | B10: ='Med_Reconciliation'!B9 | C10: ='Med_Reconciliation'!D9 | D10: ='Med_Reconciliation'!E9 | E10: ='Med_Reconciliation'!F9 | F10: ='Med_Reconciliation'!G9 | G10: ='Med_Reconciliation'!I9 | H10: ='Med_Reconciliation'!J9 | I10: ='Med_Reconciliation'!K9 | J10: ='Med_Reconciliation'!L9 | K10: ='Med_Reconciliation'!M9 | L10: ='Med_Reconciliation'!O9
A11: ='Med_Reconciliation'!A10 | B11: ='Med_Reconciliation'!B10 | C11: ='Med_Reconciliation'!D10 | D11: ='Med_Reconciliation'!E10 | E11: ='Med_Reconciliation'!F10 | F11: ='Med_Reconciliation'!G10 | G11: ='Med_Reconciliation'!I10 | H11: ='Med_Reconciliation'!J10 | I11: ='Med_Reconciliation'!K10 | J11: ='Med_Reconciliation'!L10 | K11: ='Med_Reconciliation'!M10 | L11: ='Med_Reconciliation'!O10
A12: ='Med_Reconciliation'!A11 | B12: ='Med_Reconciliation'!B11 | C12: ='Med_Reconciliation'!D11 | D12: ='Med_Reconciliation'!E11 | E12: ='Med_Reconciliation'!F11 | F12: ='Med_Reconciliation'!G11 | G12: ='Med_Reconciliation'!I11 | H12: ='Med_Reconciliation'!J11 | I12: ='Med_Reconciliation'!K11 | J12: ='Med_Reconciliation'!L11 | K12: ='Med_Reconciliation'!M11 | L12: ='Med_Reconciliation'!O11
A13: ='Med_Reconciliation'!A12 | B13: ='Med_Reconciliation'!B12 | C13: ='Med_Reconciliation'!D12 | D13: ='Med_Reconciliation'!E12 | E13: ='Med_Reconciliation'!F12 | F13: ='Med_Reconciliation'!G12 | G13: ='Med_Reconciliation'!I12 | H13: ='Med_Reconciliation'!J12 | I13: ='Med_Reconciliation'!K12 | J13: ='Med_Reconciliation'!L12 | K13: ='Med_Reconciliation'!M12 | L13: ='Med_Reconciliation'!O12
