Workbook

Sheet Read_Me
A1: Workbook owner | B1: Dana Morales, Advertising Sales Desk Supervisor
A2: Lifecycle state | B2: Approved executable record
A3: Approved objective | B3: Rank the July escalated renewal portfolio and convert approved accounts into compliant recovery actions.
A4: Source refresh | B4: CRM 2026-07-13; ad-ops 2026-07-13; orders 2026Q3; contacts 2026-07-10; activity through 2026-07-14; approval 2026-07-15.
A5: Navigation | B5: Use Dashboard first, then Scoring, Decisions, Checks, and Raw_Data sheets for lineage.

Sheet Metric_Definitions
A1: Metric | B1: Definition | C1: Unit
A2: Renewal exposure | B2: Renewal opportunity amount from order history | C2: USD
A3: Forecast variance | B3: Current Q3 forecast minus Q3 2025 baseline | C3: USD
A4: Issue burden score | B4: Open case count, severity, and issue age | C4: 0-100
A5: Operational recovery risk | B5: Weighted health, issue burden, and activity aging risk | C5: 0-100
A6: Priority score | B6: Exposure, risk, urgency, contact readiness, and forecast variance weighted for recovery order | C6: 0-100
A7: Offer compliance | B7: Recommended offer stays within local authority or remains a controlled exception | C7: Status

Sheet Assumptions
A1: Assumption | B1: Value
A2: Exposure weight | B2: 0.3
A3: Recovery risk weight | B3: 0.35
A4: Urgency weight | B4: 0.2
A5: Contact readiness weight | B5: 0.1
A6: Forecast variance weight | B6: 0.05
A7: Exposure score denominator | B7: 400000
A8: As of date | B8: 46218
D11: PriorityTierList | E11: DecisionStatusList | F11: DecisionActionList | G11: ExceptionRouteList
D12: Tier 1 | E12: Approved execution | F12: Confirm makegood inventory and delivery recovery plan | G12: Decision-maker outreach permission pending
D13: Tier 2 | E13: Controlled exception | F13: Deliver reconciled reporting package and executive summary | G13: Requested credit is above supervisor authority
D14: Tier 3 | E14: Excluded - no action | F14: Confirm verified billing credit and renewal rate hold | G14: Ad-ops blocker not cleared
D15: Controlled exception/hold | F15: Offer equivalent package swap after trafficking confirmation | G15: Closed renewal
F16: Swap misaligned audience package and reset delivery proof | G16: Contract terms outside local authority
F17: Confirm verified invoice credit and corrected bill date | G17: Customer requested September review
F18: Confirm makegood placement and revised delivery dates | G18: Ready to schedule
F19: Send reconciled district reach report and renewal summary | G19: Controlled exception
F20: Confirm package swap and creative approval timeline | G20: No sprint outreach
F21: Offer 60-day rate hold without additional credit
F22: Send corrected lift summary and renewal confidence note
F23: Confirm makegood placement and invoice correction route
F24: Hold customer-facing offer until decision-maker route is approved
F25: Route credit request to manager; do not promise local credit
F26: Wait for product feed fix before customer offer
F27: No sprint action; keep closure note
F28: Escalate to manager and legal owner; no rep commitment
F29: Hold for September agency review

Sheet Raw_CRM
A1: Account ID | B1: Account Name | C1: Segment | D1: Account Tier | E1: Owner Rep | F1: Renewal Date | G1: Health Score | H1: Lifecycle State | I1: Forecast Category | J1: Requested Recovery Value | K1: Escalation Reason | L1: Approved Action Note
A2: A-1001 | B2: Meridian Health Partners | C2: Healthcare | D2: Key Growth | E2: Maya Chen | F2: 46227 | G2: 48 | H2: Approved execution | I2: Commit at risk | J2: 21000 | K2: Delivery underpacing and reporting trust | L2: Confirm makegood inventory and delivery recovery plan
A3: A-1002 | B3: Larkspur Credit Union | C3: Financial Services | D3: Core | E3: Jordan Patel | F3: 46234 | G3: 52 | H3: Approved execution | I3: Best case | J3: 0 | K3: Reporting discrepancy | L3: Deliver reconciled reporting package and executive summary
A4: A-1003 | B4: Cobalt Cloud Systems | C4: Technology | D4: Key Growth | E4: Priya Nair | F4: 46239 | G4: 56 | H4: Approved execution | I4: Commit at risk | J4: 9500 | K4: Invoice credit and rate hold request | L4: Confirm verified billing credit and renewal rate hold
A5: A-1004 | B5: Harborview Furnishings | C5: Retail | D5: Core | E5: Luis Romero | F5: 46231 | G5: 61 | H5: Approved execution | I5: Best case | J5: 12000 | K5: Creative trafficking delay | L5: Offer equivalent package swap after trafficking confirmation
A6: A-1005 | B6: Axion Robotics | C6: Industrial | D6: Key Growth | E6: Devon Brooks | F6: 46246 | G6: 44 | H6: Approved execution | I6: Commit at risk | J6: 18000 | K6: Audience mismatch and delivery quality | L6: Swap misaligned audience package and reset delivery proof
A7: A-1006 | B7: Greenway Kitchens | C7: Retail | D7: Emerging | E7: Maya Chen | F7: 46229 | G7: 68 | H7: Approved execution | I7: Pipeline | J7: 4800 | K7: Billing error | L7: Confirm verified invoice credit and corrected bill date
A8: A-1007 | B8: Northline Insurance | C8: Financial Services | D8: Core | E8: Jordan Patel | F8: 46237 | G8: 50 | H8: Approved execution | I8: Commit at risk | J8: 22000 | K8: Delivery underpacing | L8: Confirm makegood placement and revised delivery dates
A9: A-1008 | B9: Veridian Charter Schools | C9: Education | D9: Emerging | E9: Priya Nair | F9: 46249 | G9: 63 | H9: Approved execution | I9: Pipeline | J9: 0 | K9: Reporting trust | L9: Send reconciled district reach report and renewal summary
A10: A-1009 | B10: Copper Trail Hospitality | C10: Travel | D10: Core | E10: Luis Romero | F10: 46232 | G10: 58 | H10: Approved execution | I10: Best case | J10: 15000 | K10: Creative approval blocker | L10: Confirm package swap and creative approval timeline
A11: A-1010 | B11: Finch Legal Group | C11: Professional Services | D11: Emerging | E11: Devon Brooks | F11: 46254 | G11: 70 | H11: Approved execution | I11: Pipeline | J11: 0 | K11: Renewal rate objection | L11: Offer 60-day rate hold without additional credit
A12: A-1011 | B12: Solstice Energy Co-op | C12: Energy | D12: Core | E12: Maya Chen | F12: 46243 | G12: 55 | H12: Approved execution | I12: Best case | J12: 0 | K12: Reporting discrepancy | L12: Send corrected lift summary and renewal confidence note
A13: A-1012 | B13: Vesta Apparel Collective | C13: Retail | D13: Key Growth | E13: Jordan Patel | F13: 46235 | G13: 47 | H13: Approved execution | I13: Commit at risk | J13: 24000 | K13: Delivery underpacing and invoice dispute | L13: Confirm makegood placement and invoice correction route
... A19: A-1018 | B19: Pinyon Outdoor Media Buyers | C19: Agency | D19: Core | E19: Priya Nair | F19: 46283 | G19: 66 | H19: Excluded - September review | I19: Pipeline | J19: 0 | K19: Customer requested pause until agency consolidation | L19: Hold for September agency review

Sheet Raw_Cases
A1: Case ID | B1: Account ID | C1: Order ID | D1: Issue Type | E1: Severity | F1: Severity Score | G1: Opened Date | H1: Issue Age Days | I1: Sla Target Date | J1: Last Update Date | K1: Expected Resolution Date | L1: Current Owner | M1: Issue Status | N1: Resolution Confidence | O1: Root Cause | P1: Customer Impact | Q1: Open Dependency
A2: CASE-7201 | B2: A-1001 | C2: ORD-73101 | D2: Delivery Underpacing | E2: High | F2: 4 | G2: 46193 | H2: 25 | I2: 46211 | J2: 46216 | K2: 46219 | L2: Ad Ops - Lena Ortiz | M2: Waiting on Ad Ops | N2: Medium | O2: Inventory pacing lag | P2: Renewal confidence and delivery promise | Q2: Traffic pacing confirmation
A3: CASE-7202 | B3: A-1001 | C3: ORD-73101 | D3: Reporting Discrepancy | E3: Medium | F3: 3 | G3: 46205 | H3: 13 | I3: 46215 | J3: 46216 | K3: 46220 | L3: Reporting - Eli Park | M3: Open | N3: Medium | O3: UTM match mismatch | P3: Trust in delivery report | Q3: Reach report reconciliation
A4: CASE-7203 | B4: A-1002 | C4: ORD-73102 | D4: Reporting Discrepancy | E4: High | F4: 4 | G4: 46201 | H4: 17 | I4: 46212 | J4: 46216 | K4: 46220 | L4: Reporting - Eli Park | M4: Open | N4: High | O4: Audience reach export defect | P4: Renewal proof stalled | Q4: Corrected report
A5: CASE-7204 | B5: A-1003 | C5: ORD-73103 | D5: Billing Error | E5: High | F5: 4 | G5: 46191 | H5: 27 | I5: 46208 | J5: 46215 | K5: 46219 | L5: Billing - Nora Vale | M5: Resolved Pending Customer | N5: High | O5: Duplicate invoice line | P5: Signature withheld pending credit | Q5: Credit memo confirmation
A6: CASE-7205 | B6: A-1003 | C6: ORD-73103 | D6: Renewal Rate Objection | E6: Medium | F6: 3 | G6: 46211 | H6: 7 | I6: 46221 | J6: 46217 | K6: 46222 | L6: Sales Ops - Aaron Kim | M6: Waiting on Sales | N6: High | O6: Rate card update not explained | P6: Commercial approval delay | Q6: Rate hold language
A7: CASE-7206 | B7: A-1004 | C7: ORD-73104 | D7: Creative Trafficking | E7: Medium | F7: 3 | G7: 46204 | H7: 14 | I7: 46214 | J7: 46216 | K7: 46219 | L7: Ad Ops - Lena Ortiz | M7: Waiting on Ad Ops | N7: High | O7: Creative tags rejected | P7: Launch dates unclear | Q7: Creative retagging
A8: CASE-7207 | B8: A-1005 | C8: ORD-73105 | D8: Audience Mismatch | E8: Critical | F8: 5 | G8: 46187 | H8: 31 | I8: 46205 | J8: 46216 | K8: 46221 | L8: Product Support - Ravi Mehta | M8: Open | N8: Medium | O8: Lookalike seed list mismatch | P8: Audience quality dispute | Q8: Audience rebuild proof
A9: CASE-7208 | B9: A-1005 | C9: ORD-73105 | D9: Delivery Underpacing | E9: High | F9: 4 | G9: 46203 | H9: 15 | I9: 46213 | J9: 46216 | K9: 46221 | L9: Ad Ops - Lena Ortiz | M9: Waiting on Ad Ops | N9: Medium | O9: Audience cap after mismatch | P9: Forecast risk | Q9: Pacing reset
A10: CASE-7209 | B10: A-1006 | C10: ORD-73106 | D10: Billing Error | E10: Medium | F10: 3 | G10: 46208 | H10: 10 | I10: 46218 | J10: 46216 | K10: 46220 | L10: Billing - Nora Vale | M10: Open | N10: High | O10: Tax line miscoded | P10: Owner approval delayed | Q10: Credit memo draft
A11: CASE-7210 | B11: A-1007 | C11: ORD-73107 | D11: Delivery Underpacing | E11: High | F11: 4 | G11: 46195 | H11: 23 | I11: 46211 | J11: 46216 | K11: 46220 | L11: Ad Ops - Lena Ortiz | M11: Waiting on Ad Ops | N11: Medium | O11: Publisher inventory drop | P11: Written remedy requested | Q11: Makegood placement
A12: CASE-7211 | B12: A-1008 | C12: ORD-73108 | D12: Reporting Discrepancy | E12: Medium | F12: 3 | G12: 46209 | H12: 9 | I12: 46219 | J12: 46216 | K12: 46223 | L12: Reporting - Eli Park | M12: Open | N12: High | O12: District reach grouping error | P12: Budget meeting proof | Q12: Corrected district report
A13: CASE-7212 | B13: A-1009 | C13: ORD-73109 | D13: Creative Trafficking | E13: High | F13: 4 | G13: 46198 | H13: 20 | I13: 46210 | J13: 46216 | K13: 46219 | L13: Ad Ops - Lena Ortiz | M13: Waiting on Ad Ops | N13: Medium | O13: Brand safety tag review | P13: August flight risk | Q13: Creative approval proof
... A24: CASE-7223 | B24: A-1018 | C24: ORD-73118 | D24: Agency Consolidation | E24: Low | F24: 2 | G24: 46212 | H24: 6 | I24: 46227 | J24: 46217 | K24: 46267 | L24: Sales Ops - Aaron Kim | M24: Waiting on Customer | N24: High | O24: Agency buying team reorg | P24: Customer requested hold | Q24: September rebrief

Sheet Raw_Orders
A1: Account ID | B1: Opportunity ID | C1: Order ID | D1: Baseline Revenue | E1: Current Forecast | F1: Renewal Exposure | G1: Probability | H1: Forecast Category
A2: A-1001 | B2: OPP-2601 | C2: ORD-73101 | D2: 310000 | E2: 272000 | F2: 340000 | G2: 0.72 | H2: Commit at risk
A3: A-1002 | B3: OPP-2602 | C3: ORD-73102 | D3: 205000 | E3: 184000 | F3: 220000 | G3: 0.68 | H3: Best case
A4: A-1003 | B4: OPP-2603 | C4: ORD-73103 | D4: 275000 | E4: 240000 | F4: 295000 | G4: 0.65 | H4: Commit at risk
A5: A-1004 | B5: OPP-2604 | C5: ORD-73104 | D5: 142000 | E5: 129000 | F5: 150000 | G5: 0.7 | H5: Best case
A6: A-1005 | B6: OPP-2605 | C6: ORD-73105 | D6: 390000 | E6: 318000 | F6: 410000 | G6: 0.58 | H6: Commit at risk
A7: A-1006 | B7: OPP-2606 | C7: ORD-73106 | D7: 76000 | E7: 71000 | F7: 82000 | G7: 0.64 | H7: Pipeline
A8: A-1007 | B8: OPP-2607 | C8: ORD-73107 | D8: 246000 | E8: 206000 | F8: 260000 | G8: 0.61 | H8: Commit at risk
A9: A-1008 | B9: OPP-2608 | C9: ORD-73108 | D9: 98000 | E9: 88000 | F9: 110000 | G9: 0.6 | H9: Pipeline
A10: A-1009 | B10: OPP-2609 | C10: ORD-73109 | D10: 174000 | E10: 149000 | F10: 190000 | G10: 0.63 | H10: Best case
A11: A-1010 | B11: OPP-2610 | C11: ORD-73110 | D11: 72000 | E11: 70000 | F11: 75000 | G11: 0.59 | H11: Pipeline
A12: A-1011 | B12: OPP-2611 | C12: ORD-73111 | D12: 160000 | E12: 140000 | F12: 175000 | G12: 0.62 | H12: Best case
A13: A-1012 | B13: OPP-2612 | C13: ORD-73112 | D13: 290000 | E13: 238000 | F13: 305000 | G13: 0.57 | H13: Commit at risk
... A19: A-1018 | B19: OPP-2618 | C19: ORD-73118 | D19: 124000 | E19: 118000 | F19: 135000 | G19: 0.5 | H19: Pipeline

Sheet Raw_Contacts
A1: Contact ID | B1: Account ID | C1: Account Name | D1: Contact Name | E1: Title | F1: Contact Role | G1: Decision Authority | H1: Outreach Permission | I1: Preferred Channel | J1: Timezone | K1: Unavailable Window | L1: Sensitivity Flag | M1: Owner Rep | N1: Backup Owner
A2: CT-001A | B2: A-1001 | C2: Meridian Health Partners | D2: Dr. Lena Morris | E2: Chief Marketing Officer | F2: Final Renewal Approver | G2: Yes | H2: Approved | I2: Email then call | J2: Eastern | K2: None | L2: Executive expects delivery plan | M2: Maya Chen | N2: Devon Brooks
A3: CT-001B | B3: A-1001 | C3: Meridian Health Partners | D3: Nora Blake | E3: Ad Operations Counterpart | F3: Operational Contact | G3: No | H3: Approved | I3: Email | J3: Eastern | K3: None | L3: Standard operating route | M3: Maya Chen | N3: Devon Brooks
A4: CT-002A | B4: A-1002 | C4: Larkspur Credit Union | D4: Tanya Wells | E4: Director of Marketing | F4: Final Renewal Approver | G4: Yes | H4: Approved | I4: Email | J4: Central | K4: Avoid Friday after 12:00 | L4: Compliance copy required | M4: Jordan Patel | N4: Maya Chen
A5: CT-002B | B5: A-1002 | C5: Larkspur Credit Union | D5: Theo Walsh | E5: Compliance Marketing Contact | F5: Operational Contact | G5: No | H5: Approved | I5: Email | J5: Eastern | K5: None | L5: Standard operating route | M5: Jordan Patel | N5: Maya Chen
A6: CT-003A | B6: A-1003 | C6: Cobalt Cloud Systems | D6: Rafael Soto | E6: VP Demand Generation | F6: Final Renewal Approver | G6: Yes | H6: Approved | I6: Call | J6: Pacific | K6: Unavailable July 22 AM | L6: Wants billing proof first | M6: Priya Nair | N6: Jordan Patel
A7: CT-003B | B7: A-1003 | C7: Cobalt Cloud Systems | D7: Vikram Shah | E7: Demand Operations Contact | F7: Operational Contact | G7: No | H7: Approved | I7: Email | J7: Eastern | K7: None | L7: Standard operating route | M7: Priya Nair | N7: Jordan Patel
A8: CT-003C | B8: A-1003 | C8: Cobalt Cloud Systems | D8: Rafael Finance Desk | E8: Finance Contact | F8: Finance Contact | G8: No | H8: Finance Only | I8: Email | J8: Pacific | K8: None | L8: Use only for billing documentation | M8: Priya Nair | N8: Jordan Patel
A9: CT-004A | B9: A-1004 | C9: Harborview Furnishings | D9: Nina Cho | E9: Retail Media Lead | F9: Final Renewal Approver | G9: Yes | H9: Approved | I9: Email | J9: Pacific | K9: None | L9: Creative team must be copied | M9: Luis Romero | N9: Priya Nair
A10: CT-004B | B10: A-1004 | C10: Harborview Furnishings | D10: Paige Ellis | E10: Campaign Operations Contact | F10: Operational Contact | G10: No | H10: Approved | I10: Email | J10: Eastern | K10: None | L10: Standard operating route | M10: Luis Romero | N10: Priya Nair
A11: CT-005A | B11: A-1005 | C11: Axion Robotics | D11: Mark Feld | E11: VP Marketing | F11: Final Renewal Approver | G11: Yes | H11: Approved | I11: Call | J11: Central | K11: Unavailable July 19 | L11: Needs audience proof | M11: Devon Brooks | N11: Luis Romero
A12: CT-005B | B12: A-1005 | C12: Axion Robotics | D12: Olivia Grant | E12: Media Operations Contact | F12: Operational Contact | G12: No | H12: Approved | I12: Email | J12: Eastern | K12: None | L12: Standard operating route | M12: Devon Brooks | N12: Luis Romero
... A41: CT-018B | B41: A-1018 | C41: Pinyon Outdoor Media Buyers | D41: Noah Becker | E41: Agency Planner | F41: Operational Contact | G41: No | H41: Approved | I41: Email | J41: Pacific | K41: None | L41: Standard operating route | M41: Priya Nair | N41: Luis Romero

Sheet Raw_Activity
A1: Activity ID | B1: Account ID | C1: Owner Rep | D1: Activity Type | E1: Activity Date | F1: Customer Request | G1: Internal Commitment | H1: Commitment Due Date | I1: Commitment Status | J1: Confirmation Source | K1: Customer Sentiment | L1: Requested Decision Date | M1: Next Step | N1: Related Case ID | O1: Note
A2: ACT-26001A | B2: A-1001 | C2: Maya Chen | D2: Customer call | E2: 46206 | F2: CMO asked for delivery plan before renewal call. | G2: Open case review with operational owner | H2: 46210 | I2: Completed | J2: CRM call note | K2: Concerned | L2: 46227 | M2: Prepare recovery evidence | N2: CASE-7201 | O2: Initial escalation intake
A3: ACT-26001B | B3: A-1001 | C3: Maya Chen | D3: Email | E3: 46215 | F3: CMO asked for delivery plan before renewal call. | G3: Send corrected pacing plan | H3: 46217 | I3: Overdue | J3: Gmail thread | K3: Escalated | L3: 46227 | M3: Confirm makegood inventory and delivery recovery plan | N3: CASE-7201 | O3: Commitment carried into recovery review
A4: ACT-26002A | B4: A-1002 | C4: Jordan Patel | D4: Customer call | E4: 46204 | F4: Marketing director requested corrected reach report. | G4: Open case review with operational owner | H4: 46208 | I4: Completed | J4: CRM call note | K4: Concerned | L4: 46234 | M4: Prepare recovery evidence | N4: CASE-7203 | O4: Initial escalation intake
A5: ACT-26002B | B5: A-1002 | C5: Jordan Patel | D5: Email | E5: 46213 | F5: Marketing director requested corrected reach report. | G5: Provide reconciled reach report | H5: 46220 | I5: Open | J5: Gmail thread | K5: Concerned | L5: 46234 | M5: Deliver reconciled reporting package and executive summary | N5: CASE-7203 | O5: Commitment carried into recovery review
A6: ACT-26003A | B6: A-1003 | C6: Priya Nair | D6: Customer call | E6: 46205 | F6: Demand gen VP asked for invoice correction before signing. | G6: Open case review with operational owner | H6: 46209 | I6: Completed | J6: CRM call note | K6: Concerned | L6: 46235 | M6: Prepare recovery evidence | N6: CASE-7204 | O6: Initial escalation intake
A7: ACT-26003B | B7: A-1003 | C7: Priya Nair | D7: Email | E7: 46214 | F7: Demand gen VP asked for invoice correction before signing. | G7: Confirm billing investigation opened | H7: 46215 | I7: Completed | J7: Gmail thread | K7: Concerned | L7: 46239 | M7: Confirm verified billing credit and renewal rate hold | N7: CASE-7204 | O7: Commitment carried into recovery review
A8: ACT-26004A | B8: A-1004 | C8: Luis Romero | D8: Customer call | E8: 46203 | F8: Retail media lead requested trafficking fix and revised launch dates. | G8: Open case review with operational owner | H8: 46207 | I8: Completed | J8: CRM call note | K8: Cautious | L8: 46231 | M8: Prepare recovery evidence | N8: CASE-7206 | O8: Initial escalation intake
A9: ACT-26004B | B9: A-1004 | C9: Luis Romero | D9: Email | E9: 46212 | F9: Retail media lead requested trafficking fix and revised launch dates. | G9: Send creative retagging ETA | H9: 46215 | I9: Overdue | J9: Gmail thread | K9: Concerned | L9: 46231 | M9: Offer equivalent package swap after trafficking confirmation | N9: CASE-7206 | O9: Commitment carried into recovery review
A10: ACT-26005A | B10: A-1005 | C10: Devon Brooks | D10: Customer call | E10: 46202 | F10: VP Marketing requested audience correction plan before PO. | G10: Open case review with operational owner | H10: 46206 | I10: Completed | J10: CRM call note | K10: Concerned | L10: 46235 | M10: Prepare recovery evidence | N10: CASE-7207 | O10: Initial escalation intake
A11: ACT-26005B | B11: A-1005 | C11: Devon Brooks | D11: Email | E11: 46211 | F11: VP Marketing requested audience correction plan before PO. | G11: Share audience rebuild proof | H11: 46214 | I11: Missed | J11: No confirmation | K11: Escalated | L11: 46239 | M11: Swap misaligned audience package and reset delivery proof | N11: CASE-7207 | O11: Commitment carried into recovery review
A12: ACT-26006A | B12: A-1006 | C12: Maya Chen | D12: Customer call | E12: 46207 | F12: Owner asked for invoice correction before approving fall campaign. | G12: Open case review with operational owner | H12: 46211 | I12: Completed | J12: CRM call note | K12: Cautious | L12: 46229 | M12: Prepare recovery evidence | N12: CASE-7209 | O12: Initial escalation intake
A13: ACT-26006B | B13: A-1006 | C13: Maya Chen | D13: Email | E13: 46216 | F13: Owner asked for invoice correction before approving fall campaign. | G13: Send credit memo note | H13: 46220 | I13: Open | J13: Gmail thread | K13: Concerned | L13: 46229 | M13: Confirm verified invoice credit and corrected bill date | N13: CASE-7209 | O13: Commitment carried into recovery review
... A42: ACT-26041 | B42: A-1017 | C42: Jordan Patel | D42: Legal handoff | E42: 46217 | F42: Procurement requested data-use term changes not owned by the sales desk. | G42: Legal owner to draft data-use response | H42: 46227 | I42: Open | J42: Internal checkpoint | K42: Escalated | L42: 46239 | M42: Escalate to manager and legal owner; no rep commitment | N42: CASE-7221 | O42: Manager visibility item

Sheet Raw_Offers
A1: Offer Code | B1: Issue Type | C1: Eligible Tiers | D1: Max Value | E1: Approval Level | F1: Expiration Date | G1: Description | H1: Exclusions
A2: MG-15 | B2: Delivery Underpacing | C2: Key Growth, Core, Emerging | D2: 25000 | E2: Supervisor | F2: 46295 | G2: Makegood inventory up to 15% of affected booked impressions after ad-ops validation. | H2: No guaranteed performance or new inventory categories.
A3: CR-10K | B3: Billing Error | C3: Key Growth, Core, Emerging | D3: 10000 | E3: Supervisor | F3: 46295 | G3: Verified invoice credit up to $10,000 with billing case attached. | H3: Amounts above cap require manager approval.
A4: RH-60 | B4: Renewal Rate Objection | C4: Core, Emerging | D4: 0 | E4: Supervisor | F4: 46295 | G4: Hold current renewal CPM for 60 days when no extra credit is promised. | H4: Cannot combine with unapproved credit or terms beyond 60 days.
A5: SW-PKG | B5: Creative Trafficking; Audience Mismatch; Product Feed Blocker | C5: Key Growth, Core, Emerging | D5: 18000 | E5: Supervisor | F5: 46295 | G5: Equivalent-value package swap after operational owner confirms feasibility. | H5: No customer commitment before blocker clears.
A6: RPT-COMP | B6: Reporting Discrepancy | C6: Key Growth, Core, Emerging | D6: 0 | E6: Supervisor | F6: 46295 | G6: Expedited reporting reconciliation package with customer-facing summary. | H6: No performance guarantee or monetary credit.
A7: MGR-REQ | B7: Over-limit or unsupported | C7: All | D7: 0 | E7: Manager required | F7: 46295 | G7: Controlled exception route for over-limit credits, legal terms, unsupported offers, or missing authority. | H7: Reps may not present as approved local commitment.

Sheet Raw_Approval
A1: Account ID | B1: Approval Status | C1: Approved Offer | D1: Approved Action | E1: Exception Reason | F1: Execution Window Start | G1: Execution Window End
A2: A-1001 | B2: Approved execution | C2: MG-15 | D2: Confirm makegood inventory and delivery recovery plan | F2: 46220 | G2: 46227
A3: A-1002 | B3: Approved execution | C3: RPT-COMP | D3: Deliver reconciled reporting package and executive summary | F3: 46220 | G3: 46227
A4: A-1003 | B4: Approved execution | C4: CR-10K | D4: Confirm verified billing credit and renewal rate hold | F4: 46220 | G4: 46227
A5: A-1004 | B5: Approved execution | C5: SW-PKG | D5: Offer equivalent package swap after trafficking confirmation | F5: 46220 | G5: 46227
A6: A-1005 | B6: Approved execution | C6: SW-PKG | D6: Swap misaligned audience package and reset delivery proof | F6: 46220 | G6: 46227
A7: A-1006 | B7: Approved execution | C7: CR-10K | D7: Confirm verified invoice credit and corrected bill date | F7: 46220 | G7: 46227
A8: A-1007 | B8: Approved execution | C8: MG-15 | D8: Confirm makegood placement and revised delivery dates | F8: 46220 | G8: 46227
A9: A-1008 | B9: Approved execution | C9: RPT-COMP | D9: Send reconciled district reach report and renewal summary | F9: 46220 | G9: 46227
A10: A-1009 | B10: Approved execution | C10: SW-PKG | D10: Confirm package swap and creative approval timeline | F10: 46220 | G10: 46227
A11: A-1010 | B11: Approved execution | C11: RH-60 | D11: Offer 60-day rate hold without additional credit | F11: 46220 | G11: 46227
A12: A-1011 | B12: Approved execution | C12: RPT-COMP | D12: Send corrected lift summary and renewal confidence note | F12: 46220 | G12: 46227
A13: A-1012 | B13: Approved execution | C13: MG-15 | D13: Confirm makegood placement and invoice correction route | F13: 46220 | G13: 46227
A14: A-1013 | B14: Controlled exception | C14: MG-15 | D14: Hold customer-facing offer until decision-maker route is approved | E14: Decision-maker outreach permission pending | F14: 46220 | G14: 46227
A15: A-1014 | B15: Controlled exception | C15: MGR-REQ | D15: Route credit request to manager; do not promise local credit | E15: Requested credit is above supervisor authority | F15: 46220 | G15: 46227
A16: A-1015 | B16: Controlled exception | C16: SW-PKG | D16: Wait for product feed fix before customer offer | E16: Ad-ops blocker not cleared | F16: 46220 | G16: 46227
A17: A-1016 | B17: Excluded - no action | D17: No sprint action; keep closure note | E17: Closed renewal | F17: 46220 | G17: 46227
A18: A-1017 | B18: Controlled exception | C18: MGR-REQ | D18: Escalate to manager and legal owner; no rep commitment | E18: Contract terms outside local authority | F18: 46220 | G18: 46227
A19: A-1018 | B19: Excluded - no action | D19: Hold for September agency review | E19: Customer requested September review | F19: 46220 | G19: 46227

Sheet Case_Summary
A1: Account ID | B1: Open Cases | C1: Max Severity | D1: Avg Issue Age | E1: Primary Issue | F1: Source Case ID
A2: A-1001 | B2: 2 | C2: 4 | D2: 19 | E2: Delivery Underpacing | F2: CASE-7201
A3: A-1002 | B3: 1 | C3: 4 | D3: 17 | E3: Reporting Discrepancy | F3: CASE-7203
A4: A-1003 | B4: 2 | C4: 4 | D4: 17 | E4: Billing Error | F4: CASE-7204
A5: A-1004 | B5: 1 | C5: 3 | D5: 14 | E5: Creative Trafficking | F5: CASE-7206
A6: A-1005 | B6: 2 | C6: 5 | D6: 23 | E6: Audience Mismatch | F6: CASE-7207
A7: A-1006 | B7: 1 | C7: 3 | D7: 10 | E7: Billing Error | F7: CASE-7209
A8: A-1007 | B8: 1 | C8: 4 | D8: 23 | E8: Delivery Underpacing | F8: CASE-7210
A9: A-1008 | B9: 1 | C9: 3 | D9: 9 | E9: Reporting Discrepancy | F9: CASE-7211
A10: A-1009 | B10: 1 | C10: 4 | D10: 20 | E10: Creative Trafficking | F10: CASE-7212
A11: A-1010 | B11: 1 | C11: 2 | D11: 5 | E11: Renewal Rate Objection | F11: CASE-7213
A12: A-1011 | B12: 1 | C12: 4 | D12: 18 | E12: Reporting Discrepancy | F12: CASE-7214
A13: A-1012 | B13: 2 | C13: 5 | D13: 20 | E13: Delivery Underpacing | F13: CASE-7215
... A16: A-1015 | B16: 1 | C16: 4 | D16: 21 | E16: Product Feed Blocker | F16: CASE-7219
A17: A-1016 | B17: 0 | C17: 0 | D17: 0 | F17: CASE-7220
A18: A-1017 | B18: 2 | C18: 5 | D18: 29.5 | E18: Data-Use Terms | F18: CASE-7221
A19: A-1018 | B19: 1 | C19: 2 | D19: 6 | E19: Agency Consolidation | F19: CASE-7223

Sheet Activity_Summary
A1: Account ID | B1: Overdue Commitments | C1: Last Touch | D1: Days Since Last Touch
A2: A-1001 | B2: 1 | C2: 46217 | D2: 1
A3: A-1002 | B3: 0 | C3: 46213 | D3: 5
A4: A-1003 | B4: 0 | C4: 46214 | D4: 4
A5: A-1004 | B5: 1 | C5: 46212 | D5: 6
A6: A-1005 | B6: 1 | C6: 46216 | D6: 2
A7: A-1006 | B7: 0 | C7: 46216 | D7: 2
A8: A-1007 | B8: 1 | C8: 46213 | D8: 5
A9: A-1008 | B9: 0 | C9: 46215 | D9: 3
A10: A-1009 | B10: 1 | C10: 46212 | D10: 6
A11: A-1010 | B11: 0 | C11: 46217 | D11: 1
A12: A-1011 | B12: 0 | C12: 46213 | D12: 5
A13: A-1012 | B13: 1 | C13: 46217 | D13: 1
... A19: A-1018 | B19: 0 | C19: 46217 | D19: 1

Sheet Normalized_Accounts
A1: Account ID | B1: Account Name | C1: Segment | D1: Tier | E1: Owner Rep | F1: Renewal Date | G1: Health Score | H1: Approval Status | I1: Renewal Exposure | J1: Baseline Revenue | K1: Current Forecast | L1: Forecast Variance | M1: Open Cases | N1: Max Severity | O1: Avg Issue Age | P1: Overdue Commitments | Q1: Last Touch | R1: Days Since Last Touch | S1: Contact Readiness | T1: Primary Issue | U1: Approved Offer | V1: Requested Recovery Value | W1: Offer Cap | X1: Offer Compliance | Y1: Exception Reason | Z1: Source Lineage
A2: A-1001 | B2: =VLOOKUP(A2,Raw_CRM!$A$2:$L$19,2,FALSE()) -> Meridian Health Partners | C2: =VLOOKUP(A2,Raw_CRM!$A$2:$L$19,3,FALSE()) -> Healthcare | D2: =VLOOKUP(A2,Raw_CRM!$A$2:$L$19,4,FALSE()) -> Key Growth | E2: =VLOOKUP(A2,Raw_CRM!$A$2:$L$19,5,FALSE()) -> Maya Chen | F2: =VLOOKUP(A2,Raw_CRM!$A$2:$L$19,6,FALSE()) -> 46227 | G2: =VLOOKUP(A2,Raw_CRM!$A$2:$L$19,7,FALSE()) -> 48 | H2: =VLOOKUP(A2,Raw_Approval!$A$2:$G$19,2,FALSE()) -> Approved execution | I2: =VLOOKUP(A2,Raw_Orders!$A$2:$H$19,6,FALSE()) -> 340000 | J2: =VLOOKUP(A2,Raw_Orders!$A$2:$H$19,4,FALSE()) -> 310000 | K2: =VLOOKUP(A2,Raw_Orders!$A$2:$H$19,5,FALSE()) -> 272000 | L2: =K2-J2 -> -38000 | M2: =VLOOKUP(A2,Case_Summary!$A$2:$F$19,2,FALSE()) -> 2 | N2: =VLOOKUP(A2,Case_Summary!$A$2:$F$19,3,FALSE()) -> 4 | O2: =VLOOKUP(A2,Case_Summary!$A$2:$F$19,4,FALSE()) -> 19 | P2: =VLOOKUP(A2,Activity_Summary!$A$2:$D$19,2,FALSE()) -> 1 | Q2: =VLOOKUP(A2,Activity_Summary!$A$2:$D$19,3,FALSE()) -> 46217 | R2: =Assumptions!$B$8-Q2 -> 1 | S2: =IF(COUNTIFS(Raw_Contacts!$B$2:$B$41,A2,Raw_Contacts!$F$2:$F$41,"Final Renewal Approver",Raw_Contacts!$H$2:$H$41,"Approved")>0,"Ready",IF(COUNTIFS(Raw_Contacts!$B$2:$B$41,A2,Raw_Contacts!$H$2:$H$41,"Operations Only")>0,"Ops route only",IF(COUNTIFS(Raw_Contacts!$B$2:$B$41,A2,Raw_Contacts!$H$2:$H$41,"Do not contact executive")>0,"Manager route only","Pending permission"))) -> Ready | T2: =IF(VLOOKUP(A2,Case_Summary!$A$2:$F$19,5,FALSE())=0,"",VLOOKUP(A2,Case_Summary!$A$2:$F$19,5,FALSE())) -> Delivery Underpacing | U2: =IF(VLOOKUP(A2,Raw_Approval!$A$2:$G$19,3,FALSE())=0,"",VLOOKUP(A2,Raw_Approval!$A$2:$G$19,3,FALSE())) -> MG-15 | V2: =VLOOKUP(A2,Raw_CRM!$A$2:$L$19,10,FALSE()) -> 21000 | W2: =IF(U2="","",IFERROR(VLOOKUP(U2,Raw_Offers!$A$2:$G$7,4,FALSE()),0)) -> 25000 | X2: =IF(H2<>"Approved execution","Controlled",IF(U2="","No offer",IF(U2="MGR-REQ","Manager required",IF(OR(W2=0,V2<=W2),"Within authority","Over limit")))) -> Within authority | Y2: =IF(VLOOKUP(A2,Raw_Approval!$A$2:$G$19,5,FALSE())=0,"",VLOOKUP(A2,Raw_Approval!$A$2:$G$19,5,FALSE())) | Z2: CRM, cases, orders, contacts, activity, offers, approval
A3: A-1002 | B3: =VLOOKUP(A3,Raw_CRM!$A$2:$L$19,2,FALSE()) -> Larkspur Credit Union | C3: =VLOOKUP(A3,Raw_CRM!$A$2:$L$19,3,FALSE()) -> Financial Services | D3: =VLOOKUP(A3,Raw_CRM!$A$2:$L$19,4,FALSE()) -> Core | E3: =VLOOKUP(A3,Raw_CRM!$A$2:$L$19,5,FALSE()) -> Jordan Patel | F3: =VLOOKUP(A3,Raw_CRM!$A$2:$L$19,6,FALSE()) -> 46234 | G3: =VLOOKUP(A3,Raw_CRM!$A$2:$L$19,7,FALSE()) -> 52 | H3: =VLOOKUP(A3,Raw_Approval!$A$2:$G$19,2,FALSE()) -> Approved execution | I3: =VLOOKUP(A3,Raw_Orders!$A$2:$H$19,6,FALSE()) -> 220000 | J3: =VLOOKUP(A3,Raw_Orders!$A$2:$H$19,4,FALSE()) -> 205000 | K3: =VLOOKUP(A3,Raw_Orders!$A$2:$H$19,5,FALSE()) -> 184000 | L3: =K3-J3 -> -21000 | M3: =VLOOKUP(A3,Case_Summary!$A$2:$F$19,2,FALSE()) -> 1 | N3: =VLOOKUP(A3,Case_Summary!$A$2:$F$19,3,FALSE()) -> 4 | O3: =VLOOKUP(A3,Case_Summary!$A$2:$F$19,4,FALSE()) -> 17 | P3: =VLOOKUP(A3,Activity_Summary!$A$2:$D$19,2,FALSE()) -> 0 | Q3: =VLOOKUP(A3,Activity_Summary!$A$2:$D$19,3,FALSE()) -> 46213 | R3: =Assumptions!$B$8-Q3 -> 5 | S3: =IF(COUNTIFS(Raw_Contacts!$B$2:$B$41,A3,Raw_Contacts!$F$2:$F$41,"Final Renewal Approver",Raw_Contacts!$H$2:$H$41,"Approved")>0,"Ready",IF(COUNTIFS(Raw_Contacts!$B$2:$B$41,A3,Raw_Contacts!$H$2:$H$41,"Operations Only")>0,"Ops route only",IF(COUNTIFS(Raw_Contacts!$B$2:$B$41,A3,Raw_Contacts!$H$2:$H$41,"Do not contact executive")>0,"Manager route only","Pending permission"))) -> Ready | T3: =IF(VLOOKUP(A3,Case_Summary!$A$2:$F$19,5,FALSE())=0,"",VLOOKUP(A3,Case_Summary!$A$2:$F$19,5,FALSE())) -> Reporting Discrepancy | U3: =IF(VLOOKUP(A3,Raw_Approval!$A$2:$G$19,3,FALSE())=0,"",VLOOKUP(A3,Raw_Approval!$A$2:$G$19,3,FALSE())) -> RPT-COMP | V3: =VLOOKUP(A3,Raw_CRM!$A$2:$L$19,10,FALSE()) -> 0 | W3: =IF(U3="","",IFERROR(VLOOKUP(U3,Raw_Offers!$A$2:$G$7,4,FALSE()),0)) -> 0 | X3: =IF(H3<>"Approved execution","Controlled",IF(U3="","No offer",IF(U3="MGR-REQ","Manager required",IF(OR(W3=0,V3<=W3),"Within authority","Over limit")))) -> Within authority | Y3: =IF(VLOOKUP(A3,Raw_Approval!$A$2:$G$19,5,FALSE())=0,"",VLOOKUP(A3,Raw_Approval!$A$2:$G$19,5,FALSE())) | Z3: CRM, cases, orders, contacts, activity, offers, approval
A4: A-1003 | B4: =VLOOKUP(A4,Raw_CRM!$A$2:$L$19,2,FALSE()) -> Cobalt Cloud Systems | C4: =VLOOKUP(A4,Raw_CRM!$A$2:$L$19,3,FALSE()) -> Technology | D4: =VLOOKUP(A4,Raw_CRM!$A$2:$L$19,4,FALSE()) -> Key Growth | E4: =VLOOKUP(A4,Raw_CRM!$A$2:$L$19,5,FALSE()) -> Priya Nair | F4: =VLOOKUP(A4,Raw_CRM!$A$2:$L$19,6,FALSE()) -> 46239 | G4: =VLOOKUP(A4,Raw_CRM!$A$2:$L$19,7,FALSE()) -> 56 | H4: =VLOOKUP(A4,Raw_Approval!$A$2:$G$19,2,FALSE()) -> Approved execution | I4: =VLOOKUP(A4,Raw_Orders!$A$2:$H$19,6,FALSE()) -> 295000 | J4: =VLOOKUP(A4,Raw_Orders!$A$2:$H$19,4,FALSE()) -> 275000 | K4: =VLOOKUP(A4,Raw_Orders!$A$2:$H$19,5,FALSE()) -> 240000 | L4: =K4-J4 -> -35000 | M4: =VLOOKUP(A4,Case_Summary!$A$2:$F$19,2,FALSE()) -> 2 | N4: =VLOOKUP(A4,Case_Summary!$A$2:$F$19,3,FALSE()) -> 4 | O4: =VLOOKUP(A4,Case_Summary!$A$2:$F$19,4,FALSE()) -> 17 | P4: =VLOOKUP(A4,Activity_Summary!$A$2:$D$19,2,FALSE()) -> 0 | Q4: =VLOOKUP(A4,Activity_Summary!$A$2:$D$19,3,FALSE()) -> 46214 | R4: =Assumptions!$B$8-Q4 -> 4 | S4: =IF(COUNTIFS(Raw_Contacts!$B$2:$B$41,A4,Raw_Contacts!$F$2:$F$41,"Final Renewal Approver",Raw_Contacts!$H$2:$H$41,"Approved")>0,"Ready",IF(COUNTIFS(Raw_Contacts!$B$2:$B$41,A4,Raw_Contacts!$H$2:$H$41,"Operations Only")>0,"Ops route only",IF(COUNTIFS(Raw_Contacts!$B$2:$B$41,A4,Raw_Contacts!$H$2:$H$41,"Do not contact executive")>0,"Manager route only","Pending permission"))) -> Ready | T4: =IF(VLOOKUP(A4,Case_Summary!$A$2:$F$19,5,FALSE())=0,"",VLOOKUP(A4,Case_Summary!$A$2:$F$19,5,FALSE())) -> Billing Error | U4: =IF(VLOOKUP(A4,Raw_Approval!$A$2:$G$19,3,FALSE())=0,"",VLOOKUP(A4,Raw_Approval!$A$2:$G$19,3,FALSE())) -> CR-10K | V4: =VLOOKUP(A4,Raw_CRM!$A$2:$L$19,10,FALSE()) -> 9500 | W4: =IF(U4="","",IFERROR(VLOOKUP(U4,Raw_Offers!$A$2:$G$7,4,FALSE()),0)) -> 10000 | X4: =IF(H4<>"Approved execution","Controlled",IF(U4="","No offer",IF(U4="MGR-REQ","Manager required",IF(OR(W4=0,V4<=W4),"Within authority","Over limit")))) -> Within authority | Y4: =IF(VLOOKUP(A4,Raw_Approval!$A$2:$G$19,5,FALSE())=0,"",VLOOKUP(A4,Raw_Approval!$A$2:$G$19,5,FALSE())) | Z4: CRM, cases, orders, contacts, activity, offers, approval
A5: A-1004 | B5: =VLOOKUP(A5,Raw_CRM!$A$2:$L$19,2,FALSE()) -> Harborview Furnishings | C5: =VLOOKUP(A5,Raw_CRM!$A$2:$L$19,3,FALSE()) -> Retail | D5: =VLOOKUP(A5,Raw_CRM!$A$2:$L$19,4,FALSE()) -> Core | E5: =VLOOKUP(A5,Raw_CRM!$A$2:$L$19,5,FALSE()) -> Luis Romero | F5: =VLOOKUP(A5,Raw_CRM!$A$2:$L$19,6,FALSE()) -> 46231 | G5: =VLOOKUP(A5,Raw_CRM!$A$2:$L$19,7,FALSE()) -> 61 | H5: =VLOOKUP(A5,Raw_Approval!$A$2:$G$19,2,FALSE()) -> Approved execution | I5: =VLOOKUP(A5,Raw_Orders!$A$2:$H$19,6,FALSE()) -> 150000 | J5: =VLOOKUP(A5,Raw_Orders!$A$2:$H$19,4,FALSE()) -> 142000 | K5: =VLOOKUP(A5,Raw_Orders!$A$2:$H$19,5,FALSE()) -> 129000 | L5: =K5-J5 -> -13000 | M5: =VLOOKUP(A5,Case_Summary!$A$2:$F$19,2,FALSE()) -> 1 | N5: =VLOOKUP(A5,Case_Summary!$A$2:$F$19,3,FALSE()) -> 3 | O5: =VLOOKUP(A5,Case_Summary!$A$2:$F$19,4,FALSE()) -> 14 | P5: =VLOOKUP(A5,Activity_Summary!$A$2:$D$19,2,FALSE()) -> 1 | Q5: =VLOOKUP(A5,Activity_Summary!$A$2:$D$19,3,FALSE()) -> 46212 | R5: =Assumptions!$B$8-Q5 -> 6 | S5: =IF(COUNTIFS(Raw_Contacts!$B$2:$B$41,A5,Raw_Contacts!$F$2:$F$41,"Final Renewal Approver",Raw_Contacts!$H$2:$H$41,"Approved")>0,"Ready",IF(COUNTIFS(Raw_Contacts!$B$2:$B$41,A5,Raw_Contacts!$H$2:$H$41,"Operations Only")>0,"Ops route only",IF(COUNTIFS(Raw_Contacts!$B$2:$B$41,A5,Raw_Contacts!$H$2:$H$41,"Do not contact executive")>0,"Manager route only","Pending permission"))) -> Ready | T5: =IF(VLOOKUP(A5,Case_Summary!$A$2:$F$19,5,FALSE())=0,"",VLOOKUP(A5,Case_Summary!$A$2:$F$19,5,FALSE())) -> Creative Trafficking | U5: =IF(VLOOKUP(A5,Raw_Approval!$A$2:$G$19,3,FALSE())=0,"",VLOOKUP(A5,Raw_Approval!$A$2:$G$19,3,FALSE())) -> SW-PKG | V5: =VLOOKUP(A5,Raw_CRM!$A$2:$L$19,10,FALSE()) -> 12000 | W5: =IF(U5="","",IFERROR(VLOOKUP(U5,Raw_Offers!$A$2:$G$7,4,FALSE()),0)) -> 18000 | X5: =IF(H5<>"Approved execution","Controlled",IF(U5="","No offer",IF(U5="MGR-REQ","Manager required",IF(OR(W5=0,V5<=W5),"Within authority","Over limit")))) -> Within authority | Y5: =IF(VLOOKUP(A5,Raw_Approval!$A$2:$G$19,5,FALSE())=0,"",VLOOKUP(A5,Raw_Approval!$A$2:$G$19,5,FALSE())) | Z5: CRM, cases, orders, contacts, activity, offers, approval
A6: A-1005 | B6: =VLOOKUP(A6,Raw_CRM!$A$2:$L$19,2,FALSE()) -> Axion Robotics | C6: =VLOOKUP(A6,Raw_CRM!$A$2:$L$19,3,FALSE()) -> Industrial | D6: =VLOOKUP(A6,Raw_CRM!$A$2:$L$19,4,FALSE()) -> Key Growth | E6: =VLOOKUP(A6,Raw_CRM!$A$2:$L$19,5,FALSE()) -> Devon Brooks | F6: =VLOOKUP(A6,Raw_CRM!$A$2:$L$19,6,FALSE()) -> 46246 | G6: =VLOOKUP(A6,Raw_CRM!$A$2:$L$19,7,FALSE()) -> 44 | H6: =VLOOKUP(A6,Raw_Approval!$A$2:$G$19,2,FALSE()) -> Approved execution | I6: =VLOOKUP(A6,Raw_Orders!$A$2:$H$19,6,FALSE()) -> 410000 | J6: =VLOOKUP(A6,Raw_Orders!$A$2:$H$19,4,FALSE()) -> 390000 | K6: =VLOOKUP(A6,Raw_Orders!$A$2:$H$19,5,FALSE()) -> 318000 | L6: =K6-J6 -> -72000 | M6: =VLOOKUP(A6,Case_Summary!$A$2:$F$19,2,FALSE()) -> 2 | N6: =VLOOKUP(A6,Case_Summary!$A$2:$F$19,3,FALSE()) -> 5 | O6: =VLOOKUP(A6,Case_Summary!$A$2:$F$19,4,FALSE()) -> 23 | P6: =VLOOKUP(A6,Activity_Summary!$A$2:$D$19,2,FALSE()) -> 1 | Q6: =VLOOKUP(A6,Activity_Summary!$A$2:$D$19,3,FALSE()) -> 46216 | R6: =Assumptions!$B$8-Q6 -> 2 | S6: =IF(COUNTIFS(Raw_Contacts!$B$2:$B$41,A6,Raw_Contacts!$F$2:$F$41,"Final Renewal Approver",Raw_Contacts!$H$2:$H$41,"Approved")>0,"Ready",IF(COUNTIFS(Raw_Contacts!$B$2:$B$41,A6,Raw_Contacts!$H$2:$H$41,"Operations Only")>0,"Ops route only",IF(COUNTIFS(Raw_Contacts!$B$2:$B$41,A6,Raw_Contacts!$H$2:$H$41,"Do not contact executive")>0,"Manager route only","Pending permission"))) -> Ready | T6: =IF(VLOOKUP(A6,Case_Summary!$A$2:$F$19,5,FALSE())=0,"",VLOOKUP(A6,Case_Summary!$A$2:$F$19,5,FALSE())) -> Audience Mismatch | U6: =IF(VLOOKUP(A6,Raw_Approval!$A$2:$G$19,3,FALSE())=0,"",VLOOKUP(A6,Raw_Approval!$A$2:$G$19,3,FALSE())) -> SW-PKG | V6: =VLOOKUP(A6,Raw_CRM!$A$2:$L$19,10,FALSE()) -> 18000 | W6: =IF(U6="","",IFERROR(VLOOKUP(U6,Raw_Offers!$A$2:$G$7,4,FALSE()),0)) -> 18000 | X6: =IF(H6<>"Approved execution","Controlled",IF(U6="","No offer",IF(U6="MGR-REQ","Manager required",IF(OR(W6=0,V6<=W6),"Within authority","Over limit")))) -> Within authority | Y6: =IF(VLOOKUP(A6,Raw_Approval!$A$2:$G$19,5,FALSE())=0,"",VLOOKUP(A6,Raw_Approval!$A$2:$G$19,5,FALSE())) | Z6: CRM, cases, orders, contacts, activity, offers, approval
A7: A-1006 | B7: =VLOOKUP(A7,Raw_CRM!$A$2:$L$19,2,FALSE()) -> Greenway Kitchens | C7: =VLOOKUP(A7,Raw_CRM!$A$2:$L$19,3,FALSE()) -> Retail | D7: =VLOOKUP(A7,Raw_CRM!$A$2:$L$19,4,FALSE()) -> Emerging | E7: =VLOOKUP(A7,Raw_CRM!$A$2:$L$19,5,FALSE()) -> Maya Chen | F7: =VLOOKUP(A7,Raw_CRM!$A$2:$L$19,6,FALSE()) -> 46229 | G7: =VLOOKUP(A7,Raw_CRM!$A$2:$L$19,7,FALSE()) -> 68 | H7: =VLOOKUP(A7,Raw_Approval!$A$2:$G$19,2,FALSE()) -> Approved execution | I7: =VLOOKUP(A7,Raw_Orders!$A$2:$H$19,6,FALSE()) -> 82000 | J7: =VLOOKUP(A7,Raw_Orders!$A$2:$H$19,4,FALSE()) -> 76000 | K7: =VLOOKUP(A7,Raw_Orders!$A$2:$H$19,5,FALSE()) -> 71000 | L7: =K7-J7 -> -5000 | M7: =VLOOKUP(A7,Case_Summary!$A$2:$F$19,2,FALSE()) -> 1 | N7: =VLOOKUP(A7,Case_Summary!$A$2:$F$19,3,FALSE()) -> 3 | O7: =VLOOKUP(A7,Case_Summary!$A$2:$F$19,4,FALSE()) -> 10 | P7: =VLOOKUP(A7,Activity_Summary!$A$2:$D$19,2,FALSE()) -> 0 | Q7: =VLOOKUP(A7,Activity_Summary!$A$2:$D$19,3,FALSE()) -> 46216 | R7: =Assumptions!$B$8-Q7 -> 2 | S7: =IF(COUNTIFS(Raw_Contacts!$B$2:$B$41,A7,Raw_Contacts!$F$2:$F$41,"Final Renewal Approver",Raw_Contacts!$H$2:$H$41,"Approved")>0,"Ready",IF(COUNTIFS(Raw_Contacts!$B$2:$B$41,A7,Raw_Contacts!$H$2:$H$41,"Operations Only")>0,"Ops route only",IF(COUNTIFS(Raw_Contacts!$B$2:$B$41,A7,Raw_Contacts!$H$2:$H$41,"Do not contact executive")>0,"Manager route only","Pending permission"))) -> Ready | T7: =IF(VLOOKUP(A7,Case_Summary!$A$2:$F$19,5,FALSE())=0,"",VLOOKUP(A7,Case_Summary!$A$2:$F$19,5,FALSE())) -> Billing Error | U7: =IF(VLOOKUP(A7,Raw_Approval!$A$2:$G$19,3,FALSE())=0,"",VLOOKUP(A7,Raw_Approval!$A$2:$G$19,3,FALSE())) -> CR-10K | V7: =VLOOKUP(A7,Raw_CRM!$A$2:$L$19,10,FALSE()) -> 4800 | W7: =IF(U7="","",IFERROR(VLOOKUP(U7,Raw_Offers!$A$2:$G$7,4,FALSE()),0)) -> 10000 | X7: =IF(H7<>"Approved execution","Controlled",IF(U7="","No offer",IF(U7="MGR-REQ","Manager required",IF(OR(W7=0,V7<=W7),"Within authority","Over limit")))) -> Within authority | Y7: =IF(VLOOKUP(A7,Raw_Approval!$A$2:$G$19,5,FALSE())=0,"",VLOOKUP(A7,Raw_Approval!$A$2:$G$19,5,FALSE())) | Z7: CRM, cases, orders, contacts, activity, offers, approval
A8: A-1007 | B8: =VLOOKUP(A8,Raw_CRM!$A$2:$L$19,2,FALSE()) -> Northline Insurance | C8: =VLOOKUP(A8,Raw_CRM!$A$2:$L$19,3,FALSE()) -> Financial Services | D8: =VLOOKUP(A8,Raw_CRM!$A$2:$L$19,4,FALSE()) -> Core | E8: =VLOOKUP(A8,Raw_CRM!$A$2:$L$19,5,FALSE()) -> Jordan Patel | F8: =VLOOKUP(A8,Raw_CRM!$A$2:$L$19,6,FALSE()) -> 46237 | G8: =VLOOKUP(A8,Raw_CRM!$A$2:$L$19,7,FALSE()) -> 50 | H8: =VLOOKUP(A8,Raw_Approval!$A$2:$G$19,2,FALSE()) -> Approved execution | I8: =VLOOKUP(A8,Raw_Orders!$A$2:$H$19,6,FALSE()) -> 260000 | J8: =VLOOKUP(A8,Raw_Orders!$A$2:$H$19,4,FALSE()) -> 246000 | K8: =VLOOKUP(A8,Raw_Orders!$A$2:$H$19,5,FALSE()) -> 206000 | L8: =K8-J8 -> -40000 | M8: =VLOOKUP(A8,Case_Summary!$A$2:$F$19,2,FALSE()) -> 1 | N8: =VLOOKUP(A8,Case_Summary!$A$2:$F$19,3,FALSE()) -> 4 | O8: =VLOOKUP(A8,Case_Summary!$A$2:$F$19,4,FALSE()) -> 23 | P8: =VLOOKUP(A8,Activity_Summary!$A$2:$D$19,2,FALSE()) -> 1 | Q8: =VLOOKUP(A8,Activity_Summary!$A$2:$D$19,3,FALSE()) -> 46213 | R8: =Assumptions!$B$8-Q8 -> 5 | S8: =IF(COUNTIFS(Raw_Contacts!$B$2:$B$41,A8,Raw_Contacts!$F$2:$F$41,"Final Renewal Approver",Raw_Contacts!$H$2:$H$41,"Approved")>0,"Ready",IF(COUNTIFS(Raw_Contacts!$B$2:$B$41,A8,Raw_Contacts!$H$2:$H$41,"Operations Only")>0,"Ops route only",IF(COUNTIFS(Raw_Contacts!$B$2:$B$41,A8,Raw_Contacts!$H$2:$H$41,"Do not contact executive")>0,"Manager route only","Pending permission"))) -> Ready | T8: =IF(VLOOKUP(A8,Case_Summary!$A$2:$F$19,5,FALSE())=0,"",VLOOKUP(A8,Case_Summary!$A$2:$F$19,5,FALSE())) -> Delivery Underpacing | U8: =IF(VLOOKUP(A8,Raw_Approval!$A$2:$G$19,3,FALSE())=0,"",VLOOKUP(A8,Raw_Approval!$A$2:$G$19,3,FALSE())) -> MG-15 | V8: =VLOOKUP(A8,Raw_CRM!$A$2:$L$19,10,FALSE()) -> 22000 | W8: =IF(U8="","",IFERROR(VLOOKUP(U8,Raw_Offers!$A$2:$G$7,4,FALSE()),0)) -> 25000 | X8: =IF(H8<>"Approved execution","Controlled",IF(U8="","No offer",IF(U8="MGR-REQ","Manager required",IF(OR(W8=0,V8<=W8),"Within authority","Over limit")))) -> Within authority | Y8: =IF(VLOOKUP(A8,Raw_Approval!$A$2:$G$19,5,FALSE())=0,"",VLOOKUP(A8,Raw_Approval!$A$2:$G$19,5,FALSE())) | Z8: CRM, cases, orders, contacts, activity, offers, approval
A9: A-1008 | B9: =VLOOKUP(A9,Raw_CRM!$A$2:$L$19,2,FALSE()) -> Veridian Charter Schools | C9: =VLOOKUP(A9,Raw_CRM!$A$2:$L$19,3,FALSE()) -> Education | D9: =VLOOKUP(A9,Raw_CRM!$A$2:$L$19,4,FALSE()) -> Emerging | E9: =VLOOKUP(A9,Raw_CRM!$A$2:$L$19,5,FALSE()) -> Priya Nair | F9: =VLOOKUP(A9,Raw_CRM!$A$2:$L$19,6,FALSE()) -> 46249 | G9: =VLOOKUP(A9,Raw_CRM!$A$2:$L$19,7,FALSE()) -> 63 | H9: =VLOOKUP(A9,Raw_Approval!$A$2:$G$19,2,FALSE()) -> Approved execution | I9: =VLOOKUP(A9,Raw_Orders!$A$2:$H$19,6,FALSE()) -> 110000 | J9: =VLOOKUP(A9,Raw_Orders!$A$2:$H$19,4,FALSE()) -> 98000 | K9: =VLOOKUP(A9,Raw_Orders!$A$2:$H$19,5,FALSE()) -> 88000 | L9: =K9-J9 -> -10000 | M9: =VLOOKUP(A9,Case_Summary!$A$2:$F$19,2,FALSE()) -> 1 | N9: =VLOOKUP(A9,Case_Summary!$A$2:$F$19,3,FALSE()) -> 3 | O9: =VLOOKUP(A9,Case_Summary!$A$2:$F$19,4,FALSE()) -> 9 | P9: =VLOOKUP(A9,Activity_Summary!$A$2:$D$19,2,FALSE()) -> 0 | Q9: =VLOOKUP(A9,Activity_Summary!$A$2:$D$19,3,FALSE()) -> 46215 | R9: =Assumptions!$B$8-Q9 -> 3 | S9: =IF(COUNTIFS(Raw_Contacts!$B$2:$B$41,A9,Raw_Contacts!$F$2:$F$41,"Final Renewal Approver",Raw_Contacts!$H$2:$H$41,"Approved")>0,"Ready",IF(COUNTIFS(Raw_Contacts!$B$2:$B$41,A9,Raw_Contacts!$H$2:$H$41,"Operations Only")>0,"Ops route only",IF(COUNTIFS(Raw_Contacts!$B$2:$B$41,A9,Raw_Contacts!$H$2:$H$41,"Do not contact executive")>0,"Manager route only","Pending permission"))) -> Ready | T9: =IF(VLOOKUP(A9,Case_Summary!$A$2:$F$19,5,FALSE())=0,"",VLOOKUP(A9,Case_Summary!$A$2:$F$19,5,FALSE())) -> Reporting Discrepancy | U9: =IF(VLOOKUP(A9,Raw_Approval!$A$2:$G$19,3,FALSE())=0,"",VLOOKUP(A9,Raw_Approval!$A$2:$G$19,3,FALSE())) -> RPT-COMP | V9: =VLOOKUP(A9,Raw_CRM!$A$2:$L$19,10,FALSE()) -> 0 | W9: =IF(U9="","",IFERROR(VLOOKUP(U9,Raw_Offers!$A$2:$G$7,4,FALSE()),0)) -> 0 | X9: =IF(H9<>"Approved execution","Controlled",IF(U9="","No offer",IF(U9="MGR-REQ","Manager required",IF(OR(W9=0,V9<=W9),"Within authority","Over limit")))) -> Within authority | Y9: =IF(VLOOKUP(A9,Raw_Approval!$A$2:$G$19,5,FALSE())=0,"",VLOOKUP(A9,Raw_Approval!$A$2:$G$19,5,FALSE())) | Z9: CRM, cases, orders, contacts, activity, offers, approval
A10: A-1009 | B10: =VLOOKUP(A10,Raw_CRM!$A$2:$L$19,2,FALSE()) -> Copper Trail Hospitality | C10: =VLOOKUP(A10,Raw_CRM!$A$2:$L$19,3,FALSE()) -> Travel | D10: =VLOOKUP(A10,Raw_CRM!$A$2:$L$19,4,FALSE()) -> Core | E10: =VLOOKUP(A10,Raw_CRM!$A$2:$L$19,5,FALSE()) -> Luis Romero | F10: =VLOOKUP(A10,Raw_CRM!$A$2:$L$19,6,FALSE()) -> 46232 | G10: =VLOOKUP(A10,Raw_CRM!$A$2:$L$19,7,FALSE()) -> 58 | H10: =VLOOKUP(A10,Raw_Approval!$A$2:$G$19,2,FALSE()) -> Approved execution | I10: =VLOOKUP(A10,Raw_Orders!$A$2:$H$19,6,FALSE()) -> 190000 | J10: =VLOOKUP(A10,Raw_Orders!$A$2:$H$19,4,FALSE()) -> 174000 | K10: =VLOOKUP(A10,Raw_Orders!$A$2:$H$19,5,FALSE()) -> 149000 | L10: =K10-J10 -> -25000 | M10: =VLOOKUP(A10,Case_Summary!$A$2:$F$19,2,FALSE()) -> 1 | N10: =VLOOKUP(A10,Case_Summary!$A$2:$F$19,3,FALSE()) -> 4 | O10: =VLOOKUP(A10,Case_Summary!$A$2:$F$19,4,FALSE()) -> 20 | P10: =VLOOKUP(A10,Activity_Summary!$A$2:$D$19,2,FALSE()) -> 1 | Q10: =VLOOKUP(A10,Activity_Summary!$A$2:$D$19,3,FALSE()) -> 46212 | R10: =Assumptions!$B$8-Q10 -> 6 | S10: =IF(COUNTIFS(Raw_Contacts!$B$2:$B$41,A10,Raw_Contacts!$F$2:$F$41,"Final Renewal Approver",Raw_Contacts!$H$2:$H$41,"Approved")>0,"Ready",IF(COUNTIFS(Raw_Contacts!$B$2:$B$41,A10,Raw_Contacts!$H$2:$H$41,"Operations Only")>0,"Ops route only",IF(COUNTIFS(Raw_Contacts!$B$2:$B$41,A10,Raw_Contacts!$H$2:$H$41,"Do not contact executive")>0,"Manager route only","Pending permission"))) -> Ready | T10: =IF(VLOOKUP(A10,Case_Summary!$A$2:$F$19,5,FALSE())=0,"",VLOOKUP(A10,Case_Summary!$A$2:$F$19,5,FALSE())) -> Creative Trafficking | U10: =IF(VLOOKUP(A10,Raw_Approval!$A$2:$G$19,3,FALSE())=0,"",VLOOKUP(A10,Raw_Approval!$A$2:$G$19,3,FALSE())) -> SW-PKG | V10: =VLOOKUP(A10,Raw_CRM!$A$2:$L$19,10,FALSE()) -> 15000 | W10: =IF(U10="","",IFERROR(VLOOKUP(U10,Raw_Offers!$A$2:$G$7,4,FALSE()),0)) -> 18000 | X10: =IF(H10<>"Approved execution","Controlled",IF(U10="","No offer",IF(U10="MGR-REQ","Manager required",IF(OR(W10=0,V10<=W10),"Within authority","Over limit")))) -> Within authority | Y10: =IF(VLOOKUP(A10,Raw_Approval!$A$2:$G$19,5,FALSE())=0,"",VLOOKUP(A10,Raw_Approval!$A$2:$G$19,5,FALSE())) | Z10: CRM, cases, orders, contacts, activity, offers, approval
A11: A-1010 | B11: =VLOOKUP(A11,Raw_CRM!$A$2:$L$19,2,FALSE()) -> Finch Legal Group | C11: =VLOOKUP(A11,Raw_CRM!$A$2:$L$19,3,FALSE()) -> Professional Services | D11: =VLOOKUP(A11,Raw_CRM!$A$2:$L$19,4,FALSE()) -> Emerging | E11: =VLOOKUP(A11,Raw_CRM!$A$2:$L$19,5,FALSE()) -> Devon Brooks | F11: =VLOOKUP(A11,Raw_CRM!$A$2:$L$19,6,FALSE()) -> 46254 | G11: =VLOOKUP(A11,Raw_CRM!$A$2:$L$19,7,FALSE()) -> 70 | H11: =VLOOKUP(A11,Raw_Approval!$A$2:$G$19,2,FALSE()) -> Approved execution | I11: =VLOOKUP(A11,Raw_Orders!$A$2:$H$19,6,FALSE()) -> 75000 | J11: =VLOOKUP(A11,Raw_Orders!$A$2:$H$19,4,FALSE()) -> 72000 | K11: =VLOOKUP(A11,Raw_Orders!$A$2:$H$19,5,FALSE()) -> 70000 | L11: =K11-J11 -> -2000 | M11: =VLOOKUP(A11,Case_Summary!$A$2:$F$19,2,FALSE()) -> 1 | N11: =VLOOKUP(A11,Case_Summary!$A$2:$F$19,3,FALSE()) -> 2 | O11: =VLOOKUP(A11,Case_Summary!$A$2:$F$19,4,FALSE()) -> 5 | P11: =VLOOKUP(A11,Activity_Summary!$A$2:$D$19,2,FALSE()) -> 0 | Q11: =VLOOKUP(A11,Activity_Summary!$A$2:$D$19,3,FALSE()) -> 46217 | R11: =Assumptions!$B$8-Q11 -> 1 | S11: =IF(COUNTIFS(Raw_Contacts!$B$2:$B$41,A11,Raw_Contacts!$F$2:$F$41,"Final Renewal Approver",Raw_Contacts!$H$2:$H$41,"Approved")>0,"Ready",IF(COUNTIFS(Raw_Contacts!$B$2:$B$41,A11,Raw_Contacts!$H$2:$H$41,"Operations Only")>0,"Ops route only",IF(COUNTIFS(Raw_Contacts!$B$2:$B$41,A11,Raw_Contacts!$H$2:$H$41,"Do not contact executive")>0,"Manager route only","Pending permission"))) -> Ready | T11: =IF(VLOOKUP(A11,Case_Summary!$A$2:$F$19,5,FALSE())=0,"",VLOOKUP(A11,Case_Summary!$A$2:$F$19,5,FALSE())) -> Renewal Rate Objection | U11: =IF(VLOOKUP(A11,Raw_Approval!$A$2:$G$19,3,FALSE())=0,"",VLOOKUP(A11,Raw_Approval!$A$2:$G$19,3,FALSE())) -> RH-60 | V11: =VLOOKUP(A11,Raw_CRM!$A$2:$L$19,10,FALSE()) -> 0 | W11: =IF(U11="","",IFERROR(VLOOKUP(U11,Raw_Offers!$A$2:$G$7,4,FALSE()),0)) -> 0 | X11: =IF(H11<>"Approved execution","Controlled",IF(U11="","No offer",IF(U11="MGR-REQ","Manager required",IF(OR(W11=0,V11<=W11),"Within authority","Over limit")))) -> Within authority | Y11: =IF(VLOOKUP(A11,Raw_Approval!$A$2:$G$19,5,FALSE())=0,"",VLOOKUP(A11,Raw_Approval!$A$2:$G$19,5,FALSE())) | Z11: CRM, cases, orders, contacts, activity, offers, approval
A12: A-1011 | B12: =VLOOKUP(A12,Raw_CRM!$A$2:$L$19,2,FALSE()) -> Solstice Energy Co-op | C12: =VLOOKUP(A12,Raw_CRM!$A$2:$L$19,3,FALSE()) -> Energy | D12: =VLOOKUP(A12,Raw_CRM!$A$2:$L$19,4,FALSE()) -> Core | E12: =VLOOKUP(A12,Raw_CRM!$A$2:$L$19,5,FALSE()) -> Maya Chen | F12: =VLOOKUP(A12,Raw_CRM!$A$2:$L$19,6,FALSE()) -> 46243 | G12: =VLOOKUP(A12,Raw_CRM!$A$2:$L$19,7,FALSE()) -> 55 | H12: =VLOOKUP(A12,Raw_Approval!$A$2:$G$19,2,FALSE()) -> Approved execution | I12: =VLOOKUP(A12,Raw_Orders!$A$2:$H$19,6,FALSE()) -> 175000 | J12: =VLOOKUP(A12,Raw_Orders!$A$2:$H$19,4,FALSE()) -> 160000 | K12: =VLOOKUP(A12,Raw_Orders!$A$2:$H$19,5,FALSE()) -> 140000 | L12: =K12-J12 -> -20000 | M12: =VLOOKUP(A12,Case_Summary!$A$2:$F$19,2,FALSE()) -> 1 | N12: =VLOOKUP(A12,Case_Summary!$A$2:$F$19,3,FALSE()) -> 4 | O12: =VLOOKUP(A12,Case_Summary!$A$2:$F$19,4,FALSE()) -> 18 | P12: =VLOOKUP(A12,Activity_Summary!$A$2:$D$19,2,FALSE()) -> 0 | Q12: =VLOOKUP(A12,Activity_Summary!$A$2:$D$19,3,FALSE()) -> 46213 | R12: =Assumptions!$B$8-Q12 -> 5 | S12: =IF(COUNTIFS(Raw_Contacts!$B$2:$B$41,A12,Raw_Contacts!$F$2:$F$41,"Final Renewal Approver",Raw_Contacts!$H$2:$H$41,"Approved")>0,"Ready",IF(COUNTIFS(Raw_Contacts!$B$2:$B$41,A12,Raw_Contacts!$H$2:$H$41,"Operations Only")>0,"Ops route only",IF(COUNTIFS(Raw_Contacts!$B$2:$B$41,A12,Raw_Contacts!$H$2:$H$41,"Do not contact executive")>0,"Manager route only","Pending permission"))) -> Ready | T12: =IF(VLOOKUP(A12,Case_Summary!$A$2:$F$19,5,FALSE())=0,"",VLOOKUP(A12,Case_Summary!$A$2:$F$19,5,FALSE())) -> Reporting Discrepancy | U12: =IF(VLOOKUP(A12,Raw_Approval!$A$2:$G$19,3,FALSE())=0,"",VLOOKUP(A12,Raw_Approval!$A$2:$G$19,3,FALSE())) -> RPT-COMP | V12: =VLOOKUP(A12,Raw_CRM!$A$2:$L$19,10,FALSE()) -> 0 | W12: =IF(U12="","",IFERROR(VLOOKUP(U12,Raw_Offers!$A$2:$G$7,4,FALSE()),0)) -> 0 | X12: =IF(H12<>"Approved execution","Controlled",IF(U12="","No offer",IF(U12="MGR-REQ","Manager required",IF(OR(W12=0,V12<=W12),"Within authority","Over limit")))) -> Within authority | Y12: =IF(VLOOKUP(A12,Raw_Approval!$A$2:$G$19,5,FALSE())=0,"",VLOOKUP(A12,Raw_Approval!$A$2:$G$19,5,FALSE())) | Z12: CRM, cases, orders, contacts, activity, offers, approval
A13: A-1012 | B13: =VLOOKUP(A13,Raw_CRM!$A$2:$L$19,2,FALSE()) -> Vesta Apparel Collective | C13: =VLOOKUP(A13,Raw_CRM!$A$2:$L$19,3,FALSE()) -> Retail | D13: =VLOOKUP(A13,Raw_CRM!$A$2:$L$19,4,FALSE()) -> Key Growth | E13: =VLOOKUP(A13,Raw_CRM!$A$2:$L$19,5,FALSE()) -> Jordan Patel | F13: =VLOOKUP(A13,Raw_CRM!$A$2:$L$19,6,FALSE()) -> 46235 | G13: =VLOOKUP(A13,Raw_CRM!$A$2:$L$19,7,FALSE()) -> 47 | H13: =VLOOKUP(A13,Raw_Approval!$A$2:$G$19,2,FALSE()) -> Approved execution | I13: =VLOOKUP(A13,Raw_Orders!$A$2:$H$19,6,FALSE()) -> 305000 | J13: =VLOOKUP(A13,Raw_Orders!$A$2:$H$19,4,FALSE()) -> 290000 | K13: =VLOOKUP(A13,Raw_Orders!$A$2:$H$19,5,FALSE()) -> 238000 | L13: =K13-J13 -> -52000 | M13: =VLOOKUP(A13,Case_Summary!$A$2:$F$19,2,FALSE()) -> 2 | N13: =VLOOKUP(A13,Case_Summary!$A$2:$F$19,3,FALSE()) -> 5 | O13: =VLOOKUP(A13,Case_Summary!$A$2:$F$19,4,FALSE()) -> 20 | P13: =VLOOKUP(A13,Activity_Summary!$A$2:$D$19,2,FALSE()) -> 1 | Q13: =VLOOKUP(A13,Activity_Summary!$A$2:$D$19,3,FALSE()) -> 46217 | R13: =Assumptions!$B$8-Q13 -> 1 | S13: =IF(COUNTIFS(Raw_Contacts!$B$2:$B$41,A13,Raw_Contacts!$F$2:$F$41,"Final Renewal Approver",Raw_Contacts!$H$2:$H$41,"Approved")>0,"Ready",IF(COUNTIFS(Raw_Contacts!$B$2:$B$41,A13,Raw_Contacts!$H$2:$H$41,"Operations Only")>0,"Ops route only",IF(COUNTIFS(Raw_Contacts!$B$2:$B$41,A13,Raw_Contacts!$H$2:$H$41,"Do not contact executive")>0,"Manager route only","Pending permission"))) -> Ready | T13: =IF(VLOOKUP(A13,Case_Summary!$A$2:$F$19,5,FALSE())=0,"",VLOOKUP(A13,Case_Summary!$A$2:$F$19,5,FALSE())) -> Delivery Underpacing | U13: =IF(VLOOKUP(A13,Raw_Approval!$A$2:$G$19,3,FALSE())=0,"",VLOOKUP(A13,Raw_Approval!$A$2:$G$19,3,FALSE())) -> MG-15 | V13: =VLOOKUP(A13,Raw_CRM!$A$2:$L$19,10,FALSE()) -> 24000 | W13: =IF(U13="","",IFERROR(VLOOKUP(U13,Raw_Offers!$A$2:$G$7,4,FALSE()),0)) -> 25000 | X13: =IF(H13<>"Approved execution","Controlled",IF(U13="","No offer",IF(U13="MGR-REQ","Manager required",IF(OR(W13=0,V13<=W13),"Within authority","Over limit")))) -> Within authority | Y13: =IF(VLOOKUP(A13,Raw_Approval!$A$2:$G$19,5,FALSE())=0,"",VLOOKUP(A13,Raw_Approval!$A$2:$G$19,5,FALSE())) | Z13: CRM, cases, orders, contacts, activity, offers, approval
... A19: A-1018 | B19: =VLOOKUP(A19,Raw_CRM!$A$2:$L$19,2,FALSE()) -> Pinyon Outdoor Media Buyers | C19: =VLOOKUP(A19,Raw_CRM!$A$2:$L$19,3,FALSE()) -> Agency | D19: =VLOOKUP(A19,Raw_CRM!$A$2:$L$19,4,FALSE()) -> Core | E19: =VLOOKUP(A19,Raw_CRM!$A$2:$L$19,5,FALSE()) -> Priya Nair | F19: =VLOOKUP(A19,Raw_CRM!$A$2:$L$19,6,FALSE()) -> 46283 | G19: =VLOOKUP(A19,Raw_CRM!$A$2:$L$19,7,FALSE()) -> 66 | H19: =VLOOKUP(A19,Raw_Approval!$A$2:$G$19,2,FALSE()) -> Excluded - no action | I19: =VLOOKUP(A19,Raw_Orders!$A$2:$H$19,6,FALSE()) -> 135000 | J19: =VLOOKUP(A19,Raw_Orders!$A$2:$H$19,4,FALSE()) -> 124000 | K19: =VLOOKUP(A19,Raw_Orders!$A$2:$H$19,5,FALSE()) -> 118000 | L19: =K19-J19 -> -6000 | M19: =VLOOKUP(A19,Case_Summary!$A$2:$F$19,2,FALSE()) -> 1 | N19: =VLOOKUP(A19,Case_Summary!$A$2:$F$19,3,FALSE()) -> 2 | O19: =VLOOKUP(A19,Case_Summary!$A$2:$F$19,4,FALSE()) -> 6 | P19: =VLOOKUP(A19,Activity_Summary!$A$2:$D$19,2,FALSE()) -> 0 | Q19: =VLOOKUP(A19,Activity_Summary!$A$2:$D$19,3,FALSE()) -> 46217 | R19: =Assumptions!$B$8-Q19 -> 1 | S19: =IF(COUNTIFS(Raw_Contacts!$B$2:$B$41,A19,Raw_Contacts!$F$2:$F$41,"Final Renewal Approver",Raw_Contacts!$H$2:$H$41,"Approved")>0,"Ready",IF(COUNTIFS(Raw_Contacts!$B$2:$B$41,A19,Raw_Contacts!$H$2:$H$41,"Operations Only")>0,"Ops route only",IF(COUNTIFS(Raw_Contacts!$B$2:$B$41,A19,Raw_Contacts!$H$2:$H$41,"Do not contact executive")>0,"Manager route only","Pending permission"))) -> Pending permission | T19: =IF(VLOOKUP(A19,Case_Summary!$A$2:$F$19,5,FALSE())=0,"",VLOOKUP(A19,Case_Summary!$A$2:$F$19,5,FALSE())) -> Agency Consolidation | U19: =IF(VLOOKUP(A19,Raw_Approval!$A$2:$G$19,3,FALSE())=0,"",VLOOKUP(A19,Raw_Approval!$A$2:$G$19,3,FALSE())) | V19: =VLOOKUP(A19,Raw_CRM!$A$2:$L$19,10,FALSE()) -> 0 | W19: =IF(U19="","",IFERROR(VLOOKUP(U19,Raw_Offers!$A$2:$G$7,4,FALSE()),0)) | X19: =IF(H19<>"Approved execution","Controlled",IF(U19="","No offer",IF(U19="MGR-REQ","Manager required",IF(OR(W19=0,V19<=W19),"Within authority","Over limit")))) -> Controlled | Y19: =IF(VLOOKUP(A19,Raw_Approval!$A$2:$G$19,5,FALSE())=0,"",VLOOKUP(A19,Raw_Approval!$A$2:$G$19,5,FALSE())) -> Customer requested September review | Z19: CRM, cases, orders, contacts, activity, offers, approval

Sheet Scoring
A1: Account ID | B1: Account Name | C1: Approval Status | D1: Exposure Score | E1: Issue Burden Score | F1: Health Risk Score | G1: Urgency Score | H1: Activity Risk Score | I1: Forecast Risk Score | J1: Contact Readiness Score | K1: Recovery Risk Score | L1: Priority Score | M1: Rank | N1: Priority Tier
A2: A-1001 | B2: =VLOOKUP(A2,Normalized_Accounts!$A$2:$Z$19,2,FALSE()) -> Meridian Health Partners | C2: =VLOOKUP(A2,Normalized_Accounts!$A$2:$Z$19,8,FALSE()) -> Approved execution | D2: =MIN(100,VLOOKUP(A2,Normalized_Accounts!$A$2:$Z$19,9,FALSE())/Assumptions!$B$7*100) -> 85 | E2: =MIN(100,VLOOKUP(A2,Normalized_Accounts!$A$2:$Z$19,13,FALSE())*12+VLOOKUP(A2,Normalized_Accounts!$A$2:$Z$19,14,FALSE())*10+VLOOKUP(A2,Normalized_Accounts!$A$2:$Z$19,15,FALSE())*0.9) -> 81.1 | F2: =100-VLOOKUP(A2,Normalized_Accounts!$A$2:$Z$19,7,FALSE()) -> 52 | G2: =IF(VLOOKUP(A2,Normalized_Accounts!$A$2:$Z$19,6,FALSE())-Assumptions!$B$8<=14,100,IF(VLOOKUP(A2,Normalized_Accounts!$A$2:$Z$19,6,FALSE())-Assumptions!$B$8<=30,75,IF(VLOOKUP(A2,Normalized_Accounts!$A$2:$Z$19,6,FALSE())-Assumptions!$B$8<=45,50,25))) -> 100 | H2: =MIN(100,VLOOKUP(A2,Normalized_Accounts!$A$2:$Z$19,16,FALSE())*30+VLOOKUP(A2,Normalized_Accounts!$A$2:$Z$19,18,FALSE())*2) -> 32 | I2: =MIN(100,ABS(VLOOKUP(A2,Normalized_Accounts!$A$2:$Z$19,12,FALSE()))/100000*100) -> 38 | J2: =IF(VLOOKUP(A2,Normalized_Accounts!$A$2:$Z$19,19,FALSE())="Ready",100,IF(VLOOKUP(A2,Normalized_Accounts!$A$2:$Z$19,19,FALSE())="Ops route only",60,IF(VLOOKUP(A2,Normalized_Accounts!$A$2:$Z$19,19,FALSE())="Manager route only",20,0))) -> 100 | K2: =F2*0.35+E2*0.4+H2*0.25 -> 58.64 | L2: =D2*Assumptions!$B$2+K2*Assumptions!$B$3+G2*Assumptions!$B$4+J2*Assumptions!$B$5+I2*Assumptions!$B$6 -> 77.924 | M2: =RANK(L2,$L$2:$L$19,0) -> 2 | N2: =IF(C2<>"Approved execution","Controlled exception/hold",IF(L2>=75,"Tier 1",IF(L2>=60,"Tier 2","Tier 3"))) -> Tier 1
A3: A-1002 | B3: =VLOOKUP(A3,Normalized_Accounts!$A$2:$Z$19,2,FALSE()) -> Larkspur Credit Union | C3: =VLOOKUP(A3,Normalized_Accounts!$A$2:$Z$19,8,FALSE()) -> Approved execution | D3: =MIN(100,VLOOKUP(A3,Normalized_Accounts!$A$2:$Z$19,9,FALSE())/Assumptions!$B$7*100) -> 55 | E3: =MIN(100,VLOOKUP(A3,Normalized_Accounts!$A$2:$Z$19,13,FALSE())*12+VLOOKUP(A3,Normalized_Accounts!$A$2:$Z$19,14,FALSE())*10+VLOOKUP(A3,Normalized_Accounts!$A$2:$Z$19,15,FALSE())*0.9) -> 67.3 | F3: =100-VLOOKUP(A3,Normalized_Accounts!$A$2:$Z$19,7,FALSE()) -> 48 | G3: =IF(VLOOKUP(A3,Normalized_Accounts!$A$2:$Z$19,6,FALSE())-Assumptions!$B$8<=14,100,IF(VLOOKUP(A3,Normalized_Accounts!$A$2:$Z$19,6,FALSE())-Assumptions!$B$8<=30,75,IF(VLOOKUP(A3,Normalized_Accounts!$A$2:$Z$19,6,FALSE())-Assumptions!$B$8<=45,50,25))) -> 75 | H3: =MIN(100,VLOOKUP(A3,Normalized_Accounts!$A$2:$Z$19,16,FALSE())*30+VLOOKUP(A3,Normalized_Accounts!$A$2:$Z$19,18,FALSE())*2) -> 10 | I3: =MIN(100,ABS(VLOOKUP(A3,Normalized_Accounts!$A$2:$Z$19,12,FALSE()))/100000*100) -> 21 | J3: =IF(VLOOKUP(A3,Normalized_Accounts!$A$2:$Z$19,19,FALSE())="Ready",100,IF(VLOOKUP(A3,Normalized_Accounts!$A$2:$Z$19,19,FALSE())="Ops route only",60,IF(VLOOKUP(A3,Normalized_Accounts!$A$2:$Z$19,19,FALSE())="Manager route only",20,0))) -> 100 | K3: =F3*0.35+E3*0.4+H3*0.25 -> 46.22 | L3: =D3*Assumptions!$B$2+K3*Assumptions!$B$3+G3*Assumptions!$B$4+J3*Assumptions!$B$5+I3*Assumptions!$B$6 -> 58.727 | M3: =RANK(L3,$L$2:$L$19,0) -> 10 | N3: =IF(C3<>"Approved execution","Controlled exception/hold",IF(L3>=75,"Tier 1",IF(L3>=60,"Tier 2","Tier 3"))) -> Tier 3
