Workbook

Sheet Manager Readiness Dashboard
A1: Manager Readiness Dashboard
A2: HB-RAMP-2026-07 | approval request pending
A5: Readiness_Status | B5: Representatives
A6: Ready - pending manager | B6: =COUNTIF('Rep Readiness Summary'!K2:K11,A6) -> 3
A7: Limited exception - staged supervised | B7: =COUNTIF('Rep Readiness Summary'!K2:K11,A7) -> 1
A8: Remediation required | B8: =COUNTIF('Rep Readiness Summary'!K2:K11,A8) -> 2
A9: Pending evidence | B9: =COUNTIF('Rep Readiness Summary'!K2:K11,A9) -> 2
A10: Blocked - unresolved exception | B10: =COUNTIF('Rep Readiness Summary'!K2:K11,A10) -> 2

Sheet Definitions
A1: Term | B1: Definition
A2: Ready - pending manager | B2: All seven competencies evidenced; desk manager approval still pending
A3: Limited exception - staged supervised | B3: Approved limited exception exists; independent coverage still blocked
A4: Remediation required | B4: Failed evidence requires planned remediation or retest
A5: Pending evidence | B5: Evidence scheduled or not yet due
A6: Blocked - unresolved exception | B6: Licensing or compliance blocker unresolved

Sheet Requirements
A1: Competency_ID | B1: Competency_Name | C1: Required_Evidence | D1: Minimum_Rule | E1: Prerequisite | F1: Approval_Role
A2: GS-C01 | B2: Discovery and qualification | C2: Discovery simulation pass | D2: Score >= 85 | E2: Intake complete | F2: Trainer signoff
A3: GS-C02 | B3: Group fare quote mechanics | C3: Quote assessment pass | D3: Score >= 88 | E3: GS-C01 | F3: Product trainer signoff
A4: GS-C03 | B4: Contract and deposit terms | C4: Terms assessment pass | D4: Score >= 90 | E4: GS-C02 | F4: Contract trainer signoff
A5: GS-C04 | B5: Compliance disclosures | C5: Compliance checklist pass | D5: Pass with no critical miss | E5: GS-C01 | F5: Compliance signoff
A6: GS-C05 | B6: CRM opportunity hygiene | C6: CRM audit pass | D6: Score >= 95 | E6: GS-C01 | F6: QA signoff
A7: GS-C06 | B7: Escalation judgment | C7: Escalation scenario pass | D7: Score >= 85 | E7: GS-C03 and GS-C04 | F7: Supervisor recommendation
A8: GS-C07 | B8: Customer handoff readiness | C8: Live observation and handoff note | D8: QA score >= 90 and supervisor signoff | E8: GS-C02 through GS-C06 | F8: Desk manager approval

Sheet Evidence Register
A1: Rep_ID | B1: Representative_Name | C1: Competency_ID | D1: Competency_Name | E1: Required_Evidence | F1: Minimum_Rule | G1: Latest_Evidence | H1: Evidence_Date | I1: Score | J1: Evidence_Status | K1: Owner_ID | L1: Due_Date | M1: Exception_Code | N1: Approval_State | O1: Next_Action | P1: Source_Reference
A2: REP-2701 | B2: Maya Chen | C2: GS-C01 | D2: Discovery and qualification | E2: Discovery simulation pass | F2: Score >= 85 | G2: Discovery simulation pass | H2: 46214 | I2: 92 | J2: Complete | K2: Trainer | N2: Evidence complete | O2: Evidence meets July ramp standard | P2: LMS-2701-GS-C01
A3: REP-2701 | B3: Maya Chen | C3: GS-C02 | D3: Group fare quote mechanics | E3: Quote assessment pass | F3: Score >= 88 | G3: Quote assessment pass | H3: 46215 | I3: 94 | J3: Complete | K3: Product | N3: Evidence complete | O3: Evidence meets July ramp standard | P3: LMS-2701-GS-C02
A4: REP-2701 | B4: Maya Chen | C4: GS-C03 | D4: Contract and deposit terms | E4: Terms assessment pass | F4: Score >= 90 | G4: Terms assessment pass | H4: 46216 | I4: 93 | J4: Complete | K4: Contract | N4: Evidence complete | O4: Evidence meets July ramp standard | P4: LMS-2701-GS-C03
A5: REP-2701 | B5: Maya Chen | C5: GS-C04 | D5: Compliance disclosures | E5: Compliance checklist pass | F5: Pass with no critical miss | G5: Compliance checklist pass | H5: 46217 | I5: 2 | J5: Complete | K5: Compliance | N5: Evidence complete | O5: Evidence meets July ramp standard | P5: LMS-2701-GS-C04
A6: REP-2701 | B6: Maya Chen | C6: GS-C05 | D6: CRM opportunity hygiene | E6: CRM audit pass | F6: Score >= 95 | G6: CRM audit pass | H6: 46213 | I6: 99 | J6: Complete | K6: QA | N6: Evidence complete | O6: Evidence meets July ramp standard | P6: LMS-2701-GS-C05
A7: REP-2701 | B7: Maya Chen | C7: GS-C06 | D7: Escalation judgment | E7: Escalation scenario pass | F7: Score >= 85 | G7: Escalation scenario pass | H7: 46214 | I7: 90 | J7: Complete | K7: Supervisor | N7: Evidence complete | O7: Evidence meets July ramp standard | P7: LMS-2701-GS-C06
A8: REP-2701 | B8: Maya Chen | C8: GS-C07 | D8: Customer handoff readiness | E8: Live observation and handoff note | F8: QA score >= 90 and supervisor signoff | G8: Live observation and handoff note | H8: 46215 | I8: 95 | J8: Complete | K8: Desk | N8: Evidence complete | O8: Evidence meets July ramp standard | P8: LMS-2701-GS-C07
A9: REP-2702 | B9: Jordan Patel | C9: GS-C01 | D9: Discovery and qualification | E9: Discovery simulation pass | F9: Score >= 85 | G9: Discovery simulation pass | H9: 46214 | I9: 92 | J9: Complete | K9: Trainer | N9: Evidence complete | O9: Evidence meets July ramp standard | P9: LMS-2702-GS-C01
A10: REP-2702 | B10: Jordan Patel | C10: GS-C02 | D10: Group fare quote mechanics | E10: Quote assessment pass | F10: Score >= 88 | G10: Quote assessment pass | H10: 46215 | I10: 94 | J10: Complete | K10: Product | N10: Evidence complete | O10: Evidence meets July ramp standard | P10: LMS-2702-GS-C02
A11: REP-2702 | B11: Jordan Patel | C11: GS-C03 | D11: Contract and deposit terms | E11: Terms assessment pass | F11: Score >= 90 | G11: Terms assessment pass | H11: 46216 | I11: 93 | J11: Complete | K11: Contract | N11: Evidence complete | O11: Evidence meets July ramp standard | P11: LMS-2702-GS-C03
A12: REP-2702 | B12: Jordan Patel | C12: GS-C04 | D12: Compliance disclosures | E12: Compliance checklist pass | F12: Pass with no critical miss | G12: Compliance checklist pass | H12: 46217 | I12: 2 | J12: Complete | K12: Compliance | N12: Evidence complete | O12: Evidence meets July ramp standard | P12: LMS-2702-GS-C04
A13: REP-2702 | B13: Jordan Patel | C13: GS-C05 | D13: CRM opportunity hygiene | E13: CRM audit pass | F13: Score >= 95 | G13: CRM audit pass | H13: 46213 | I13: 99 | J13: Complete | K13: QA | N13: Evidence complete | O13: Evidence meets July ramp standard | P13: LMS-2702-GS-C05
A14: REP-2702 | B14: Jordan Patel | C14: GS-C06 | D14: Escalation judgment | E14: Escalation scenario pass | F14: Score >= 85 | G14: Escalation scenario pass | H14: 46214 | I14: 90 | J14: Complete | K14: Supervisor | N14: Evidence complete | O14: Evidence meets July ramp standard | P14: LMS-2702-GS-C06
A15: REP-2702 | B15: Jordan Patel | C15: GS-C07 | D15: Customer handoff readiness | E15: Live observation and handoff note | F15: QA score >= 90 and supervisor signoff | G15: Limited exception memorandum | H15: 46215 | I15: 86 | J15: Approved Exception | K15: SUP-411 | L15: 46223 | M15: EX-LIM-2702 | N15: Approved limited exception | O15: Live observation moved to 2026-07-20; approved limited supervised low-risk coverage only | P15: LMS-2702-GS-C07
A16: REP-2703 | B16: Sofia Ramirez | C16: GS-C01 | D16: Discovery and qualification | E16: Discovery simulation pass | F16: Score >= 85 | G16: Discovery simulation pass | H16: 46214 | I16: 92 | J16: Complete | K16: Trainer | N16: Evidence complete | O16: Evidence meets July ramp standard | P16: LMS-2703-GS-C01
A17: REP-2703 | B17: Sofia Ramirez | C17: GS-C02 | D17: Group fare quote mechanics | E17: Quote assessment pass | F17: Score >= 88 | G17: Quote assessment pass | H17: 46215 | I17: 94 | J17: Complete | K17: Product | N17: Evidence complete | O17: Evidence meets July ramp standard | P17: LMS-2703-GS-C02
A18: REP-2703 | B18: Sofia Ramirez | C18: GS-C03 | D18: Contract and deposit terms | E18: Terms assessment pass | F18: Score >= 90 | G18: Terms assessment pass | H18: 46216 | I18: 82 | J18: Failed | K18: TRN-503 | L18: 46220 | M18: EX-REM-2703 | N18: Remediation scheduled | O18: Contract terms retest scheduled 2026-07-17 | P18: LMS-2703-GS-C03
A19: REP-2703 | B19: Sofia Ramirez | C19: GS-C04 | D19: Compliance disclosures | E19: Compliance checklist pass | F19: Pass with no critical miss | G19: Compliance checklist pass | H19: 46217 | I19: 2 | J19: Complete | K19: Compliance | N19: Evidence complete | O19: Evidence meets July ramp standard | P19: LMS-2703-GS-C04
A20: REP-2703 | B20: Sofia Ramirez | C20: GS-C05 | D20: CRM opportunity hygiene | E20: CRM audit pass | F20: Score >= 95 | G20: CRM audit pass | H20: 46213 | I20: 99 | J20: Complete | K20: QA | N20: Evidence complete | O20: Evidence meets July ramp standard | P20: LMS-2703-GS-C05
A21: REP-2703 | B21: Sofia Ramirez | C21: GS-C06 | D21: Escalation judgment | E21: Escalation scenario pass | F21: Score >= 85 | G21: Escalation scenario pass | H21: 46214 | I21: 90 | J21: Complete | K21: Supervisor | N21: Evidence complete | O21: Evidence meets July ramp standard | P21: LMS-2703-GS-C06
A22: REP-2703 | B22: Sofia Ramirez | C22: GS-C07 | D22: Customer handoff readiness | E22: Live observation and handoff note | F22: QA score >= 90 and supervisor signoff | G22: Not yet complete | J22: Open | K22: TRN-503 | L22: 46220 | M22: EX-REM-2703 | N22: Remediation scheduled | O22: Live observation blocked until contract retest passes | P22: LMS-2703-GS-C07
A23: REP-2704 | B23: Ethan Brooks | C23: GS-C01 | D23: Discovery and qualification | E23: Discovery simulation pass | F23: Score >= 85 | G23: Discovery simulation pass | H23: 46214 | I23: 92 | J23: Complete | K23: Trainer | N23: Evidence complete | O23: Evidence meets July ramp standard | P23: LMS-2704-GS-C01
A24: REP-2704 | B24: Ethan Brooks | C24: GS-C02 | D24: Group fare quote mechanics | E24: Quote assessment pass | F24: Score >= 88 | G24: Quote assessment pass | H24: 46215 | I24: 94 | J24: Complete | K24: Product | N24: Evidence complete | O24: Evidence meets July ramp standard | P24: LMS-2704-GS-C02
A25: REP-2704 | B25: Ethan Brooks | C25: GS-C03 | D25: Contract and deposit terms | E25: Terms assessment pass | F25: Score >= 90 | G25: Terms assessment pass | H25: 46216 | I25: 93 | J25: Complete | K25: Contract | N25: Evidence complete | O25: Evidence meets July ramp standard | P25: LMS-2704-GS-C03
A26: REP-2704 | B26: Ethan Brooks | C26: GS-C04 | D26: Compliance disclosures | E26: Compliance checklist pass | F26: Pass with no critical miss | G26: Not yet complete | H26: 46217 | J26: Blocked | K26: COM-201 | L26: 46225 | M26: EX-LIC-2704 | N26: Unresolved | O26: State seller-of-travel licensing hold blocks compliance signoff | P26: LMS-2704-GS-C04
A27: REP-2704 | B27: Ethan Brooks | C27: GS-C05 | D27: CRM opportunity hygiene | E27: CRM audit pass | F27: Score >= 95 | G27: CRM audit pass | H27: 46213 | I27: 99 | J27: Complete | K27: QA | N27: Evidence complete | O27: Evidence meets July ramp standard | P27: LMS-2704-GS-C05
A28: REP-2704 | B28: Ethan Brooks | C28: GS-C06 | D28: Escalation judgment | E28: Escalation scenario pass | F28: Score >= 85 | G28: Not yet complete | J28: Open | K28: COM-201 | L28: 46225 | M28: EX-LIC-2704 | N28: Unresolved | O28: Escalation scenario held until licensing release | P28: LMS-2704-GS-C06
A29: REP-2704 | B29: Ethan Brooks | C29: GS-C07 | D29: Customer handoff readiness | E29: Live observation and handoff note | F29: QA score >= 90 and supervisor signoff | G29: Not yet complete | J29: Open | K29: COM-201 | L29: 46225 | M29: EX-LIC-2704 | N29: Unresolved | O29: No live observation until licensing release | P29: LMS-2704-GS-C07
A30: REP-2705 | B30: Priya Nair | C30: GS-C01 | D30: Discovery and qualification | E30: Discovery simulation pass | F30: Score >= 85 | G30: Discovery simulation pass | H30: 46214 | I30: 92 | J30: Complete | K30: Trainer | N30: Evidence complete | O30: Evidence meets July ramp standard | P30: LMS-2705-GS-C01
A31: REP-2705 | B31: Priya Nair | C31: GS-C02 | D31: Group fare quote mechanics | E31: Quote assessment pass | F31: Score >= 88 | G31: Quote assessment pass | H31: 46215 | I31: 94 | J31: Complete | K31: Product | N31: Evidence complete | O31: Evidence meets July ramp standard | P31: LMS-2705-GS-C02
A32: REP-2705 | B32: Priya Nair | C32: GS-C03 | D32: Contract and deposit terms | E32: Terms assessment pass | F32: Score >= 90 | G32: Terms assessment pass | H32: 46216 | I32: 93 | J32: Complete | K32: Contract | N32: Evidence complete | O32: Evidence meets July ramp standard | P32: LMS-2705-GS-C03
A33: REP-2705 | B33: Priya Nair | C33: GS-C04 | D33: Compliance disclosures | E33: Compliance checklist pass | F33: Pass with no critical miss | G33: Compliance checklist pass | H33: 46217 | I33: 2 | J33: Complete | K33: Compliance | N33: Evidence complete | O33: Evidence meets July ramp standard | P33: LMS-2705-GS-C04
A34: REP-2705 | B34: Priya Nair | C34: GS-C05 | D34: CRM opportunity hygiene | E34: CRM audit pass | F34: Score >= 95 | G34: CRM audit pass | H34: 46213 | I34: 91 | J34: Failed | K34: TRN-503 | L34: 46219 | M34: EX-CRM-2705 | N34: Remediation scheduled | O34: CRM audit missed deposit follow-up note; remediation scheduled | P34: LMS-2705-GS-C05
A35: REP-2705 | B35: Priya Nair | C35: GS-C06 | D35: Escalation judgment | E35: Escalation scenario pass | F35: Score >= 85 | G35: Escalation scenario pass | H35: 46214 | I35: 90 | J35: Complete | K35: Supervisor | N35: Evidence complete | O35: Evidence meets July ramp standard | P35: LMS-2705-GS-C06
A36: REP-2705 | B36: Priya Nair | C36: GS-C07 | D36: Customer handoff readiness | E36: Live observation and handoff note | F36: QA score >= 90 and supervisor signoff | G36: Live observation and handoff note | H36: 46215 | I36: 95 | J36: Complete | K36: Desk | N36: Evidence complete | O36: Evidence meets July ramp standard | P36: LMS-2705-GS-C07
A37: REP-2706 | B37: Liam O'Neill | C37: GS-C01 | D37: Discovery and qualification | E37: Discovery simulation pass | F37: Score >= 85 | G37: Discovery simulation pass | H37: 46214 | I37: 92 | J37: Complete | K37: Trainer | N37: Evidence complete | O37: Evidence meets July ramp standard | P37: LMS-2706-GS-C01
A38: REP-2706 | B38: Liam O'Neill | C38: GS-C02 | D38: Group fare quote mechanics | E38: Quote assessment pass | F38: Score >= 88 | G38: Quote assessment pass | H38: 46215 | I38: 94 | J38: Complete | K38: Product | N38: Evidence complete | O38: Evidence meets July ramp standard | P38: LMS-2706-GS-C02
A39: REP-2706 | B39: Liam O'Neill | C39: GS-C03 | D39: Contract and deposit terms | E39: Terms assessment pass | F39: Score >= 90 | G39: Terms assessment pass | H39: 46216 | I39: 93 | J39: Complete | K39: Contract | N39: Evidence complete | O39: Evidence meets July ramp standard | P39: LMS-2706-GS-C03
A40: REP-2706 | B40: Liam O'Neill | C40: GS-C04 | D40: Compliance disclosures | E40: Compliance checklist pass | F40: Pass with no critical miss | G40: Compliance checklist pass | H40: 46217 | I40: 2 | J40: Complete | K40: Compliance | N40: Evidence complete | O40: Evidence meets July ramp standard | P40: LMS-2706-GS-C04
...

Sheet Exception View
A1: Exception_Code | B1: Rep_ID | C1: Competency_ID | D1: Exception_Reason | E1: Approval_State | F1: Exception_Opened_Date | G1: Exception_Owner | H1: Next_Action | I1: Next_Action_Due_Date | J1: Days_Open
A2: EX-LIM-2702 | B2: REP-2702 | C2: GS-C07 | D2: Approved limited exception | E2: Approved limited exception | F2: 46217 | G2: SUP-411 | H2: Keep Jordan on low-risk affinity renewals with senior rep review until live observation closes | I2: 46223 | J2: =DATE(2026,7,17)-F2 -> 3
A3: EX-REM-2703 | B3: REP-2703 | C3: GS-C03 | D3: Failed contract terms | E3: Remediation scheduled | F3: 46216 | G3: TRN-503 | H3: Complete M301 remediation and retest before live observation | I3: 46220 | J3: =DATE(2026,7,17)-F3 -> 4
A4: EX-LIC-2704 | B4: REP-2704 | C4: GS-C04 | D4: Licensing hold | E4: Unresolved | F4: 46214 | G4: COM-201 | H4: Compliance to confirm seller-of-travel license clearance | I4: 46225 | J4: =DATE(2026,7,17)-F4 -> 6
A5: EX-CRM-2705 | B5: REP-2705 | C5: GS-C05 | D5: CRM hygiene gap | E5: Remediation scheduled | F5: 46218 | G5: TRN-503 | H5: Rebuild CRM opportunity notes and pass audit | I5: 46219 | J5: =DATE(2026,7,17)-F5 -> 2
A6: EX-LIVE-2706 | B6: REP-2706 | C6: GS-C07 | D6: Missed live observation | E6: Pending evidence | F6: 46218 | G6: TRN-505 | H6: Complete live call observation before manager approval | I6: 46220 | J6: =DATE(2026,7,17)-F6 -> 2
A7: EX-COMP-2708 | B7: REP-2708 | C7: GS-C04 | D7: Compliance disclosure miss | E7: Unresolved | F7: 46217 | G7: COM-201 | H7: Pass disclosure retest and compliance review | I7: 46221 | J7: =DATE(2026,7,17)-F7 -> 3
A8: EX-PANEL-2709 | B8: REP-2709 | C8: GS-C07 | D8: Supervisor panel pending | E8: Pending evidence | F8: 46218 | G8: SUP-410 | H8: Complete supervisor recommendation panel | I8: 46220 | J8: =DATE(2026,7,17)-F8 -> 2

Sheet Rep Readiness Summary
A1: Rep_ID | B1: Representative_Name | C1: Segment | D1: Supervisor_ID | E1: Complete_Count | F1: Required_Count | G1: Approved_Exception_Count | H1: Failed_Count | I1: Open_or_Blocked_Count | J1: Evidence_Complete_Pct | K1: Readiness_Status | L1: Approval_State
A2: REP-2701 | B2: Maya Chen | C2: Corporate | D2: SUP-410 | E2: =COUNTIFS('Evidence Register'!$A$2:$A$71,A2,'Evidence Register'!$J$2:$J$71,"Complete") -> 7 | F2: 7 | G2: =COUNTIFS('Evidence Register'!$A$2:$A$71,A2,'Evidence Register'!$J$2:$J$71,"Approved Exception") -> 0 | H2: =COUNTIFS('Evidence Register'!$A$2:$A$71,A2,'Evidence Register'!$J$2:$J$71,"Failed") -> 0 | I2: =COUNTIFS('Evidence Register'!$A$2:$A$71,A2,'Evidence Register'!$J$2:$J$71,"Open")+COUNTIFS('Evidence Register'!$A$2:$A$71,A2,'Evidence Register'!$J$2:$J$71,"Blocked") -> 0 | J2: =E2/F2 -> 1 | K2: =IF(COUNTIFS('Exception View'!$B$2:$B$8,A2,'Exception View'!$E$2:$E$8,"Unresolved")>0,"Blocked - unresolved exception",IF(E2=F2,"Ready - pending manager",IF(G2>0,"Limited exception - staged supervised",IF(H2>0,"Remediation required","Pending evidence")))) -> Ready - pending manager | L2: HB-RAMP-2026-07 pending
A3: REP-2702 | B3: Jordan Patel | C3: Affinity | D3: SUP-411 | E3: =COUNTIFS('Evidence Register'!$A$2:$A$71,A3,'Evidence Register'!$J$2:$J$71,"Complete") -> 6 | F3: 7 | G3: =COUNTIFS('Evidence Register'!$A$2:$A$71,A3,'Evidence Register'!$J$2:$J$71,"Approved Exception") -> 1 | H3: =COUNTIFS('Evidence Register'!$A$2:$A$71,A3,'Evidence Register'!$J$2:$J$71,"Failed") -> 0 | I3: =COUNTIFS('Evidence Register'!$A$2:$A$71,A3,'Evidence Register'!$J$2:$J$71,"Open")+COUNTIFS('Evidence Register'!$A$2:$A$71,A3,'Evidence Register'!$J$2:$J$71,"Blocked") -> 0 | J3: =E3/F3 -> 0.85714286 | K3: =IF(COUNTIFS('Exception View'!$B$2:$B$8,A3,'Exception View'!$E$2:$E$8,"Unresolved")>0,"Blocked - unresolved exception",IF(E3=F3,"Ready - pending manager",IF(G3>0,"Limited exception - staged supervised",IF(H3>0,"Remediation required","Pending evidence")))) -> Limited exception - staged supervised | L3: HB-RAMP-2026-07 pending
A4: REP-2703 | B4: Sofia Ramirez | C4: Education | D4: SUP-412 | E4: =COUNTIFS('Evidence Register'!$A$2:$A$71,A4,'Evidence Register'!$J$2:$J$71,"Complete") -> 5 | F4: 7 | G4: =COUNTIFS('Evidence Register'!$A$2:$A$71,A4,'Evidence Register'!$J$2:$J$71,"Approved Exception") -> 0 | H4: =COUNTIFS('Evidence Register'!$A$2:$A$71,A4,'Evidence Register'!$J$2:$J$71,"Failed") -> 1 | I4: =COUNTIFS('Evidence Register'!$A$2:$A$71,A4,'Evidence Register'!$J$2:$J$71,"Open")+COUNTIFS('Evidence Register'!$A$2:$A$71,A4,'Evidence Register'!$J$2:$J$71,"Blocked") -> 1 | J4: =E4/F4 -> 0.71428571 | K4: =IF(COUNTIFS('Exception View'!$B$2:$B$8,A4,'Exception View'!$E$2:$E$8,"Unresolved")>0,"Blocked - unresolved exception",IF(E4=F4,"Ready - pending manager",IF(G4>0,"Limited exception - staged supervised",IF(H4>0,"Remediation required","Pending evidence")))) -> Remediation required | L4: HB-RAMP-2026-07 pending
A5: REP-2704 | B5: Ethan Brooks | C5: Meetings | D5: SUP-413 | E5: =COUNTIFS('Evidence Register'!$A$2:$A$71,A5,'Evidence Register'!$J$2:$J$71,"Complete") -> 4 | F5: 7 | G5: =COUNTIFS('Evidence Register'!$A$2:$A$71,A5,'Evidence Register'!$J$2:$J$71,"Approved Exception") -> 0 | H5: =COUNTIFS('Evidence Register'!$A$2:$A$71,A5,'Evidence Register'!$J$2:$J$71,"Failed") -> 0 | I5: =COUNTIFS('Evidence Register'!$A$2:$A$71,A5,'Evidence Register'!$J$2:$J$71,"Open")+COUNTIFS('Evidence Register'!$A$2:$A$71,A5,'Evidence Register'!$J$2:$J$71,"Blocked") -> 3 | J5: =E5/F5 -> 0.57142857 | K5: =IF(COUNTIFS('Exception View'!$B$2:$B$8,A5,'Exception View'!$E$2:$E$8,"Unresolved")>0,"Blocked - unresolved exception",IF(E5=F5,"Ready - pending manager",IF(G5>0,"Limited exception - staged supervised",IF(H5>0,"Remediation required","Pending evidence")))) -> Blocked - unresolved exception | L5: HB-RAMP-2026-07 pending
A6: REP-2705 | B6: Priya Nair | C6: Corporate | D6: SUP-410 | E6: =COUNTIFS('Evidence Register'!$A$2:$A$71,A6,'Evidence Register'!$J$2:$J$71,"Complete") -> 6 | F6: 7 | G6: =COUNTIFS('Evidence Register'!$A$2:$A$71,A6,'Evidence Register'!$J$2:$J$71,"Approved Exception") -> 0 | H6: =COUNTIFS('Evidence Register'!$A$2:$A$71,A6,'Evidence Register'!$J$2:$J$71,"Failed") -> 1 | I6: =COUNTIFS('Evidence Register'!$A$2:$A$71,A6,'Evidence Register'!$J$2:$J$71,"Open")+COUNTIFS('Evidence Register'!$A$2:$A$71,A6,'Evidence Register'!$J$2:$J$71,"Blocked") -> 0 | J6: =E6/F6 -> 0.85714286 | K6: =IF(COUNTIFS('Exception View'!$B$2:$B$8,A6,'Exception View'!$E$2:$E$8,"Unresolved")>0,"Blocked - unresolved exception",IF(E6=F6,"Ready - pending manager",IF(G6>0,"Limited exception - staged supervised",IF(H6>0,"Remediation required","Pending evidence")))) -> Remediation required | L6: HB-RAMP-2026-07 pending
A7: REP-2706 | B7: Liam O'Neill | C7: Affinity | D7: SUP-411 | E7: =COUNTIFS('Evidence Register'!$A$2:$A$71,A7,'Evidence Register'!$J$2:$J$71,"Complete") -> 6 | F7: 7 | G7: =COUNTIFS('Evidence Register'!$A$2:$A$71,A7,'Evidence Register'!$J$2:$J$71,"Approved Exception") -> 0 | H7: =COUNTIFS('Evidence Register'!$A$2:$A$71,A7,'Evidence Register'!$J$2:$J$71,"Failed") -> 0 | I7: =COUNTIFS('Evidence Register'!$A$2:$A$71,A7,'Evidence Register'!$J$2:$J$71,"Open")+COUNTIFS('Evidence Register'!$A$2:$A$71,A7,'Evidence Register'!$J$2:$J$71,"Blocked") -> 1 | J7: =E7/F7 -> 0.85714286 | K7: =IF(COUNTIFS('Exception View'!$B$2:$B$8,A7,'Exception View'!$E$2:$E$8,"Unresolved")>0,"Blocked - unresolved exception",IF(E7=F7,"Ready - pending manager",IF(G7>0,"Limited exception - staged supervised",IF(H7>0,"Remediation required","Pending evidence")))) -> Pending evidence | L7: HB-RAMP-2026-07 pending
A8: REP-2707 | B8: Ava Thompson | C8: Education | D8: SUP-412 | E8: =COUNTIFS('Evidence Register'!$A$2:$A$71,A8,'Evidence Register'!$J$2:$J$71,"Complete") -> 7 | F8: 7 | G8: =COUNTIFS('Evidence Register'!$A$2:$A$71,A8,'Evidence Register'!$J$2:$J$71,"Approved Exception") -> 0 | H8: =COUNTIFS('Evidence Register'!$A$2:$A$71,A8,'Evidence Register'!$J$2:$J$71,"Failed") -> 0 | I8: =COUNTIFS('Evidence Register'!$A$2:$A$71,A8,'Evidence Register'!$J$2:$J$71,"Open")+COUNTIFS('Evidence Register'!$A$2:$A$71,A8,'Evidence Register'!$J$2:$J$71,"Blocked") -> 0 | J8: =E8/F8 -> 1 | K8: =IF(COUNTIFS('Exception View'!$B$2:$B$8,A8,'Exception View'!$E$2:$E$8,"Unresolved")>0,"Blocked - unresolved exception",IF(E8=F8,"Ready - pending manager",IF(G8>0,"Limited exception - staged supervised",IF(H8>0,"Remediation required","Pending evidence")))) -> Ready - pending manager | L8: HB-RAMP-2026-07 pending
A9: REP-2708 | B9: Noah Kim | C9: Meetings | D9: SUP-413 | E9: =COUNTIFS('Evidence Register'!$A$2:$A$71,A9,'Evidence Register'!$J$2:$J$71,"Complete") -> 5 | F9: 7 | G9: =COUNTIFS('Evidence Register'!$A$2:$A$71,A9,'Evidence Register'!$J$2:$J$71,"Approved Exception") -> 0 | H9: =COUNTIFS('Evidence Register'!$A$2:$A$71,A9,'Evidence Register'!$J$2:$J$71,"Failed") -> 1 | I9: =COUNTIFS('Evidence Register'!$A$2:$A$71,A9,'Evidence Register'!$J$2:$J$71,"Open")+COUNTIFS('Evidence Register'!$A$2:$A$71,A9,'Evidence Register'!$J$2:$J$71,"Blocked") -> 1 | J9: =E9/F9 -> 0.71428571 | K9: =IF(COUNTIFS('Exception View'!$B$2:$B$8,A9,'Exception View'!$E$2:$E$8,"Unresolved")>0,"Blocked - unresolved exception",IF(E9=F9,"Ready - pending manager",IF(G9>0,"Limited exception - staged supervised",IF(H9>0,"Remediation required","Pending evidence")))) -> Blocked - unresolved exception | L9: HB-RAMP-2026-07 pending
A10: REP-2709 | B10: Isabella Reed | C10: Corporate | D10: SUP-410 | E10: =COUNTIFS('Evidence Register'!$A$2:$A$71,A10,'Evidence Register'!$J$2:$J$71,"Complete") -> 6 | F10: 7 | G10: =COUNTIFS('Evidence Register'!$A$2:$A$71,A10,'Evidence Register'!$J$2:$J$71,"Approved Exception") -> 0 | H10: =COUNTIFS('Evidence Register'!$A$2:$A$71,A10,'Evidence Register'!$J$2:$J$71,"Failed") -> 0 | I10: =COUNTIFS('Evidence Register'!$A$2:$A$71,A10,'Evidence Register'!$J$2:$J$71,"Open")+COUNTIFS('Evidence Register'!$A$2:$A$71,A10,'Evidence Register'!$J$2:$J$71,"Blocked") -> 1 | J10: =E10/F10 -> 0.85714286 | K10: =IF(COUNTIFS('Exception View'!$B$2:$B$8,A10,'Exception View'!$E$2:$E$8,"Unresolved")>0,"Blocked - unresolved exception",IF(E10=F10,"Ready - pending manager",IF(G10>0,"Limited exception - staged supervised",IF(H10>0,"Remediation required","Pending evidence")))) -> Pending evidence | L10: HB-RAMP-2026-07 pending
A11: REP-2710 | B11: Marcus Lee | C11: Affinity | D11: SUP-411 | E11: =COUNTIFS('Evidence Register'!$A$2:$A$71,A11,'Evidence Register'!$J$2:$J$71,"Complete") -> 7 | F11: 7 | G11: =COUNTIFS('Evidence Register'!$A$2:$A$71,A11,'Evidence Register'!$J$2:$J$71,"Approved Exception") -> 0 | H11: =COUNTIFS('Evidence Register'!$A$2:$A$71,A11,'Evidence Register'!$J$2:$J$71,"Failed") -> 0 | I11: =COUNTIFS('Evidence Register'!$A$2:$A$71,A11,'Evidence Register'!$J$2:$J$71,"Open")+COUNTIFS('Evidence Register'!$A$2:$A$71,A11,'Evidence Register'!$J$2:$J$71,"Blocked") -> 0 | J11: =E11/F11 -> 1 | K11: =IF(COUNTIFS('Exception View'!$B$2:$B$8,A11,'Exception View'!$E$2:$E$8,"Unresolved")>0,"Blocked - unresolved exception",IF(E11=F11,"Ready - pending manager",IF(G11>0,"Limited exception - staged supervised",IF(H11>0,"Remediation required","Pending evidence")))) -> Ready - pending manager | L11: HB-RAMP-2026-07 pending

Sheet Reconciliation Checks
A1: Check | B1: Formula_Result | C1: Expected
A2: Cohort reps | B2: =COUNTA('Rep Readiness Summary'!A2:A11) -> 10 | C2: 10
A3: Evidence rows | B3: =COUNTA('Evidence Register'!A2:A71) -> 70 | C3: 70
A4: Ready count | B4: =COUNTIF('Rep Readiness Summary'!K2:K11,"Ready - pending manager") -> 3 | C4: 3
A5: Limited exception count | B5: =COUNTIF('Rep Readiness Summary'!K2:K11,"Limited exception - staged supervised") -> 1 | C5: 1
A6: Blocked count | B6: =COUNTIF('Rep Readiness Summary'!K2:K11,"Blocked - unresolved exception") -> 2 | C6: 2

Sheet Register Analysis
A1: Competency | B1: Open/failed evidence
A2: GS-C01 | B2: =COUNTIFS('Evidence Register'!$C$2:$C$71,A2,'Evidence Register'!$J$2:$J$71,"Failed")+COUNTIFS('Evidence Register'!$C$2:$C$71,A2,'Evidence Register'!$J$2:$J$71,"Open")+COUNTIFS('Evidence Register'!$C$2:$C$71,A2,'Evidence Register'!$J$2:$J$71,"Blocked") -> 0
A3: GS-C02 | B3: =COUNTIFS('Evidence Register'!$C$2:$C$71,A3,'Evidence Register'!$J$2:$J$71,"Failed")+COUNTIFS('Evidence Register'!$C$2:$C$71,A3,'Evidence Register'!$J$2:$J$71,"Open")+COUNTIFS('Evidence Register'!$C$2:$C$71,A3,'Evidence Register'!$J$2:$J$71,"Blocked") -> 0
A4: GS-C03 | B4: =COUNTIFS('Evidence Register'!$C$2:$C$71,A4,'Evidence Register'!$J$2:$J$71,"Failed")+COUNTIFS('Evidence Register'!$C$2:$C$71,A4,'Evidence Register'!$J$2:$J$71,"Open")+COUNTIFS('Evidence Register'!$C$2:$C$71,A4,'Evidence Register'!$J$2:$J$71,"Blocked") -> 1
A5: GS-C04 | B5: =COUNTIFS('Evidence Register'!$C$2:$C$71,A5,'Evidence Register'!$J$2:$J$71,"Failed")+COUNTIFS('Evidence Register'!$C$2:$C$71,A5,'Evidence Register'!$J$2:$J$71,"Open")+COUNTIFS('Evidence Register'!$C$2:$C$71,A5,'Evidence Register'!$J$2:$J$71,"Blocked") -> 2
A6: GS-C05 | B6: =COUNTIFS('Evidence Register'!$C$2:$C$71,A6,'Evidence Register'!$J$2:$J$71,"Failed")+COUNTIFS('Evidence Register'!$C$2:$C$71,A6,'Evidence Register'!$J$2:$J$71,"Open")+COUNTIFS('Evidence Register'!$C$2:$C$71,A6,'Evidence Register'!$J$2:$J$71,"Blocked") -> 1
A7: GS-C06 | B7: =COUNTIFS('Evidence Register'!$C$2:$C$71,A7,'Evidence Register'!$J$2:$J$71,"Failed")+COUNTIFS('Evidence Register'!$C$2:$C$71,A7,'Evidence Register'!$J$2:$J$71,"Open")+COUNTIFS('Evidence Register'!$C$2:$C$71,A7,'Evidence Register'!$J$2:$J$71,"Blocked") -> 1
A8: GS-C07 | B8: =COUNTIFS('Evidence Register'!$C$2:$C$71,A8,'Evidence Register'!$J$2:$J$71,"Failed")+COUNTIFS('Evidence Register'!$C$2:$C$71,A8,'Evidence Register'!$J$2:$J$71,"Open")+COUNTIFS('Evidence Register'!$C$2:$C$71,A8,'Evidence Register'!$J$2:$J$71,"Blocked") -> 5
A11: Exception | B11: Owner | C11: Days open
A12: EX-LIM-2702 | B12: SUP-411 | C12: ='Exception View'!J2 -> 3
A13: EX-REM-2703 | B13: TRN-503 | C13: ='Exception View'!J3 -> 4
A14: EX-LIC-2704 | B14: COM-201 | C14: ='Exception View'!J4 -> 6
A15: EX-CRM-2705 | B15: TRN-503 | C15: ='Exception View'!J5 -> 2
A16: EX-LIVE-2706 | B16: TRN-505 | C16: ='Exception View'!J6 -> 2
A17: EX-COMP-2708 | B17: COM-201 | C17: ='Exception View'!J7 -> 3
A18: EX-PANEL-2709 | B18: SUP-410 | C18: ='Exception View'!J8 -> 2
A21: Rep | B21: Complete evidence %
A22: REP-2701 | B22: ='Rep Readiness Summary'!J2 -> 1
A23: REP-2702 | B23: ='Rep Readiness Summary'!J3 -> 0.85714286
A24: REP-2703 | B24: ='Rep Readiness Summary'!J4 -> 0.71428571
A25: REP-2704 | B25: ='Rep Readiness Summary'!J5 -> 0.57142857
A26: REP-2705 | B26: ='Rep Readiness Summary'!J6 -> 0.85714286
A27: REP-2706 | B27: ='Rep Readiness Summary'!J7 -> 0.85714286
A28: REP-2707 | B28: ='Rep Readiness Summary'!J8 -> 1
A29: REP-2708 | B29: ='Rep Readiness Summary'!J9 -> 0.71428571
A30: REP-2709 | B30: ='Rep Readiness Summary'!J10 -> 0.85714286
A31: REP-2710 | B31: ='Rep Readiness Summary'!J11 -> 1
